Workbook
Name CAofSales: Assumptions!$L$71:$P$71
Name CapexofSales: Assumptions!$L$45:$P$45
Name CircToggle: IS!$R$18
Name CoName: Inputs!$E$3
Name datareq: Inputs!$E$11
Name Days: Inputs!$E$9
Name DIH: Assumptions!$L$65:$P$65
Name DPO: Assumptions!$L$78:$P$78
Name DSO: Assumptions!$L$59:$P$59
Name EndCashTable: Assumptions!$V$10:$W$14
Name FYE: Inputs!$E$7
Name GrossMargins: Assumptions!$L$19:$P$19
Name IntangAdd: Assumptions!$L$51:$P$51
Name IQ_CH: 110000
Name IQ_CQ: 5000
Name IQ_CY: 10000
Name IQ_DAILY: 500000
Name IQ_FH: 100000
Name IQ_FQ: 500
Name IQ_FY: 1000
Name IQ_LTM: 2000
Name IQ_MONTH: 15000
Name IQ_NTM: 6000
Name IQ_WEEK: 50000
Name IQ_YTD: 3000
Name OpScenario: Assumptions!$F$4
Name OtherCLofSales: Assumptions!$L$84:$P$84
Name SalesGrowth: Assumptions!$L$12:$P$12
Name SGAofSales: Assumptions!$L$27:$P$27
Name subhead: Inputs!$E$5

Sheet Inputs
B3: Company | E3: Sharang Corporation
B5: Subheading | E5: Dollars in millions, except per share data
B7: Last Fiscal Year End | E7: 45291
B9: Days per year | E9: 365
B11: Missing data indicator | E11: datarequired
XX1000: 127155

Sheet Assumptions
B1: ="Projection Assumptions for "&CoName -> Projection Assumptions for Sharang Corporation
B3: Option Selection
B4: Operating scenario | F4: 1
H6: FYE Adjustment | I6: -2 | J6: =I6+1 -> -1 | K6: =J6+1 -> 0 | L6: =K6+1 -> 1 | M6: =L6+1 -> 2 | N6: =M6+1 -> 3 | O6: =N6+1 -> 4 | P6: =O6+1 -> 5
I8: Historical | L8: Projected | V8: Data Table (10 points)
I9: =YEAR(FYE)+I6 -> 2021 | J9: =YEAR(FYE)+J6 -> 2022 | K9: =YEAR(FYE)+K6 -> 2023 | L9: =YEAR(FYE)+L6 -> 2024 | M9: =YEAR(FYE)+M6 -> 2025 | N9: =YEAR(FYE)+N6 -> 2026 | O9: =YEAR(FYE)+O6 -> 2027 | P9: =YEAR(FYE)+P6 -> 2028 | R9: Annual Step
W10: =CF!P34 -> 64.542129
B11: Income Statement Assumptions | V11: =1 -> 1 | W11: 64.542224
B12: Sales (% growth) | J12: =IS!J34 -> 0.097911607 | K12: =IS!K34 -> 0.066827901 | L12: =CHOOSE($F$4,L13,L14,L15,L16) -> 0.06 | M12: =CHOOSE($F$4,M13,M14,M15,M16) -> 0.056 | N12: =CHOOSE($F$4,N13,N14,N15,N16) -> 0.052 | O12: =CHOOSE($F$4,O13,O14,O15,O16) -> 0.048 | P12: =CHOOSE($F$4,P13,P14,P15,P16) -> 0.044 | V12: =V11+1 -> 2 | W12: 35.000023
C13: Base | H13: 1 | L13: 0.06 | M13: =L13+$R13 -> 0.056 | N13: =M13+$R13 -> 0.052 | O13: =N13+$R13 -> 0.048 | P13: =O13+$R13 -> 0.044 | R13: -0.004 | V13: =V12+1 -> 3 | W13: 632.82768
C14: Management | H14: =H13+1 -> 2 | L14: 0.067 | M14: =L14+$R14 -> 0.06 | N14: =M14+$R14 -> 0.053 | O14: =N14+$R14 -> 0.046 | P14: =O14+$R14 -> 0.039 | R14: -0.007 | V14: =V13+1 -> 4 | W14: 34.999897
C15: Upside | H15: =H14+1 -> 3 | L15: 0.075 | M15: =L15+$R15 -> 0.075 | N15: =M15+$R15 -> 0.075 | O15: =N15+$R15 -> 0.075 | P15: =O15+$R15 -> 0.075 | R15: 0
C16: Downside | H16: =H15+1 -> 4 | L16: 0.05 | M16: =L16+$R16 -> 0.038 | N16: =M16+$R16 -> 0.026 | O16: =N16+$R16 -> 0.014 | P16: =O16+$R16 -> 0.002 | R16: -0.012
B19: Gross margins | I19: =1-I20 -> 0.50885216 | J19: =1-J20 -> 0.47778668 | K19: =1-K20 -> 0.47 | L19: =1-L20 -> 0.466 | M19: =1-M20 -> 0.466 | N19: =1-N20 -> 0.466 | O19: =1-O20 -> 0.466 | P19: =1-P20 -> 0.466
B20: Cost of goods sold (% sales) | I20: =(1-IS!I27) -> 0.49114784 | J20: =(1-IS!J27) -> 0.52221332 | K20: =(1-IS!K27) -> 0.53 | L20: {=INDEX(L21:L24,$F$4)} -> 0.534 | M20: {=INDEX(M21:M24,$F$4)} -> 0.534 | N20: {=INDEX(N21:N24,$F$4)} -> 0.534 | O20: {=INDEX(O21:O24,$F$4)} -> 0.534 | P20: {=INDEX(P21:P24,$F$4)} -> 0.534
C21: Base | H21: 1 | L21: =(1-46.6%) -> 0.534 | M21: =(1-46.6%) -> 0.534 | N21: =(1-46.6%) -> 0.534 | O21: =(1-46.6%) -> 0.534 | P21: =(1-46.6%) -> 0.534
C22: Management | H22: =H21+1 -> 2 | L22: 0.53 | M22: =L22+0.002 -> 0.532 | N22: =M22+0.002 -> 0.534 | O22: =N22+0.002 -> 0.536 | P22: =O22+0.002 -> 0.538
C23: Upside | H23: =H22+1 -> 3 | L23: 0.52 | M23: 0.52 | N23: 0.52 | O23: 0.52 | P23: 0.52
C24: Downside | H24: =H23+1 -> 4 | L24: 0.545 | M24: 0.545 | N24: 0.545 | O24: 0.545 | P24: 0.545
B26: SG&A (% sales) | I26: =IS!I28 -> 0.29631233 | J26: =IS!J28 -> 0.27389241 | K26: =IS!K28 -> 0.2674206 | L26: {=INDEX(L27:L30,$F$4)} -> 0.281 | M26: {=INDEX(M27:M30,$F$4)} -> 0.281 | N26: {=INDEX(N27:N30,$F$4)} -> 0.281 | O26: {=INDEX(O27:O30,$F$4)} -> 0.281 | P26: {=INDEX(P27:P30,$F$4)} -> 0.281
C27: Base | H27: 1 | L27: 0.281 | M27: 0.281 | N27: 0.281 | O27: 0.281 | P27: 0.281
C28: Management | H28: =H27+1 -> 2 | L28: 0.281 | M28: 0.281 | N28: 0.281 | O28: 0.281 | P28: 0.281
C29: Upside | H29: =H28+1 -> 3 | L29: 0.281 | M29: 0.281 | N29: 0.281 | O29: 0.281 | P29: 0.281
C30: Downside | H30: =H29+1 -> 4 | L30: 0.281 | M30: 0.281 | N30: 0.281 | O30: 0.281 | P30: 0.281
B32: Depreciation () | I32: =IS!I14/IS!I7 -> 0.02780465 | J32: =IS!J14/IS!J7 -> 0.026095262 | K32: =IS!K14/IS!K7 -> 0.025615775 | L32: {=INDEX(L33:L36,$F$4)} -> 0.027 | M32: {=INDEX(M33:M36,$F$4)} -> 0.027 | N32: {=INDEX(N33:N36,$F$4)} -> 0.027 | O32: {=INDEX(O33:O36,$F$4)} -> 0.027 | P32: {=INDEX(P33:P36,$F$4)} -> 0.027
C33: Base | H33: 1 | L33: 0.027 | M33: =$L33 -> 0.027 | N33: =$L33 -> 0.027 | O33: =$L33 -> 0.027 | P33: =$L33 -> 0.027
C34: Management | H34: =H33+1 -> 2 | L34: 0.027 | M34: =$L34 -> 0.027 | N34: =$L34 -> 0.027 | O34: =$L34 -> 0.027 | P34: =$L34 -> 0.027
C35: Upside | H35: =H34+1 -> 3 | L35: 0.027 | M35: =$L35 -> 0.027 | N35: =$L35 -> 0.027 | O35: =$L35 -> 0.027 | P35: =$L35 -> 0.027
C36: Downside | H36: =H35+1 -> 4 | L36: 0.027 | M36: =$L36 -> 0.027 | N36: =$L36 -> 0.027 | O36: =$L36 -> 0.027 | P36: =$L36 -> 0.027
B38: Amortization() | I38: =IS!I15/IS!I7 -> 0.0020295365 | J38: =IS!J15/IS!J7 -> 0.0012323618 | K38: =IS!K15/IS!K7 -> 0.001010769 | L38: {=INDEX(L39:L42,$F$4)} -> 0.0014825148 | M38: {=INDEX(M39:M42,$F$4)} -> 0.0013726989 | N38: {=INDEX(N39:N42,$F$4)} -> 0.0012828962 | O38: {=INDEX(O39:O42,$F$4)} -> 0.0012102794 | P38: {=INDEX(P39:P42,$F$4)} -> 0.001152647
C39: Base | H39: 1 | L39: 0.0014825148 | M39: 0.0013726989 | N39: 0.0012828962 | O39: 0.0012102794 | P39: 0.001152647
C40: Management | H40: =H39+1 -> 2 | L40: 0.001 | M40: =$L40 -> 0.001 | N40: =$L40 -> 0.001 | O40: =$L40 -> 0.001 | P40: =$L40 -> 0.001
C41: Upside | H41: =H40+1 -> 3 | L41: 0.001 | M41: =$L41 -> 0.001 | N41: =$L41 -> 0.001 | O41: =$L41 -> 0.001 | P41: =$L41 -> 0.001
C42: Downside | H42: =H41+1 -> 4 | L42: 0.001 | M42: =$L42 -> 0.001 | N42: =$L42 -> 0.001 | O42: =$L42 -> 0.001 | P42: =$L42 -> 0.001
B44: Cash Flow Statement Assumptions
B45: Capital expenditures (% sales) | I45: =Dep!I10 -> 0.029022372 | J45: =Dep!J10 -> 0.062357508 | K45: =Dep!K10 -> 0.11378371 | L45: {=INDEX(L46:L49,$F$4)} -> 0.05 | M45: {=INDEX(M46:M49,$F$4)} -> 0.05 | N45: {=INDEX(N46:N49,$F$4)} -> 0.05 | O45: {=INDEX(O46:O49,$F$4)} -> 0.05 | P45: {=INDEX(P46:P49,$F$4)} -> 0.05
C46: Base | H46: 1 | L46: 0.05 | M46: 0.05 | N46: 0.05 | O46: 0.05 | P46: 0.05
C47: Management | H47: =H46+1 -> 2 | L47: 0.07 | M47: 0.07 | N47: 0.05 | O47: 0.03 | P47: 0.03
C48: Upside | H48: =H47+1 -> 3 | L48: 0.026119625 | M48: 0.027 | N48: 0.027 | O48: 0.027 | P48: 0.027
C49: Downside | H49: =H48+1 -> 4 | L49: 0.07 | M49: 0.07 | N49: 0.07 | O49: 0.07 | P49: 0.027
...

Sheet IS
B1: ="Income Statement for "&CoName -> Income Statement for Sharang Corporation
B2: {=subhead} -> Dollars in millions, except per share data
H3: FYE Adjustment | I3: -2 | J3: =I3+1 -> -1 | K3: =J3+1 -> 0 | L3: =K3+1 -> 1 | M3: =L3+1 -> 2 | N3: =M3+1 -> 3 | O3: =N3+1 -> 4 | P3: =O3+1 -> 5
I5: ="Historical Year Ending "&TEXT(FYE,"Mmmm dd") & "," -> Historical Year Ending December 31, | L5: ="Projected Year Ending "&TEXT(FYE,"Mmmm Dd,") -> Projected Year Ending December 31,
I6: =YEAR(FYE)+I3 -> 2021 | J6: =YEAR(FYE)+J3 -> 2022 | K6: =YEAR(FYE)+K3 -> 2023 | L6: =YEAR(FYE)+L3 -> 2024 | M6: =YEAR(FYE)+M3 -> 2025 | N6: =YEAR(FYE)+N3 -> 2026 | O6: =YEAR(FYE)+O3 -> 2027 | P6: =YEAR(FYE)+P3 -> 2028
B7: Sales | I7: 2956.34 | J7: 3245.8 | K7: 3462.71 | L7: =K7*(1+L34) -> 3670.4726 | M7: =L7*(1+M34) -> 3876.0191 | N7: =M7*(1+N34) -> 4077.5721 | O7: =N7*(1+O34) -> 4273.2955 | P7: =O7*(1+P34) -> 4461.3205 | Q7: (5 points)
B8: Cost of goods sold (excluding depreciation) | I8: 1452 | J8: 1695 | K8: 1835.2363 | L8: =L7*(1-L27) -> 1960.0324 | M8: =M7*(1-M27) -> 2069.7942 | N8: =N7*(1-N27) -> 2177.4235 | O8: =O7*(1-O27) -> 2281.9398 | P8: =P7*(1-P27) -> 2382.3452 | Q8: (5 points)
C9: Gross profit | I9: =I7-I8 -> 1504.34 | J9: =J7-J8 -> 1550.8 | K9: =K7-K8 -> 1627.4737 | L9: =L7-L8 -> 1710.4402 | M9: =M7-M8 -> 1806.2249 | N9: =N7-N8 -> 1900.1486 | O9: =O7-O8 -> 1991.3557 | P9: =P7-P8 -> 2078.9754
B11: SG&A expenses (excluding amortization) | I11: 876 | J11: 889 | K11: 926 | L11: =L7*L28 -> 1031.4028 | M11: =M7*M28 -> 1089.1614 | N11: =N7*N28 -> 1145.7977 | O11: =O7*O28 -> 1200.796 | P11: =P7*P28 -> 1253.6311 | Q11: (5 points)
C12: EBITDA | I12: =I9-I11 -> 628.34 | J12: =J9-J11 -> 661.8 | K12: =K9-K11 -> 701.4737 | L12: =L9-L11 -> 679.03743 | M12: =M9-M11 -> 717.06353 | N12: =N9-N11 -> 754.35083 | O12: =O9-O11 -> 790.55967 | P12: =P9-P11 -> 825.3443
AM13: debt schedule to inc stmt
B14: Depreciation | I14: 82.2 | J14: 84.7 | K14: 88.7 | L14: =Dep!L39 -> 97.258831 | M14: =Dep!M39 -> 124.21059 | N14: =Dep!N39 -> 152.61627 | O14: =Dep!O39 -> 182.4408 | P14: =Dep!P39 -> 213.63585 | Q14: (1 point) | AM14: cf stmt to debt schedule
B15: Amortization | I15: 6 | J15: 4 | K15: 3.5 | L15: =Amort!L36 -> 2.3696152 | M15: =Amort!M36 -> 2.5928095 | N15: =Amort!N36 -> 2.8086386 | O15: =Amort!O36 -> 3.0165545 | P15: =Amort!P36 -> 3.216085 | Q15: (1 point)
C16: EBIT | I16: =I12-SUM(I14:I15) -> 540.14 | J16: =J12-SUM(J14:J15) -> 573.1 | K16: =K12-SUM(K14:K15) -> 609.2737 | L16: =L12-SUM(L14:L15) -> 579.40899 | M16: =M12-SUM(M14:M15) -> 590.26013 | N16: =N12-SUM(N14:N15) -> 598.92592 | O16: =O12-SUM(O14:O15) -> 605.10232 | P16: =P12-SUM(P14:P15) -> 608.49236 | AM16: inc stmt to cash flow stmt
AM17: wc schedule to cf stmt
B18: Interest expense | I18: 55 | J18: 53.2 | K18: 45.89 | L18: =IF(CircToggle=0,0,'Debt&Int'!L39) -> 79.076625 | M18: =IF(CircToggle=0,0,'Debt&Int'!M39) -> 68.967274 | N18: =IF(CircToggle=0,0,'Debt&Int'!N39) -> 55.005797 | O18: =IF(CircToggle=0,0,'Debt&Int'!O39) -> 39.763848 | P18: =IF(CircToggle=0,0,'Debt&Int'!P39) -> 25.144956 | Q18: (5 points) | R18: 1 | S18: Circular Calc of Debt Schedule | AM18: equity sched to cf stmt
B19: Interest (income) | I19: 0 | J19: 0 | K19: 0 | L19: =-IF(CircToggle=0,0,'Debt&Int'!L43) -> -1.362 | M19: =-IF(CircToggle=0,0,'Debt&Int'!M43) -> -0.96250001 | N19: =-IF(CircToggle=0,0,'Debt&Int'!N43) -> -0.8750002 | O19: =-IF(CircToggle=0,0,'Debt&Int'!O43) -> -0.7875013 | P19: =-IF(CircToggle=0,0,'Debt&Int'!P43) -> -0.9954223 | Q19: (5 points) | S19: 1= "on" (model "working") | AM19: debt schedule to cf stmt
C20: EBT | I20: =I16-SUM(I18:I19) -> 485.14 | J20: =J16-SUM(J18:J19) -> 519.9 | K20: =K16-SUM(K18:K19) -> 563.3837 | L20: =L16-SUM(L18:L19) -> 501.69436 | M20: =M16-SUM(M18:M19) -> 522.25536 | N20: =N16-SUM(N18:N19) -> 544.79513 | O20: =O16-SUM(O18:O19) -> 566.12597 | P20: =P16-SUM(P18:P19) -> 584.34282 | S20: 0 = "off" (change parameters) | AM20: income stmt to wc sched
AM21: cf stmt to bs
B22: Income taxes | I22: 220 | J22: 235 | K22: 175 | L22: =L20*L39 -> 155.52525 | M22: =M20*M39 -> 161.89916 | N22: =N20*N39 -> 168.88649 | O22: =O20*O39 -> 175.49905 | P22: =P20*P39 -> 181.14628 | Q22: (2 points) | AM22: d&a to bs
C23: Net income | I23: =I20-I22 -> 265.14 | J23: =J20-J22 -> 284.9 | K23: =K20-K22 -> 388.3837 | L23: =L20-L22 -> 346.16911 | M23: =M20-M22 -> 360.3562 | N23: =N20-N22 -> 375.90864 | O23: =O20-O22 -> 390.62692 | P23: =P20-P22 -> 403.19655 | AM23: debt sched to bs
C26: Margins
D27: Gross margin | I27: =IF(ISERROR(I9/I$7),datareq,I9/I$7) -> 0.50885216 | J27: =IF(ISERROR(J9/J$7),datareq,J9/J$7) -> 0.47778668 | K27: =IF(ISERROR(K9/K$7),datareq,K9/K$7) -> 0.47 | L27: {=GrossMargins} -> 0.466 | M27: 0.466 | N27: 0.466 | O27: 0.466 | P27: 0.466
D28: SG&A as a % of sales | I28: =IF(ISERROR(I$11/I$7),datareq,I$11/I$7) -> 0.29631233 | J28: =IF(ISERROR(J$11/J$7),datareq,J$11/J$7) -> 0.27389241 | K28: =IF(ISERROR(K$11/K$7),datareq,K$11/K$7) -> 0.2674206 | L28: {=SGAofSales} -> 0.281 | M28: 0.281 | N28: 0.281 | O28: 0.281 | P28: 0.281
D29: EBITDA margin | I29: =IF(ISERROR(I12/I$7),datareq,I12/I$7) -> 0.21253983 | J29: =IF(ISERROR(J12/J$7),datareq,J12/J$7) -> 0.20389426 | K29: =IF(ISERROR(K12/K$7),datareq,K12/K$7) -> 0.2025794 | L29: =IF(ISERROR(L12/L$7),datareq,L12/L$7) -> 0.185 | M29: =IF(ISERROR(M12/M$7),datareq,M12/M$7) -> 0.185 | N29: =IF(ISERROR(N12/N$7),datareq,N12/N$7) -> 0.185 | O29: =IF(ISERROR(O12/O$7),datareq,O12/O$7) -> 0.185 | P29: =IF(ISERROR(P12/P$7),datareq,P12/P$7) -> 0.185
D30: EBIT margin | I30: =IF(ISERROR(I16/I$7),datareq,I16/I$7) -> 0.18270564 | J30: =IF(ISERROR(J16/J$7),datareq,J16/J$7) -> 0.17656664 | K30: =IF(ISERROR(K16/K$7),datareq,K16/K$7) -> 0.17595285 | L30: =IF(ISERROR(L16/L$7),datareq,L16/L$7) -> 0.15785678 | M30: =IF(ISERROR(M16/M$7),datareq,M16/M$7) -> 0.15228515 | N30: =IF(ISERROR(N16/N$7),datareq,N16/N$7) -> 0.14688298 | O30: =IF(ISERROR(O16/O$7),datareq,O16/O$7) -> 0.14160086 | P30: =IF(ISERROR(P16/P$7),datareq,P16/P$7) -> 0.13639288
D31: Net income margin | I31: =IF(ISERROR(I23/I$7),datareq,I23/I$7) -> 0.089685219 | J31: =IF(ISERROR(J23/J$7),datareq,J23/J$7) -> 0.087774971 | K31: =IF(ISERROR(K23/K$7),datareq,K23/K$7) -> 0.11216178 | L31: =IF(ISERROR(L23/L$7),datareq,L23/L$7) -> 0.094311863 | M31: =IF(ISERROR(M23/M$7),datareq,M23/M$7) -> 0.092970698 | N31: =IF(ISERROR(N23/N$7),datareq,N23/N$7) -> 0.09218933 | O31: =IF(ISERROR(O23/O$7),datareq,O23/O$7) -> 0.091411165 | P31: =IF(ISERROR(P23/P$7),datareq,P23/P$7) -> 0.090376055
C33: Growth rate analysis
D34: Sales growth rate | J34: =IF(ISERROR(J7/I7-1),datareq, J7/I7-1) -> 0.097911607 | K34: =IF(ISERROR(K7/J7-1),datareq, K7/J7-1) -> 0.066827901 | L34: {=SalesGrowth} -> 0.06 | M34: 0.056 | N34: 0.052 | O34: 0.048 | P34: 0.044
D35: EBITDA growth rate | J35: =IF(ISERROR(J12/I12-1),datareq, J12/I12-1) -> 0.053251424 | K35: =IF(ISERROR(K12/J12-1),datareq, K12/J12-1) -> 0.059948172 | L35: =IF(ISERROR(L12/K12-1),datareq, L12/K12-1) -> -0.031984476 | M35: =IF(ISERROR(M12/L12-1),datareq, M12/L12-1) -> 0.056 | N35: =IF(ISERROR(N12/M12-1),datareq, N12/M12-1) -> 0.052 | O35: =IF(ISERROR(O12/N12-1),datareq, O12/N12-1) -> 0.048 | P35: =IF(ISERROR(P12/O12-1),datareq, P12/O12-1) -> 0.044
D36: EBIT growth rate | J36: =IF(ISERROR(J16/I16-1),datareq, J16/I16-1) -> 0.061021217 | K36: =IF(ISERROR(K16/J16-1),datareq, K16/J16-1) -> 0.063119351 | L36: =IF(ISERROR(L16/K16-1),datareq, L16/K16-1) -> -0.049016911 | M36: =IF(ISERROR(M16/L16-1),datareq, M16/L16-1) -> 0.018727956 | N36: =IF(ISERROR(N16/M16-1),datareq, N16/M16-1) -> 0.014681309 | O36: =IF(ISERROR(O16/N16-1),datareq, O16/N16-1) -> 0.010312456 | P36: =IF(ISERROR(P16/O16-1),datareq, P16/O16-1) -> 0.0056024208
D37: Net income growth rate | J37: =IF(ISERROR(J23/I23-1),datareq, J23/I23-1) -> 0.074526665 | K37: =IF(ISERROR(K23/J23-1),datareq, K23/J23-1) -> 0.36322815 | L37: =IF(ISERROR(L23/K23-1),datareq, L23/K23-1) -> -0.10869301 | M37: =IF(ISERROR(M23/L23-1),datareq, M23/L23-1) -> 0.040983113 | N37: =IF(ISERROR(N23/M23-1),datareq, N23/M23-1) -> 0.043158522 | O37: =IF(ISERROR(O23/N23-1),datareq, O23/N23-1) -> 0.039153887 | P37: =IF(ISERROR(P23/O23-1),datareq, P23/O23-1) -> 0.032178086
D39: Effective tax rate | I39: =IF(ISERROR(I22/I20),datareq, I22/I20) -> 0.45347735 | J39: =IF(ISERROR(J22/J20)," need data ", J22/J20) -> 0.45201 | K39: =IF(ISERROR(K22/K20)," need data ", K22/K20) -> 0.31062312 | L39: 0.31 | M39: =L39 -> 0.31 | N39: =M39 -> 0.31 | O39: =N39 -> 0.31 | P39: =O39 -> 0.31
XX1000: 127155

Sheet BS
B1: ="Balance Sheet for "&CoName -> Balance Sheet for Sharang Corporation
B2: =subhead -> Dollars in millions, except per share data
H3: FYE Adjustment | I3: -2 | J3: =I3+1 -> -1 | K3: =J3+1 -> 0 | L3: =K3+1 -> 1 | M3: =L3+1 -> 2 | N3: =M3+1 -> 3 | O3: =N3+1 -> 4 | P3: =O3+1 -> 5
I5: ="Historical Year Ending "&TEXT(FYE,"Mmmm dd") & "," -> Historical Year Ending December 31, | L5: ="Projected Year Ending "&TEXT(FYE,"Mmmm Dd,") -> Projected Year Ending December 31,
I6: =YEAR(FYE)+I3 -> 2021 | J6: =YEAR(FYE)+J3 -> 2022 | K6: =YEAR(FYE)+K3 -> 2023 | L6: =YEAR(FYE)+L3 -> 2024 | M6: =YEAR(FYE)+M3 -> 2025 | N6: =YEAR(FYE)+N3 -> 2026 | O6: =YEAR(FYE)+O3 -> 2027 | P6: =YEAR(FYE)+P3 -> 2028
B8: Cash | I8: 41.8 | J8: 45 | K8: 55.8 | L8: =CF!L34 -> 35 | M8: =CF!M34 -> 35.000001 | N8: =CF!N34 -> 35.000015 | O8: =CF!O34 -> 35.000101 | P8: =CF!P34 -> 64.542129 | Q8: (1 point)
B9: Accounts receivable, net | I9: 375 | J9: 362 | K9: 386.3 | L9: =WC!L12 -> 442.46793 | M9: =WC!M12 -> 456.6269 | N9: =WC!N12 -> 469.20007 | O9: =WC!O12 -> 480.01402 | P9: =WC!P12 -> 488.91184 | Q9: (1 point)
B10: Inventories | I10: 441 | J10: 465 | K10: 476.7 | L10: =WC!L13 -> 515.51536 | M10: =WC!M13 -> 538.71355 | N10: =WC!N13 -> 560.76111 | O10: =WC!O13 -> 581.42576 | P10: =WC!P13 -> 600.48152 | Q10: (1 point)
B11: Other current assets | I11: 110.5 | J11: 117 | K11: 102.7 | L11: =WC!L14 -> 110.11418 | M11: =WC!M14 -> 116.28057 | N11: =WC!N14 -> 122.32716 | O11: =WC!O14 -> 128.19887 | P11: =WC!P14 -> 133.83962 | Q11: (1 point)
C12: Total current assets | I12: =SUM(I8:I11) -> 968.3 | J12: =SUM(J8:J11) -> 989 | K12: =SUM(K8:K11) -> 1021.5 | L12: =SUM(L8:L11) -> 1103.0975 | M12: =SUM(M8:M11) -> 1146.621 | N12: =SUM(N8:N11) -> 1187.2884 | O12: =SUM(O8:O11) -> 1224.6387 | P12: =SUM(P8:P11) -> 1287.7751
B14: PP&E, net | I14: 487 | J14: 560 | K14: 871 | L14: =Dep!L16 -> 957.2648 | M14: =Dep!M16 -> 1026.8552 | N14: =Dep!N16 -> 1078.1175 | O14: =Dep!O16 -> 1109.3415 | P14: =Dep!P16 -> 1118.7717 | Q14: (1 point)
B15: Intangibles | I15: 98 | J15: 35 | K15: 36.1 | L15: =Amort!L16 -> 39.171915 | M15: =Amort!M16 -> 41.850899 | N15: =Amort!N16 -> 44.130268 | O15: =Amort!O16 -> 46.005668 | P15: =Amort!P16 -> 47.475089 | Q15: (1 point)
B16: Indefinite life intangibles (trademark, brand) | I16: 278.3 | J16: 200.75 | K16: 200.8 | L16: =Other!L11 -> 200.8 | M16: =Other!M11 -> 200.8 | N16: =Other!N11 -> 200.8 | O16: =Other!O11 -> 200.8 | P16: =Other!P11 -> 200.8 | Q16: (1 point)
B17: Goodwill | I17: 1245.88 | J17: 1478 | K17: 1415 | L17: =Other!L12 -> 1415 | M17: =Other!M12 -> 1415 | N17: =Other!N12 -> 1415 | O17: =Other!O12 -> 1415 | P17: =Other!P12 -> 1415 | Q17: (1 point)
B18: Other long-term assets | I18: 132.8 | J18: 144.9 | K18: 145 | L18: =Other!L13 -> 145 | M18: =Other!M13 -> 145 | N18: =Other!N13 -> 145 | O18: =Other!O13 -> 145 | P18: =Other!P13 -> 145 | Q18: (1 point)
C19: Total assets | I19: =SUM(I12:I18) -> 3210.28 | J19: =SUM(J12:J18) -> 3407.65 | K19: =SUM(K12:K18) -> 3689.4 | L19: =SUM(L12:L18) -> 3860.3342 | M19: =SUM(M12:M18) -> 3976.1271 | N19: =SUM(N12:N18) -> 4070.3361 | O19: =SUM(O12:O18) -> 4140.7859 | P19: =SUM(P12:P18) -> 4214.8218
B21: Accounts payable | I21: 276.4 | J21: 300.2 | K21: 305.8 | L21: =WC!L17 -> 327.56705 | M21: =WC!M17 -> 351.58148 | N21: =WC!N17 -> 375.82926 | O21: =WC!O17 -> 400.12095 | P21: =WC!P17 -> 424.25325 | Q21: (1 point)
B22: Other current liabilities | I22: 414 | J22: 403.4 | K22: 431.7 | L22: =WC!L18 -> 450.80744 | M22: =WC!M18 -> 476.05266 | N22: =WC!N18 -> 500.8074 | O22: =WC!O18 -> 524.84616 | P22: =WC!P18 -> 547.93939 | Q22: (1 point)
C23: Total current liabilities | I23: =SUM(I21:I22) -> 690.4 | J23: =SUM(J21:J22) -> 703.6 | K23: =SUM(K21:K22) -> 737.5 | L23: =SUM(L21:L22) -> 778.3745 | M23: =SUM(M21:M22) -> 827.63414 | N23: =SUM(N21:N22) -> 876.63666 | O23: =SUM(O21:O22) -> 924.96711 | P23: =SUM(P21:P22) -> 972.19263
B25: Revolver | I25: 303.1 | J25: =101.2+120 -> 221.2 | K25: =0.2+120+185 -> 305.2 | L25: ='Debt&Int'!L21 -> 322.7816 | M25: ='Debt&Int'!M21 -> 168.70828 | N25: ='Debt&Int'!N21 -> 234.28778 | O25: ='Debt&Int'!O21 -> 18.343477 | P25: ='Debt&Int'!P21 -> 0 | Q25: (1 point)
B26: Long-term debt | I26: 1012 | J26: 950 | K26: 760 | L26: ='Debt&Int'!L27 -> 659.8 | M26: ='Debt&Int'!M27 -> 659.5 | N26: ='Debt&Int'!N27 -> 409.2 | O26: ='Debt&Int'!O27 -> 408.8 | P26: ='Debt&Int'!P27 -> 208.2 | Q26: (1 point)
B27: Other long-term liabilities | I27: 238.2 | J27: 351.1 | K27: 342.3 | L27: =Other!L18 -> 342.3 | M27: =Other!M18 -> 342.3 | N27: =Other!N18 -> 342.3 | O27: =Other!O18 -> 342.3 | P27: =Other!P18 -> 342.3 | Q27: (1 point)
C28: Total liabilities | I28: =SUM(I23:I27) -> 2243.7 | J28: =SUM(J23:J27) -> 2225.9 | K28: =SUM(K23:K27) -> 2145 | L28: =SUM(L23:L27) -> 2103.2561 | M28: =SUM(M23:M27) -> 1998.1424 | N28: =SUM(N23:N27) -> 1862.4244 | O28: =SUM(O23:O27) -> 1694.4106 | P28: =SUM(P23:P27) -> 1522.6926
B30: Total stockholders' equity | I30: 966.58 | J30: 1181.75 | K30: 1544.4 | L30: =Equity!L13 -> 1757.0781 | M30: =Equity!M13 -> 1977.9847 | N30: =Equity!N13 -> 2207.9117 | O30: =Equity!O13 -> 2446.3752 | P30: =Equity!P13 -> 2692.1294 | Q30: (1 point)
B32: Total liabilities and equity | I32: =I28+I30 -> 3210.28 | J32: =J28+J30 -> 3407.65 | K32: =K28+K30 -> 3689.4 | L32: =L28+L30 -> 3860.3342 | M32: =M28+M30 -> 3976.1271 | N32: =N28+N30 -> 4070.3361 | O32: =O28+O30 -> 4140.7858 | P32: =P28+P30 -> 4214.822
C33: Check A = L + E | I33: =IF(ABS(I32-I19)<0.001,0,I32-I19) -> 0 | J33: =IF(ABS(J32-J19)<0.001,0,J32-J19) -> 0 | K33: =IF(ABS(K32-K19)<0.001,0,K32-K19) -> 0 | L33: =IF(ABS(L32-L19)<0.001,0,L32-L19) -> 0 | M33: =IF(ABS(M32-M19)<0.001,0,M32-M19) -> 0 | N33: =IF(ABS(N32-N19)<0.001,0,N32-N19) -> 0 | O33: =IF(ABS(O32-O19)<0.001,0,O32-O19) -> 0 | P33: =IF(ABS(P32-P19)<0.001,0,P32-P19) -> 0
B35: Total debt | I35: =SUM(I25:I26) -> 1315.1 | J35: =SUM(J25:J26) -> 1171.2 | K35: =SUM(K25:K26) -> 1065.2 | L35: =SUM(L25:L26) -> 982.5816 | M35: =SUM(M25:M26) -> 828.20828 | N35: =SUM(N25:N26) -> 643.48778 | O35: =SUM(O25:O26) -> 427.14348 | P35: =SUM(P25:P26) -> 208.2
B36: Total book capitalization | I36: =I30+I35 -> 2281.68 | J36: =J30+J35 -> 2352.95 | K36: =K30+K35 -> 2609.6 | L36: =L30+L35 -> 2739.6597 | M36: =M30+M35 -> 2806.193 | N36: =N30+N35 -> 2851.3995 | O36: =O30+O35 -> 2873.5187 | P36: =P30+P35 -> 2900.3294
B37: Total debt / total book capitalization | I37: =IF(ISERROR(I35/I36),datareq, I35/I36) -> 0.57637355 | J37: =IF(ISERROR(J35/J36),datareq, J35/J36) -> 0.49775813 | K37: =IF(ISERROR(K35/K36),datareq, K35/K36) -> 0.40818516 | L37: =IF(ISERROR(L35/L36),datareq, L35/L36) -> 0.35865097 | M37: =IF(ISERROR(M35/M36),datareq, M35/M36) -> 0.2951359 | N37: =IF(ISERROR(N35/N36),datareq, N35/N36) -> 0.22567437 | O37: =IF(ISERROR(O35/O36),datareq, O35/O36) -> 0.14864823 | P37: =IF(ISERROR(P35/P36),datareq, P35/P36) -> 0.071784951
B39: EBITDA | I39: =IS!I12 -> 628.34 | J39: =IS!J12 -> 661.8 | K39: =IS!K12 -> 701.4737 | L39: =IS!L12 -> 679.03743 | M39: =IS!M12 -> 717.06353 | N39: =IS!N12 -> 754.35083 | O39: =IS!O12 -> 790.55967 | P39: =IS!P12 -> 825.3443 | Q39: (1 point)
B40: Total debt / EBITDA | I40: =IF(ISERROR(I35/I39),datareq,I35/I39) -> 2.0929751 | J40: =IF(ISERROR(J35/J39),datareq,J35/J39) -> 1.7697189 | K40: =IF(ISERROR(K35/K39),datareq,K35/K39) -> 1.5185174 | L40: =IF(ISERROR(L35/L39),datareq,L35/L39) -> 1.4470213 | M40: =IF(ISERROR(M35/M39),datareq,M35/M39) -> 1.1549999 | N40: =IF(ISERROR(N35/N39),datareq,N35/N39) -> 0.85303516 | O40: =IF(ISERROR(O35/O39),datareq,O35/O39) -> 0.54030517 | P40: =IF(ISERROR(P35/P39),datareq,P35/P39) -> 0.25225836
B41: Interest expense | I41: =IS!I18 -> 55 | J41: =IS!J18 -> 53.2 | K41: =IS!K18 -> 45.89 | L41: =IS!L18 -> 79.076625 | M41: =IS!M18 -> 68.967274 | N41: =IS!N18 -> 55.005797 | O41: =IS!O18 -> 39.763851 | P41: =IS!P18 -> 25.144958
B42: EBITDA coverage | I42: =IF(ISERROR(I39/I41),datareq,I39/I41) -> 11.424364 | J42: =IF(ISERROR(J39/J41),datareq,J39/J41) -> 12.43985 | K42: =IF(ISERROR(K39/K41),datareq,K39/K41) -> 15.285982 | L42: =IF(ISERROR(L39/L41),datareq,L39/L41) -> 8.5870816 | M42: =IF(ISERROR(M39/M41),datareq,M39/M41) -> 10.397156 | N42: =IF(ISERROR(N39/N41),datareq,N39/N41) -> 13.714024 | O42: =IF(ISERROR(O39/O41),datareq,O39/O41) -> 19.881366 | P42: =IF(ISERROR(P39/P41),datareq,P39/P41) -> 32.823451
XX1000: 127155

Sheet WC
B1: ="Working Capital Schedule for "&CoName -> Working Capital Schedule for Sharang Corporation
B2: =subhead -> Dollars in millions, except per share data
H3: FYE Adjustment | I3: -2 | J3: =I3+1 -> -1 | K3: =J3+1 -> 0 | L3: =K3+1 -> 1 | M3: =L3+1 -> 2 | N3: =M3+1 -> 3 | O3: =N3+1 -> 4 | P3: =O3+1 -> 5
I5: ="Historical Year Ending "&TEXT(FYE,"Mmmm dd") & "," -> Historical Year Ending December 31, | L5: ="Projected Year Ending "&TEXT(FYE,"Mmmm Dd,") -> Projected Year Ending December 31,
I6: =YEAR(FYE)+I3 -> 2021 | J6: =YEAR(FYE)+J3 -> 2022 | K6: =YEAR(FYE)+K3 -> 2023 | L6: =YEAR(FYE)+L3 -> 2024 | M6: =YEAR(FYE)+M3 -> 2025 | N6: =YEAR(FYE)+N3 -> 2026 | O6: =YEAR(FYE)+O3 -> 2027 | P6: =YEAR(FYE)+P3 -> 2028
B8: Sales | I8: =IS!I7 -> 2956.34 | J8: =IS!J7 -> 3245.8 | K8: =IS!K7 -> 3462.71 | L8: =IS!L7 -> 3670.4726 | M8: =IS!M7 -> 3876.0191 | N8: =IS!N7 -> 4077.5721 | O8: =IS!O7 -> 4273.2955 | P8: =IS!P7 -> 4461.3205
B9: Cost of goods sold (excluding depreciation) | I9: =IS!I8 -> 1452 | J9: =IS!J8 -> 1695 | K9: =IS!K8 -> 1835.2363 | L9: =IS!L8 -> 1960.0324 | M9: =IS!M8 -> 2069.7942 | N9: =IS!N8 -> 2177.4235 | O9: =IS!O8 -> 2281.9398 | P9: =IS!P8 -> 2382.3452
B11: Working capital balances
C12: =BS!B9 -> Accounts receivable, net | I12: =BS!I9 -> 375 | J12: =BS!J9 -> 362 | K12: =BS!K9 -> 386.3 | L12: =L8*L26/365 -> 442.46793 | M12: =M8*M26/365 -> 456.6269 | N12: =N8*N26/365 -> 469.20007 | O12: =O8*O26/365 -> 480.01402 | P12: =P8*P26/365 -> 488.91184 | Q12: (5 points)
C13: =BS!B10 -> Inventories | I13: =BS!I10 -> 441 | J13: =BS!J10 -> 465 | K13: =BS!K10 -> 476.7 | L13: =L9*L27/365 -> 515.51536 | M13: =M9*M27/365 -> 538.71355 | N13: =N9*N27/365 -> 560.76111 | O13: =O9*O27/365 -> 581.42576 | P13: =P9*P27/365 -> 600.48152 | Q13: (5 points)
C14: =BS!B11 -> Other current assets | I14: =BS!I11 -> 110.5 | J14: =BS!J11 -> 117 | K14: =BS!K11 -> 102.7 | L14: =L8*L28 -> 110.11418 | M14: =M8*M28 -> 116.28057 | N14: =N8*N28 -> 122.32716 | O14: =O8*O28 -> 128.19887 | P14: =P8*P28 -> 133.83962 | Q14: (5 points)
D15: Total non-cash current assets | I15: =SUM(I12:I14) -> 926.5 | J15: =SUM(J12:J14) -> 944 | K15: =SUM(K12:K14) -> 965.7 | L15: =SUM(L12:L14) -> 1068.0975 | M15: =SUM(M12:M14) -> 1111.621 | N15: =SUM(N12:N14) -> 1152.2883 | O15: =SUM(O12:O14) -> 1189.6386 | P15: =SUM(P12:P14) -> 1223.233
C17: =BS!B21 -> Accounts payable | I17: =BS!I21 -> 276.4 | J17: =BS!J21 -> 300.2 | K17: =BS!K21 -> 305.8 | L17: =L9*L30/365 -> 327.56705 | M17: =M9*M30/365 -> 351.58148 | N17: =N9*N30/365 -> 375.82926 | O17: =O9*O30/365 -> 400.12095 | P17: =P9*P30/365 -> 424.25325 | Q17: (5 points)
C18: =BS!B22 -> Other current liabilities | I18: =BS!I22 -> 414 | J18: =BS!J22 -> 403.4 | K18: =BS!K22 -> 431.7 | L18: =L9*L31 -> 450.80744 | M18: =M9*M31 -> 476.05266 | N18: =N9*N31 -> 500.8074 | O18: =O9*O31 -> 524.84616 | P18: =P9*P31 -> 547.93939 | Q18: (5 points)
D19: Total non-debt current liabilities | I19: =SUM(I17:I18) -> 690.4 | J19: =SUM(J17:J18) -> 703.6 | K19: =SUM(K17:K18) -> 737.5 | L19: =SUM(L17:L18) -> 778.3745 | M19: =SUM(M17:M18) -> 827.63414 | N19: =SUM(N17:N18) -> 876.63666 | O19: =SUM(O17:O18) -> 924.96711 | P19: =SUM(P17:P18) -> 972.19263
B21: Net working capital / (deficit) | I21: =I15-I19 -> 236.1 | J21: =J15-J19 -> 240.4 | K21: =K15-K19 -> 228.2 | L21: =L15-L19 -> 289.72297 | M21: =M15-M19 -> 283.98689 | N21: =N15-N19 -> 275.65169 | O21: =O15-O19 -> 264.67153 | P21: =P15-P19 -> 251.04034
B23: (Increase) / decrease in working capital | J23: =I21-J21 -> -4.3 | K23: =J21-K21 -> 12.2 | L23: =K21-L21 -> -61.522972 | M23: =L21-M21 -> 5.7360818 | N23: =M21-N21 -> 8.3351995 | O23: =N21-O21 -> 10.980158 | P23: =O21-P21 -> 13.631195
B25: Ratios and assumptions
C26: =C12&" (days sales outstanding)" -> Accounts receivable, net (days sales outstanding) | I26: =IF(ISERROR(I12/I8)*Days, datareq, (I12/I8)*Days) -> 46.298802 | J26: =IF(ISERROR(J12/J8)*Days, datareq, (J12/J8)*Days) -> 40.707992 | K26: =IF(ISERROR(K12/K8)*Days, datareq, (K12/K8)*Days) -> 40.719408 | L26: {=DSO} -> 44 | M26: 43 | N26: 42 | O26: 41 | P26: 40
C27: =C13&" (days inventory held)" -> Inventories (days inventory held) | I27: =IF(ISERROR(I13/I9), datareq, I13/I9*Days) -> 110.85744 | J27: =IF(ISERROR(J13/J9), datareq, J13/J9*Days) -> 100.13274 | K27: =IF(ISERROR(K13/K9), datareq, K13/K9*Days) -> 94.808227 | L27: {=DIH} -> 96 | M27: 95 | N27: 94 | O27: 93 | P27: 92
C28: =C14&" (as % of sales)" -> Other current assets (as % of sales) | I28: =IF(ISERROR(I14/I8), datareq, I14/I8) -> 0.037377298 | J28: =IF(ISERROR(J14/J8), datareq, J14/J8) -> 0.036046583 | K28: =IF(ISERROR(K14/K8), datareq, K14/K8) -> 0.029658851 | L28: {=CAofSales} -> 0.03 | M28: 0.03 | N28: 0.03 | O28: 0.03 | P28: 0.03
C30: =C17&" (days outstanding)" -> Accounts payable (days outstanding) | I30: =IF(ISERROR(I17/I9), datareq, I17/I9*Days) -> 69.480716 | J30: =IF(ISERROR(J17/J9), datareq, J17/J9*Days) -> 64.644838 | K30: =IF(ISERROR(K17/K9), datareq, K17/K9*Days) -> 60.818871 | L30: {=DPO} -> 61 | M30: 62 | N30: 63 | O30: 64 | P30: 65
C31: =C18&" (as % cost of sales)" -> Other current liabilities (as % cost of sales) | I31: =IF(ISERROR(I18/I9),datareq,I18/I9) -> 0.28512397 | J31: =IF(ISERROR(J18/J9),datareq,J18/J9) -> 0.2379941 | K31: =IF(ISERROR(K18/K9),datareq,K18/K9) -> 0.23522856 | L31: {=OtherCLofSales} -> 0.23 | M31: 0.23 | N31: 0.23 | O31: 0.23 | P31: 0.23
B33: Cash flows by individual accounts
C34: =C12 -> Accounts receivable, net | J34: =I12-J12 -> 13 | K34: =J12-K12 -> -24.3 | L34: =K12-L12 -> -56.16793 | M34: =L12-M12 -> -14.158974 | N34: =M12-N12 -> -12.573169 | O34: =N12-O12 -> -10.813945 | P34: =O12-P12 -> -8.8978208 | Q34: (5 points for the section)
C35: =C13 -> Inventories | J35: =I13-J13 -> -24 | K35: =J13-K13 -> -11.7 | L35: =K13-L13 -> -38.815363 | M35: =L13-M13 -> -23.198191 | N35: =M13-N13 -> -22.047561 | O35: =N13-O13 -> -20.664644 | P35: =O13-P13 -> -19.05576
C36: =C14 -> Other current assets | J36: =I14-J14 -> -6.5 | K36: =J14-K14 -> 14.3 | L36: =K14-L14 -> -7.414178 | M36: =L14-M14 -> -6.166394 | N36: =M14-N14 -> -6.0465897 | O36: =N14-O14 -> -5.8717038 | P36: =O14-P14 -> -5.6407501
C37: =C17 -> Accounts payable | J37: =J17-I17 -> 23.8 | K37: =K17-J17 -> 5.6 | L37: =L17-K17 -> 21.767053 | M37: =M17-L17 -> 24.014424 | N37: =N17-M17 -> 24.247781 | O37: =O17-N17 -> 24.291694 | P37: =P17-O17 -> 24.132295
C38: =C18 -> Other current liabilities | J38: =J18-I18 -> -10.6 | K38: =K18-J18 -> 28.3 | L38: =L18-K18 -> 19.107445 | M38: =M18-L18 -> 25.245217 | N38: =N18-M18 -> 24.754738 | O38: =O18-N18 -> 24.038755 | P38: =P18-O18 -> 23.093231
B39: =B23 -> (Increase) / decrease in working capital | J39: =SUM(J34:J38) -> -4.3 | K39: =SUM(K34:K38) -> 12.2 | L39: =SUM(L34:L38) -> -61.522972 | M39: =SUM(M34:M38) -> 5.7360818 | N39: =SUM(N34:N38) -> 8.3351995 | O39: =SUM(O34:O38) -> 10.980158 | P39: =SUM(P34:P38) -> 13.631195
XX1000: 127155

Sheet Dep
B1: ="Depreciation Schedule for "&CoName -> Depreciation Schedule for Sharang Corporation
B2: =subhead -> Dollars in millions, except per share data
H3: FYE Adjustment | I3: -2 | J3: =I3+1 -> -1 | K3: =J3+1 -> 0 | L3: =K3+1 -> 1 | M3: =L3+1 -> 2 | N3: =M3+1 -> 3 | O3: =N3+1 -> 4 | P3: =O3+1 -> 5
I5: ="Historical Year Ending "&TEXT(FYE,"Mmmm dd") & "," -> Historical Year Ending December 31, | L5: ="Projected Year Ending "&TEXT(FYE,"Mmmm Dd,") -> Projected Year Ending December 31,
I6: =YEAR(FYE)+I3 -> 2021 | J6: =YEAR(FYE)+J3 -> 2022 | K6: =YEAR(FYE)+K3 -> 2023 | L6: =YEAR(FYE)+L3 -> 2024 | M6: =YEAR(FYE)+M3 -> 2025 | N6: =YEAR(FYE)+N3 -> 2026 | O6: =YEAR(FYE)+O3 -> 2027 | P6: =YEAR(FYE)+P3 -> 2028
B8: Sales | I8: =IS!I7 -> 2956.34 | J8: =IS!J7 -> 3245.8 | K8: =IS!K7 -> 3462.71 | L8: =IS!L7 -> 3670.4726 | M8: =IS!M7 -> 3876.0191 | N8: =IS!N7 -> 4077.5721 | O8: =IS!O7 -> 4273.2955 | P8: =IS!P7 -> 4461.3205
B9: Capital expenditures | I9: 85.8 | J9: =82.4+120 -> 202.4 | K9: =89+120+185 -> 394 | L9: =L8*L10 -> 183.52363 | M9: =M8*M10 -> 193.80095 | N9: =N8*N10 -> 203.8786 | O9: =O8*O10 -> 213.66478 | P9: =P8*P10 -> 223.06603
D10: Capital expenditures as % of sales | I10: =IF(ISERROR(I9/I8),datareq,I9/I8) -> 0.029022372 | J10: =IF(ISERROR(J9/J8),datareq,J9/J8) -> 0.062357508 | K10: =IF(ISERROR(K9/K8),datareq,K9/K8) -> 0.11378371 | L10: {=CapexofSales} -> 0.05 | M10: 0.05 | N10: 0.05 | O10: 0.05 | P10: 0.05
B12: Beginning net PP&E | L12: =K16 -> 871 | M12: =L16 -> 957.2648 | N12: =M16 -> 1026.8552 | O12: =N16 -> 1078.1175 | P12: =O16 -> 1109.3415 | Q12: (1 point)
C13: Capital expenditures | L13: =L9 -> 183.52363 | M13: =M9 -> 193.80095 | N13: =N9 -> 203.8786 | O13: =O9 -> 213.66478 | P13: =P9 -> 223.06603 | Q13: (1 point)
C14: (Depreciation expense) | L14: =-L39 -> -97.258831 | M14: =-M39 -> -124.21059 | N14: =-N39 -> -152.61627 | O14: =-O39 -> -182.4408 | P14: =-P39 -> -213.63585 | Q14: (2 points)
C15: (Asset sales and write-offs) | L15: 0 | M15: 0 | N15: 0 | O15: 0 | P15: 0
B16: Ending net PP&E | I16: =BS!I14 -> 487 | J16: =BS!J14 -> 560 | K16: =BS!K14 -> 871 | L16: =SUM(L12:L15) -> 957.2648 | M16: =SUM(M12:M15) -> 1026.8552 | N16: =SUM(N12:N15) -> 1078.1175 | O16: =SUM(O12:O15) -> 1109.3415 | P16: =SUM(P12:P15) -> 1118.7717
B18: Projected Depreciation of Existing PP&E | L18: =$L$6 -> 2024 | M18: =$M$6 -> 2025 | N18: =$N$6 -> 2026 | O18: =$O$6 -> 2027 | P18: =$P$6 -> 2028
B20: Existing PP&E, net | F20: =K16 -> 871 | L20: =IF($F$26=1,IF((L18-$K$6)<=$F$24,$F$22*1/$F$24,0),IF($F$26=2,SYD($F$22,0,$F$24,L18-$K$6),"method error")) -> 84.15 | M20: =IF($F$26=1,IF((M18-$K$6)<=$F$24,$F$22*1/$F$24,0),IF($F$26=2,SYD($F$22,0,$F$24,M18-$K$6),"method error")) -> 84.15 | N20: =IF($F$26=1,IF((N18-$K$6)<=$F$24,$F$22*1/$F$24,0),IF($F$26=2,SYD($F$22,0,$F$24,N18-$K$6),"method error")) -> 84.15 | O20: =IF($F$26=1,IF((O18-$K$6)<=$F$24,$F$22*1/$F$24,0),IF($F$26=2,SYD($F$22,0,$F$24,O18-$K$6),"method error")) -> 84.15 | P20: =IF($F$26=1,IF((P18-$K$6)<=$F$24,$F$22*1/$F$24,0),IF($F$26=2,SYD($F$22,0,$F$24,P18-$K$6),"method error")) -> 84.15
C21: Land | F21: -29.5
C22: Depreciable PP&E | F22: =F20+F21 -> 841.5
B24: Useful life (years) | F24: 10
B25: Depreciation Method | F25: Straight Line | G25: (1 point)
B26: Depreciation Method | F26: =IF(F25="straight line", 1,2) -> 1
B29: Projected Depreciation of CapEx* | L29: =$L$6 -> 2024 | M29: =$M$6 -> 2025 | N29: =$N$6 -> 2026 | O29: =$O$6 -> 2027 | P29: =$P$6 -> 2028
D31: Year | E31: CapEx | F31: Useful life (years)
D32: {=TRANSPOSE(L6:P6)} -> 2024 | E32: {=TRANSPOSE(L9:P9)} -> 183.52363 | F32: 7 | G32: (1 point) | L32: =IF((L$29-$D32)<=$F32,IF((L$29-$D32)=0, $E32*1/$F32/2,$E32*1/$F32),0) -> 13.108831 | M32: =IF((M$29-$D32)<=$F32,IF((M$29-$D32)=0, $E32*1/$F32/2,$E32*1/$F32),0) -> 26.217661 | N32: =IF((N$29-$D32)<=$F32,IF((N$29-$D32)=0, $E32*1/$F32/2,$E32*1/$F32),0) -> 26.217661 | O32: =IF((O$29-$D32)<=$F32,IF((O$29-$D32)=0, $E32*1/$F32/2,$E32*1/$F32),0) -> 26.217661 | P32: =IF((P$29-$D32)<=$F32,IF((P$29-$D32)=0, $E32*1/$F32/2,$E32*1/$F32),0) -> 26.217661
D33: 2025 | E33: 193.80095 | F33: =F32 -> 7 | M33: =IF((M$29-$D33)<=$F33,IF((M$29-$D33)=0, $E33*1/$F33/2,$E33*1/$F33),0) -> 13.842925 | N33: =IF((N$29-$D33)<=$F33,IF((N$29-$D33)=0, $E33*1/$F33/2,$E33*1/$F33),0) -> 27.68585 | O33: =IF((O$29-$D33)<=$F33,IF((O$29-$D33)=0, $E33*1/$F33/2,$E33*1/$F33),0) -> 27.68585 | P33: =IF((P$29-$D33)<=$F33,IF((P$29-$D33)=0, $E33*1/$F33/2,$E33*1/$F33),0) -> 27.68585
D34: 2026 | E34: 203.8786 | F34: =F33 -> 7 | N34: =IF((N$29-$D34)<=$F34,IF((N$29-$D34)=0, $E34*1/$F34/2,$E34*1/$F34),0) -> 14.562757 | O34: =IF((O$29-$D34)<=$F34,IF((O$29-$D34)=0, $E34*1/$F34/2,$E34*1/$F34),0) -> 29.125515 | P34: =IF((P$29-$D34)<=$F34,IF((P$29-$D34)=0, $E34*1/$F34/2,$E34*1/$F34),0) -> 29.125515
D35: 2027 | E35: 213.66478 | F35: =F34 -> 7 | O35: =IF((O$29-$D35)<=$F35,IF((O$29-$D35)=0, $E35*1/$F35/2,$E35*1/$F35),0) -> 15.26177 | P35: =IF((P$29-$D35)<=$F35,IF((P$29-$D35)=0, $E35*1/$F35/2,$E35*1/$F35),0) -> 30.523539
D36: 2028 | E36: 223.06603 | F36: =F35 -> 7 | P36: =IF((P$29-$D36)<=$F36,IF((P$29-$D36)=0, $E36*1/$F36/2,$E36*1/$F36),0) -> 15.933288
L37: =SUM(L32:L36) -> 13.108831 | M37: =SUM(M32:M36) -> 40.060587 | N37: =SUM(N32:N36) -> 68.466269 | O37: =SUM(O32:O36) -> 98.290796 | P37: =SUM(P32:P36) -> 129.48585
B39: Total depreciation expense | I39: =IS!I14 -> 82.2 | J39: =IS!J14 -> 84.7 | K39: =IS!K14 -> 88.7 | L39: =L20+L37 -> 97.258831 | M39: =M20+M37 -> 124.21059 | N39: =N20+N37 -> 152.61627 | O39: =O20+O37 -> 182.4408 | P39: =P20+P37 -> 213.63585
B41: Depreciation expense as a % of PP&E | I41: =I39/BS!I14 -> 0.1687885 | J41: =J39/BS!J14 -> 0.15125 | K41: =K39/BS!K14 -> 0.10183697 | L41: =L39/L16 -> 0.10160076 | M41: =M39/M16 -> 0.12096213 | N41: =N39/N16 -> 0.1415581 | O41: =O39/O16 -> 0.16445864 | P41: =P39/P16 -> 0.19095573
B43: *Projected depreciation expense on future capex is assumed to use the straight line method adjusted for 1/2 year convention in the first year.
XX1000: 127155

Sheet Amort
B1: ="Amortization Schedule for "&CoName -> Amortization Schedule for Sharang Corporation
B2: =subhead -> Dollars in millions, except per share data
H3: FYE Adjustment | I3: -2 | J3: =I3+1 -> -1 | K3: =J3+1 -> 0 | L3: =K3+1 -> 1 | M3: =L3+1 -> 2 | N3: =M3+1 -> 3 | O3: =N3+1 -> 4 | P3: =O3+1 -> 5
I5: ="Historical Year Ending "&TEXT(FYE,"Mmmm dd") & "," -> Historical Year Ending December 31, | L5: ="Projected Year Ending "&TEXT(FYE,"Mmmm Dd,") -> Projected Year Ending December 31,
I6: =YEAR(FYE)+I3 -> 2021 | J6: =YEAR(FYE)+J3 -> 2022 | K6: =YEAR(FYE)+K3 -> 2023 | L6: =YEAR(FYE)+L3 -> 2024 | M6: =YEAR(FYE)+M3 -> 2025 | N6: =YEAR(FYE)+N3 -> 2026 | O6: =YEAR(FYE)+O3 -> 2027 | P6: =YEAR(FYE)+P3 -> 2028
B8: Sales | I8: =IS!I7 -> 2956.34 | J8: =IS!J7 -> 3245.8 | K8: =IS!K7 -> 3462.71 | L8: =IS!L7 -> 3670.4726 | M8: =IS!M7 -> 3876.0191 | N8: =IS!N7 -> 4077.5721 | O8: =IS!O7 -> 4273.2955 | P8: =IS!P7 -> 4461.3205
B9: Additions to intangibles | I9: =111.1-36.9 -> 74.2 | J9: =49.3-111.1 -> -61.8 | K9: =50.8-49.3 -> 1.5 | L9: =L8*L10 -> 5.4415299 | M9: =M8*M10 -> 5.2717941 | N9: =N8*N10 -> 5.0880068 | O9: =O8*O10 -> 4.8919552 | P9: =P8*P10 -> 4.6855057
D10: Additions as % of sales | I10: =IF(ISERROR(I9/I8),datareq,I9/I8) -> 0.025098602 | J10: =IF(ISERROR(J9/J8),datareq,J9/J8) -> -0.01903999 | K10: =IF(ISERROR(K9/K8),datareq,K9/K8) -> 0.00043318672 | L10: {=IntangAdd} -> 0.0014825148 | M10: 0.0013601053 | N10: 0.001247803 | O10: 0.0011447734 | P10: 0.0010502509
B12: Beginning intangibles | L12: =K16 -> 36.1 | M12: =L16 -> 39.171915 | N12: =M16 -> 41.850899 | O12: =N16 -> 44.130268 | P12: =O16 -> 46.005668 | Q12: (1 point)
C13: Additions to intangibles | L13: =L9 -> 5.4415299 | M13: =M9 -> 5.2717941 | N13: =N9 -> 5.0880068 | O13: =O9 -> 4.8919552 | P13: =P9 -> 4.6855057 | Q13: (1 point)
C14: (Amortization expense) | L14: =-L36 -> -2.3696152 | M14: =-M36 -> -2.5928095 | N14: =-N36 -> -2.8086386 | O14: =-O36 -> -3.0165545 | P14: =-P36 -> -3.216085 | Q14: (1 point)
C15: (Write-offs) | L15: 0 | M15: =L15 -> 0 | N15: =M15 -> 0 | O15: =N15 -> 0 | P15: =O15 -> 0
B16: Ending intangibles | I16: =BS!I15 -> 98 | J16: =BS!J15 -> 35 | K16: =BS!K15 -> 36.1 | L16: =SUM(L12:L15) -> 39.171915 | M16: =SUM(M12:M15) -> 41.850899 | N16: =SUM(N12:N15) -> 44.130268 | O16: =SUM(O12:O15) -> 46.005668 | P16: =SUM(P12:P15) -> 47.475089
B18: Projected Amortization of Existing Intangibles | L18: =$L$6 -> 2024 | M18: =$M$6 -> 2025 | N18: =$N$6 -> 2026 | O18: =$O$6 -> 2027 | P18: =$P$6 -> 2028
B20: Existing Intangibles | F20: =BS!K15 -> 36.1 | L20: =IF($F$23=1,IF((L18-$K$6)<=$F$22,$F$20*1/$F$22,0),IF($F$23=2,SYD($F$20,0,$F$22,L18-$K$6),"method error")) -> 2.25625 | M20: =IF($F$23=1,IF((M18-$K$6)<=$F$22,$F$20*1/$F$22,0),IF($F$23=2,SYD($F$20,0,$F$22,M18-$K$6),"method error")) -> 2.25625 | N20: =IF($F$23=1,IF((N18-$K$6)<=$F$22,$F$20*1/$F$22,0),IF($F$23=2,SYD($F$20,0,$F$22,N18-$K$6),"method error")) -> 2.25625 | O20: =IF($F$23=1,IF((O18-$K$6)<=$F$22,$F$20*1/$F$22,0),IF($F$23=2,SYD($F$20,0,$F$22,O18-$K$6),"method error")) -> 2.25625 | P20: =IF($F$23=1,IF((P18-$K$6)<=$F$22,$F$20*1/$F$22,0),IF($F$23=2,SYD($F$20,0,$F$22,P18-$K$6),"method error")) -> 2.25625
B22: Useful life (years) | F22: 16
B23: Amortization Method | F23: 1 | G23: (1 point)
B26: Projected Amortization of Additional Intangibles* | L26: =$L$6 -> 2024 | M26: =$M$6 -> 2025 | N26: =$N$6 -> 2026 | O26: =$O$6 -> 2027 | P26: =$P$6 -> 2028
D28: Year | E28: Additions | F28: Useful life (years)
D29: {=TRANSPOSE(L6:P6)} -> 2024 | E29: {=TRANSPOSE(L9:P9)} -> 5.4415299 | F29: 24 | L29: =IF((L$26-$D29)<=$F29,IF((L$26-$D29)=0, $E29*1/$F29/2,$E29*1/$F29),0) -> 0.11336521 | M29: =IF((M$26-$D29)<=$F29,IF((M$26-$D29)=0, $E29*1/$F29/2,$E29*1/$F29),0) -> 0.22673041 | N29: =IF((N$26-$D29)<=$F29,IF((N$26-$D29)=0, $E29*1/$F29/2,$E29*1/$F29),0) -> 0.22673041 | O29: =IF((O$26-$D29)<=$F29,IF((O$26-$D29)=0, $E29*1/$F29/2,$E29*1/$F29),0) -> 0.22673041 | P29: =IF((P$26-$D29)<=$F29,IF((P$26-$D29)=0, $E29*1/$F29/2,$E29*1/$F29),0) -> 0.22673041
D30: 2025 | E30: 5.2717941 | F30: =F29 -> 24 | M30: =IF((M$26-$D30)<=$F30,IF((M$26-$D30)=0, $E30*1/$F30/2,$E30*1/$F30),0) -> 0.10982904 | N30: =IF((N$26-$D30)<=$F30,IF((N$26-$D30)=0, $E30*1/$F30/2,$E30*1/$F30),0) -> 0.21965809 | O30: =IF((O$26-$D30)<=$F30,IF((O$26-$D30)=0, $E30*1/$F30/2,$E30*1/$F30),0) -> 0.21965809 | P30: =IF((P$26-$D30)<=$F30,IF((P$26-$D30)=0, $E30*1/$F30/2,$E30*1/$F30),0) -> 0.21965809
D31: 2026 | E31: 5.0880068 | F31: =F30 -> 24 | N31: =IF((N$26-$D31)<=$F31,IF((N$26-$D31)=0, $E31*1/$F31/2,$E31*1/$F31),0) -> 0.10600014 | O31: =IF((O$26-$D31)<=$F31,IF((O$26-$D31)=0, $E31*1/$F31/2,$E31*1/$F31),0) -> 0.21200028 | P31: =IF((P$26-$D31)<=$F31,IF((P$26-$D31)=0, $E31*1/$F31/2,$E31*1/$F31),0) -> 0.21200028
D32: 2027 | E32: 4.8919552 | F32: =F31 -> 24 | O32: =IF((O$26-$D32)<=$F32,IF((O$26-$D32)=0, $E32*1/$F32/2,$E32*1/$F32),0) -> 0.10191573 | P32: =IF((P$26-$D32)<=$F32,IF((P$26-$D32)=0, $E32*1/$F32/2,$E32*1/$F32),0) -> 0.20383147
D33: 2028 | E33: 4.6855057 | F33: =F32 -> 24 | P33: =IF((P$26-$D33)<=$F33,IF((P$26-$D33)=0, $E33*1/$F33/2,$E33*1/$F33),0) -> 0.097614702
L34: =SUM(L29:L33) -> 0.11336521 | M34: =SUM(M29:M33) -> 0.33655946 | N34: =SUM(N29:N33) -> 0.55238864 | O34: =SUM(O29:O33) -> 0.76030452 | P34: =SUM(P29:P33) -> 0.95983495
B36: Total Amortization Expense | L36: =L20+L34 -> 2.3696152 | M36: =M20+M34 -> 2.5928095 | N36: =N20+N34 -> 2.8086386 | O36: =O20+O34 -> 3.0165545 | P36: =P20+P34 -> 3.216085
B39: *Projected amortization expense on future additional intangibles is assumed to use the straight line method adjusted for 1/2 year convention in the first year.
XX1000: 127155

Sheet Other
B1: ="Other Long-Term Items Schedule for "&CoName -> Other Long-Term Items Schedule for Sharang Corporation
B2: =subhead -> Dollars in millions, except per share data
H4: FYE Adjustment | I4: -2 | J4: =I4+1 -> -1 | K4: =J4+1 -> 0 | L4: =K4+1 -> 1 | M4: =L4+1 -> 2 | N4: =M4+1 -> 3 | O4: =N4+1 -> 4 | P4: =O4+1 -> 5
I6: ="Historical Year Ending "&TEXT(FYE,"Mmmm dd") & "," -> Historical Year Ending December 31, | L6: ="Projected Year Ending "&TEXT(FYE,"Mmmm Dd,") -> Projected Year Ending December 31,
I7: =YEAR(FYE)+I4 -> 2021 | J7: =YEAR(FYE)+J4 -> 2022 | K7: =YEAR(FYE)+K4 -> 2023 | L7: =YEAR(FYE)+L4 -> 2024 | M7: =YEAR(FYE)+M4 -> 2025 | N7: =YEAR(FYE)+N4 -> 2026 | O7: =YEAR(FYE)+O4 -> 2027 | P7: =YEAR(FYE)+P4 -> 2028
B10: Assets
C11: =BS!B16 -> Indefinite life intangibles (trademark, brand) | I11: =BS!I16 -> 278.3 | J11: =BS!J16 -> 200.75 | K11: =BS!K16 -> 200.8 | L11: =K11 -> 200.8 | M11: =L11 -> 200.8 | N11: =M11 -> 200.8 | O11: =N11 -> 200.8 | P11: =O11 -> 200.8
C12: =BS!B17 -> Goodwill | I12: =BS!I17 -> 1245.88 | J12: =BS!J17 -> 1478 | K12: =BS!K17 -> 1415 | L12: =K12 -> 1415 | M12: =L12 -> 1415 | N12: =M12 -> 1415 | O12: =N12 -> 1415 | P12: =O12 -> 1415
C13: =BS!B18 -> Other long-term assets | I13: =BS!I18 -> 132.8 | J13: =BS!J18 -> 144.9 | K13: =BS!K18 -> 145 | L13: =K13 -> 145 | M13: =L13 -> 145 | N13: =M13 -> 145 | O13: =N13 -> 145 | P13: =O13 -> 145
D14: Total other long-term assets: | I14: =SUM(I11:I13) -> 1656.98 | J14: =SUM(J11:J13) -> 1823.65 | K14: =SUM(K11:K13) -> 1760.8 | L14: =SUM(L11:L13) -> 1760.8 | M14: =SUM(M11:M13) -> 1760.8 | N14: =SUM(N11:N13) -> 1760.8 | O14: =SUM(O11:O13) -> 1760.8 | P14: =SUM(P11:P13) -> 1760.8
D15: (Increase) / decrease in other assets: | J15: =I14-J14 -> -166.67 | K15: =J14-K14 -> 62.85 | L15: =K14-L14 -> 0 | M15: =L14-M14 -> 0 | N15: =M14-N14 -> 0 | O15: =N14-O14 -> 0 | P15: =O14-P14 -> 0
B17: Liabilities
C18: =BS!B27 -> Other long-term liabilities | I18: =BS!I27 -> 238.2 | J18: =BS!J27 -> 351.1 | K18: =BS!K27 -> 342.3 | L18: =K18 -> 342.3 | M18: =L18 -> 342.3 | N18: =M18 -> 342.3 | O18: =N18 -> 342.3 | P18: =O18 -> 342.3
D19: Total other long-term liabilities: | I19: =I18 -> 238.2 | J19: =J18 -> 351.1 | K19: =K18 -> 342.3 | L19: =L18 -> 342.3 | M19: =M18 -> 342.3 | N19: =N18 -> 342.3 | O19: =O18 -> 342.3 | P19: =P18 -> 342.3
D20: Increase / (decrease) in other long-term liabilities: | J20: =J19-I19 -> 112.9 | K20: =K19-J19 -> -8.8 | L20: =L19-K19 -> 0 | M20: =M19-L19 -> 0 | N20: =N19-M19 -> 0 | O20: =O19-N19 -> 0 | P20: =P19-O19 -> 0
B22: Change in other long-term assets and liabilities | J22: =J15+J20 -> -53.77 | K22: =K15+K20 -> 54.05 | L22: =L15+L20 -> 0 | M22: =M15+M20 -> 0 | N22: =N15+N20 -> 0 | O22: =O15+O20 -> 0 | P22: =P15+P20 -> 0
XX1000: 127155

Sheet Equity
B1: ="Shareholders' Equity Schedule for "&CoName -> Shareholders' Equity Schedule for Sharang Corporation
B2: =subhead -> Dollars in millions, except per share data
H4: FYE Adjustment | I4: -2 | J4: =I4+1 -> -1 | K4: =J4+1 -> 0 | L4: =K4+1 -> 1 | M4: =L4+1 -> 2 | N4: =M4+1 -> 3 | O4: =N4+1 -> 4 | P4: =O4+1 -> 5
I6: ="Historical Year Ending "&TEXT(FYE,"Mmmm dd") & "," -> Historical Year Ending December 31, | L6: ="Projected Year Ending "&TEXT(FYE,"Mmmm Dd,") -> Projected Year Ending December 31,
I7: =YEAR(FYE)+I4 -> 2021 | J7: =YEAR(FYE)+J4 -> 2022 | K7: =YEAR(FYE)+K4 -> 2023 | L7: =YEAR(FYE)+L4 -> 2024 | M7: =YEAR(FYE)+M4 -> 2025 | N7: =YEAR(FYE)+N4 -> 2026 | O7: =YEAR(FYE)+O4 -> 2027 | P7: =YEAR(FYE)+P4 -> 2028
B9: Beginning equity balance | L9: =K13 -> 1544.4 | M9: =L13 -> 1757.0781 | N9: =M13 -> 1977.9847 | O9: =N13 -> 2207.9117 | P9: =O13 -> 2446.3752
C10: Net income | L10: =L17 -> 346.16911 | M10: =M17 -> 360.3562 | N10: =N17 -> 375.90864 | O10: =O17 -> 390.6269 | P10: =P17 -> 403.19654 | Q10: (1 point)
C11: Stock-based compensation expense | L11: 11.9 | M11: =L11 -> 11.9 | N11: =M11 -> 11.9 | O11: =N11 -> 11.9 | P11: =O11 -> 11.9
C12: Dividends | L12: =-L16 -> -145.39103 | M12: =-M16 -> -151.3496 | N12: =-N16 -> -157.88163 | O12: =-O16 -> -164.0633 | P12: =-P16 -> -169.34256 | Q12: (2 points)
B13: Ending equity balance | I13: =BS!I30 -> 966.58 | J13: =BS!J30 -> 1181.75 | K13: =BS!K30 -> 1544.4 | L13: =SUM(L9:L12) -> 1757.0781 | M13: =SUM(M9:M12) -> 1977.9847 | N13: =SUM(N9:N12) -> 2207.9117 | O13: =SUM(O9:O12) -> 2446.3753 | P13: =SUM(P9:P12) -> 2692.1292
B15: Dividend assumptions
C16: Dividends | I16: 116.7 | J16: 128.5 | K16: 141.3 | L16: =L18*L17 -> 145.39103 | M16: =M18*M17 -> 151.3496 | N16: =N18*N17 -> 157.88163 | O16: =O18*O17 -> 164.0633 | P16: =P18*P17 -> 169.34255
C17: Net income | I17: =IS!I23 -> 265.14 | J17: =IS!J23 -> 284.9 | K17: =IS!K23 -> 388.3837 | L17: =IS!L23 -> 346.16911 | M17: =IS!M23 -> 360.3562 | N17: =IS!N23 -> 375.90864 | O17: =IS!O23 -> 390.62692 | P17: =IS!P23 -> 403.19655
C18: Dividend payout ratio | I18: =IF(ISERROR(I16/I17),datareq,I16/I17) -> 0.44014483 | J18: =IF(ISERROR(J16/J17),datareq,J16/J17) -> 0.45103545 | K18: =IF(ISERROR(K16/K17),datareq,K16/K17) -> 0.36381547 | L18: 0.42 | M18: =L18 -> 0.42 | N18: =M18 -> 0.42 | O18: =N18 -> 0.42 | P18: =O18 -> 0.42
XX1000: 127155

Sheet CF
B1: ="Projected Cash Flow Statement for " & CoName -> Projected Cash Flow Statement for Sharang Corporation
B2: =subhead -> Dollars in millions, except per share data
H4: FYE Adjustment | I4: -2 | J4: =I4+1 -> -1 | K4: =J4+1 -> 0 | L4: =K4+1 -> 1 | M4: =L4+1 -> 2 | N4: =M4+1 -> 3 | O4: =N4+1 -> 4 | P4: =O4+1 -> 5
L6: ="Projected Year Ending "&TEXT(FYE,"Mmmm Dd,") -> Projected Year Ending December 31,
L7: =YEAR(FYE)+L4 -> 2024 | M7: =YEAR(FYE)+M4 -> 2025 | N7: =YEAR(FYE)+N4 -> 2026 | O7: =YEAR(FYE)+O4 -> 2027 | P7: =YEAR(FYE)+P4 -> 2028
B9: Operating activities
C10: Net Income | L10: =IS!L23 -> 346.16911 | M10: =IS!M23 -> 360.3562 | N10: =IS!N23 -> 375.90864 | O10: =IS!O23 -> 390.62692 | P10: =IS!P23 -> 403.19655 | Q10: (1 point)
C11: Stock-based compensation expense | L11: =Equity!L11 -> 11.9 | M11: =Equity!M11 -> 11.9 | N11: =Equity!N11 -> 11.9 | O11: =Equity!O11 -> 11.9 | P11: =Equity!P11 -> 11.9 | Q11: (1 point)
C12: Depreciation | L12: =Dep!L39 -> 97.258831 | M12: =Dep!M39 -> 124.21059 | N12: =Dep!N39 -> 152.61627 | O12: =Dep!O39 -> 182.4408 | P12: =Dep!P39 -> 213.63585 | Q12: (1 point)
C13: Amortization | L13: =Amort!L36 -> 2.3696152 | M13: =Amort!M36 -> 2.5928095 | N13: =Amort!N36 -> 2.8086386 | O13: =Amort!O36 -> 3.0165545 | P13: =Amort!P36 -> 3.216085 | Q13: (1 point)
C14: (Increase) / decrease in working capital | L14: =WC!L39 -> -61.522972 | M14: =WC!M39 -> 5.7360818 | N14: =WC!N39 -> 8.3351995 | O14: =WC!O39 -> 10.980158 | P14: =WC!P39 -> 13.631195 | Q14: (1 point)
C15: Change in other long-term assets and liabilities | L15: =Other!L22 -> 0 | M15: =Other!M22 -> 0 | N15: =Other!N22 -> 0 | O15: =Other!O22 -> 0 | P15: =Other!P22 -> 0 | Q15: (1 point)
D16: Cash flow from operating activities | L16: =SUM(L10:L15) -> 396.17458 | M16: =SUM(M10:M15) -> 504.79567 | N16: =SUM(N10:N15) -> 551.56874 | O16: =SUM(O10:O15) -> 598.96443 | P16: =SUM(P10:P15) -> 645.57968
B18: Investing activities
C19: Capital expenditures | L19: =-Dep!L9 -> -183.52363 | M19: =-Dep!M9 -> -193.80095 | N19: =-Dep!N9 -> -203.8786 | O19: =-Dep!O9 -> -213.66478 | P19: =-Dep!P9 -> -223.06603 | Q19: (1 point)
C20: Additions to intangibles | L20: =-Amort!L9 -> -5.4415299 | M20: =-Amort!M9 -> -5.2717941 | N20: =-Amort!N9 -> -5.0880068 | O20: =-Amort!O9 -> -4.8919552 | P20: =-Amort!P9 -> -4.6855057 | Q20: (1 point)
D21: Cash flow from investing activities | L21: =SUM(L19:L20) -> -188.96516 | M21: =SUM(M19:M20) -> -199.07275 | N21: =SUM(N19:N20) -> -208.96661 | O21: =SUM(O19:O20) -> -218.55673 | P21: =SUM(P19:P20) -> -227.75153
B23: Cash flow available for financing activities | L23: =L16+L21 -> 207.20942 | M23: =M16+M21 -> 305.72293 | N23: =N16+N21 -> 342.60213 | O23: =O16+O21 -> 380.4077 | P23: =P16+P21 -> 417.82815
B25: Financing activities
C26: Issuance / (repayment) of revolver | L26: ='Debt&Int'!L20 -> 17.581604 | M26: ='Debt&Int'!M20 -> -154.07332 | N26: ='Debt&Int'!N20 -> 65.5795 | O26: ='Debt&Int'!O20 -> -215.94432 | P26: ='Debt&Int'!P20 -> -18.343542 | Q26: (1 point)
C27: Issuance of long-term debt | L27: ='Debt&Int'!L25 -> 0 | M27: ='Debt&Int'!M25 -> 0 | N27: ='Debt&Int'!N25 -> 0 | O27: ='Debt&Int'!O25 -> 0 | P27: ='Debt&Int'!P25 -> 0 | Q27: (1 point)
C28: (Repayment) of long-term debt | L28: ='Debt&Int'!L26 -> -100.2 | M28: ='Debt&Int'!M26 -> -0.3 | N28: ='Debt&Int'!N26 -> -250.3 | O28: ='Debt&Int'!O26 -> -0.4 | P28: ='Debt&Int'!P26 -> -200.6 | Q28: (1 point)
C29: Dividends | L29: =-Equity!L16 -> -145.39103 | M29: =-Equity!M16 -> -151.3496 | N29: =-Equity!N16 -> -157.88163 | O29: =-Equity!O16 -> -164.0633 | P29: =-Equity!P16 -> -169.34256 | Q29: (1 point)
D30: Cash flow from financing activities | L30: =SUM(L26:L29) -> -228.00942 | M30: =SUM(M26:M29) -> -305.72293 | N30: =SUM(N26:N29) -> -342.60213 | O30: =SUM(O26:O29) -> -380.40761 | P30: =SUM(P26:P29) -> -388.28611
B32: Net change in cash | L32: =L23+L30 -> -20.8 | M32: =M23+M30 -> 3.7823281e-07 | N32: =N23+N30 -> 7.883996e-06 | O32: =O23+O30 -> 8.2926822e-05 | P32: =P23+P30 -> 29.542045
C33: Beginning cash balance | L33: =BS!K8 -> 55.8 | M33: =BS!L8 -> 35 | N33: =BS!M8 -> 35.000001 | O33: =BS!N8 -> 35.000015 | P33: =BS!O8 -> 35.000101 | Q33: (1 point)
C34: Ending cash balance | L34: =SUM(L32:L33) -> 35 | M34: =SUM(M32:M33) -> 35 | N34: =SUM(N32:N33) -> 35.000009 | O34: =SUM(O32:O33) -> 35.000098 | P34: =SUM(P32:P33) -> 64.542146
XX1000: 127155

Sheet Debt&Int
B1: ="Debt and Interest Schedule for "&CoName -> Debt and Interest Schedule for Sharang Corporation
B2: =subhead -> Dollars in millions, except per share data
H4: FYE Adjustment | I4: -2 | J4: =I4+1 -> -1 | K4: =J4+1 -> 0 | L4: =K4+1 -> 1 | M4: =L4+1 -> 2 | N4: =M4+1 -> 3 | O4: =N4+1 -> 4 | P4: =O4+1 -> 5
I6: ="Historical Year Ending "&TEXT(FYE,"Mmmm dd") & "," -> Historical Year Ending December 31, | L6: ="Projected Year Ending "&TEXT(FYE,"Mmmm Dd,") -> Projected Year Ending December 31,
I7: =YEAR(FYE)+I4 -> 2021 | J7: =YEAR(FYE)+J4 -> 2022 | K7: =YEAR(FYE)+K4 -> 2023 | L7: =YEAR(FYE)+L4 -> 2024 | M7: =YEAR(FYE)+M4 -> 2025 | N7: =YEAR(FYE)+N4 -> 2026 | O7: =YEAR(FYE)+O4 -> 2027 | P7: =YEAR(FYE)+P4 -> 2028
B9: Cash flow available for financing activities | L9: =CF!L23 -> 207.20942 | M9: =CF!M23 -> 305.72293 | N9: =CF!N23 -> 342.60213 | O9: =CF!O23 -> 380.4077 | P9: =CF!P23 -> 417.82815 | Q9: (1 point)
C10: Dividends | L10: =-Equity!L16 -> -145.39103 | M10: =-Equity!M16 -> -151.3496 | N10: =-Equity!N16 -> -157.88163 | O10: =-Equity!O16 -> -164.0633 | P10: =-Equity!P16 -> -169.34256 | Q10: (1 point)
C11: Plus: beginning cash balance | L11: =BS!K8 -> 55.8 | M11: =BS!L8 -> 35 | N11: =BS!M8 -> 35.000001 | O11: =BS!N8 -> 35.000015 | P11: =BS!O8 -> 35.000101 | Q11: (1 point)
C12: Less: minimum cash balance | L12: -35 | M12: =L12 -> -35 | N12: =M12 -> -35 | O12: =N12 -> -35 | P12: =O12 -> -35
B13: Cash available for debt repayment | L13: =SUM(L9:L12) -> 82.618396 | M13: =SUM(M9:M12) -> 154.37332 | N13: =SUM(N9:N12) -> 184.72051 | O13: =SUM(O9:O12) -> 216.34441 | P13: =SUM(P9:P12) -> 248.48569
C14: Long-term debt issuance | L14: =L25 -> 0 | M14: =M25 -> 0 | N14: =N25 -> 0 | O14: =O25 -> 0 | P14: =P25 -> 0 | Q14: (1 point)
C15: Long-term debt (repayment) | L15: =L26 -> -100.2 | M15: =M26 -> -0.3 | N15: =N26 -> -250.3 | O15: =O26 -> -0.4 | P15: =P26 -> -200.6 | Q15: (1 point)
B16: Excess cash available for revolver | L16: =SUM(L13:L15) -> -17.581604 | M16: =SUM(M13:M15) -> 154.07332 | N16: =SUM(N13:N15) -> -65.579491 | O16: =SUM(O13:O15) -> 215.94441 | P16: =SUM(P13:P15) -> 47.885688
B18: =BS!B25 -> Revolver
C19: Beginning balance | L19: =K21 -> 305.2 | M19: =L21 -> 322.7816 | N19: =M21 -> 168.70828 | O19: =N21 -> 234.28778 | P19: =O21 -> 18.343477
C20: Issuance / (repayment) of revolver | J20: =====>>critical formula | L20: =IF(L19>0, -MIN(L16,L19),-MIN(L16,0)) -> 17.581604 | M20: =IF(M19>0, -MIN(M16,M19),-MIN(M16,0)) -> -154.07332 | N20: =IF(N19>0, -MIN(N16,N19),-MIN(N16,0)) -> 65.579491 | O20: =IF(O19>0, -MIN(O16,O19),-MIN(O16,0)) -> -215.94441 | P20: =IF(P19>0, -MIN(P16,P19),-MIN(P16,0)) -> -18.343477 | Q20: (7 points)
C21: Ending balance | I21: =BS!I25 -> 303.1 | J21: =BS!J25 -> 221.2 | K21: =BS!K25 -> 305.2 | L21: =L19+L20 -> 322.7816 | M21: =M19+M20 -> 168.70828 | N21: =N19+N20 -> 234.28777 | O21: =O19+O20 -> 18.343367 | P21: =P19+P20 -> 0
B23: =BS!B26 -> Long-term debt
C24: Beginning balance | L24: =BS!K26 -> 760 | M24: =L27 -> 659.8 | N24: =M27 -> 659.5 | O24: =N27 -> 409.2 | P24: =O27 -> 408.8
C25: Issuance | L25: 0 | M25: 0 | N25: 0 | O25: 0 | P25: 0
C26: (Repayment) | L26: -100.2 | M26: -0.3 | N26: -250.3 | O26: -0.4 | P26: -200.6
C27: Ending balance | I27: =BS!I26 -> 1012 | J27: =BS!J26 -> 950 | K27: =BS!K26 -> 760 | L27: =SUM(L24:L26) -> 659.8 | M27: =SUM(M24:M26) -> 659.5 | N27: =SUM(N24:N26) -> 409.2 | O27: =SUM(O24:O26) -> 408.8 | P27: =SUM(P24:P26) -> 208.2
B30: =B18 -> Revolver | I30: Average balances | L30: =AVERAGE(L19,L21) -> 313.9908 | M30: =AVERAGE(M19,M21) -> 245.74494 | N30: =AVERAGE(N19,N21) -> 201.49803 | O30: =AVERAGE(O19,O21) -> 126.31557 | P30: =AVERAGE(P19,P21) -> 9.1717386 | R30: Step
I31: SOFR | K31: Spread | L31: 0.05 | M31: =L31+$R31 -> 0.045 | N31: =M31+$R31 -> 0.04 | O31: =N31+$R31 -> 0.035 | P31: =O31+$R31 -> 0.03 | R31: -0.005
I32: Interest rate | K32: 200 | L32: =L31+$K32/10000 -> 0.07 | M32: =M31+$K32/10000 -> 0.065 | N32: =N31+$K32/10000 -> 0.06 | O32: =O31+$K32/10000 -> 0.055 | P32: =P31+$K32/10000 -> 0.05
I33: Interest expense | L33: =L32*L30*365/360 -> 22.284625 | M33: =M32*M30*365/360 -> 16.195274 | N33: =N32*N30*365/360 -> 12.257797 | O33: =O32*O30*365/360 -> 7.0438476 | P33: =P32*P30*365/360 -> 0.46495619
B35: =B23 -> Long-term debt | I35: =I30 -> Average balances | L35: =AVERAGE(L24,L27) -> 709.9 | M35: =AVERAGE(M24,M27) -> 659.65 | N35: =AVERAGE(N24,N27) -> 534.35 | O35: =AVERAGE(O24,O27) -> 409 | P35: =AVERAGE(P24,P27) -> 308.5
I36: =I32 -> Interest rate | L36: 0.08 | M36: =L36 -> 0.08 | N36: =M36 -> 0.08 | O36: =N36 -> 0.08 | P36: =O36 -> 0.08
I37: =I33 -> Interest expense | L37: =L35*L36 -> 56.792 | M37: =M35*M36 -> 52.772 | N37: =N35*N36 -> 42.748 | O37: =O35*O36 -> 32.72 | P37: =P35*P36 -> 24.68
I39: Total interest expense | L39: =L33+L37 -> 79.076625 | M39: =M33+M37 -> 68.967274 | N39: =N33+N37 -> 55.005797 | O39: =O33+O37 -> 39.763848 | P39: =P33+P37 -> 25.144956
B41: Cash balances | I41: =I35 -> Average balances | L41: =AVERAGE(BS!K8:L8) -> 45.4 | M41: =AVERAGE(BS!L8:M8) -> 35.000001 | N41: =AVERAGE(BS!M8:N8) -> 35.000008 | O41: =AVERAGE(BS!N8:O8) -> 35.000058 | P41: =AVERAGE(BS!O8:P8) -> 49.771115 | R41: Step
I42: =I36 -> Interest rate | L42: 0.03 | M42: =L42+$R42 -> 0.0275 | N42: =M42+$R42 -> 0.025 | O42: =N42+$R42 -> 0.0225 | P42: =O42+$R42 -> 0.02 | R42: -0.0025
I43: Interest (income) | L43: =L41*L42 -> 1.362 | M43: =M41*M42 -> 0.96250001 | N43: =N41*N42 -> 0.8750002 | O43: =O41*O42 -> 0.7875013 | P43: =P41*P42 -> 0.9954223
XX1000: 127155
