Workbook
Name CashBalRepay: Summary!$R$17
Name CashSweep: Summary!$R$18
Name Cost_of_Sales: '[1]Naming & Data Tables'!$C$9
Name Current_Sales: '[1]Naming & Data Tables'!$C$4
Name EntryMultiple: RetAnalysis!$E$6
Name FinStructure: Summary!$R$15
Name Forecast_Sales: '[1]Naming & Data Tables'!$C$8
Name Gross_Margin: '[1]Naming & Data Tables'!$C$6
Name Gross_Profit: '[1]Naming & Data Tables'!$C$10
Name IQ_CH: 110000
Name IQ_CQ: 5000
Name IQ_CY: 10000
Name IQ_DAILY: 500000
Name IQ_FH: 100000
Name IQ_FQ: 500
Name IQ_FY: 1000
Name IQ_LTM: 2000
Name IQ_MONTH: 15000
Name IQ_NTM: 6000
Name IQ_WEEK: 50000
Name IQ_YTD: 3000
Name OpScenario: Summary!$R$16
Name Sales_Growth_Rate: '[1]Naming & Data Tables'!$C$5

Sheet Summary
B2: LBO Analysis
B3: ($ in millions, fiscal year ending December 31)
B5: Transaction Summary
B6: Sources of Funds | I6: Uses of Funds | M6: Purchase Price | P6: Returns Analysis
E7: % of Total | F7: Multiple of EBITDA | L7: % of Total | M7: Equity Purchase Price | O7: =Financing!N14 -> 5448.4417 | P7: Exit Year | R7: =RetAnalysis!K5 -> 2029
D8: Amount | E8: Sources | F8: =G26 -> 45565 | G8: Cumulative | H8: Pricing | K8: Amount | L8: Uses | M8: Plus: Existing Debt | O8: =-Financing!N10 -> 1500 | P8: Entry Multiple | R8: =RetAnalysis!E6 -> 10.5
B9: Revolver | D9: {=INDEX(Financing!D9:H9,,FinStructure)} -> 0 | E9: =IF(ISERROR(D9/$D$21),0,D9/$D$21) -> 0 | F9: =IF(ISERROR(D9/$G$33),0,D9/$G$33) -> 0 | G9: =F9 -> 0 | H9: =DebtSched!E18*10000 -> 350 | I9: Purchase Target Equity | K9: {=INDEX(Financing!D22:H22,,FinStructure)} -> 5448.4417 | L9: =IF(ISERROR(K9/$K$21),0,K9/$K$21) -> 0.76325365 | M9: Plus: Noncontrolling Interest | O9: =Financing!N12 -> 0 | P9: Exit Multiple | R9: =RetAnalysis!E9 -> 10.5
B10: Term Loan A | D10: {=INDEX(Financing!D10:H10,,FinStructure)} -> 500 | E10: =IF(ISERROR(D10/$D$21),0,D10/$D$21) -> 0.070043299 | F10: =IF(ISERROR(D10/$G$33),0,D10/$G$33) -> 0.78376438 | G10: =F10+G9 -> 0.78376438 | H10: =DebtSched!E34*10000 -> 350 | I10: Repay Existing Term Loan | K10: {=INDEX(Financing!D23:H23,,FinStructure)} -> 1000 | L10: =IF(ISERROR(K10/$K$21),0,K10/$K$21) -> 0.1400866 | M10: Plus: Preferred Equity | O10: =Financing!N11 -> 0 | P10: IRR | R10: =RetAnalysis!K41 -> 0.19239375
B11: Term Loan B | D11: {=INDEX(Financing!D11:H11,,FinStructure)} -> 2000 | E11: =IF(ISERROR(D11/$D$21),0,D11/$D$21) -> 0.28017319 | F11: =IF(ISERROR(D11/$G$33),0,D11/$G$33) -> 3.1350575 | G11: =F11+G10 -> 3.9188219 | H11: =DebtSched!E49*10000 -> 375 | I11: Repay Existing Senior Notes | K11: {=INDEX(Financing!D24:H24,,FinStructure)} -> 500 | L11: =IF(ISERROR(K11/$K$21),0,K11/$K$21) -> 0.070043299 | M11: Less: Cash and Equivalents | O11: =-Financing!N13 -> -250 | P11: Cash Return | R11: =RetAnalysis!K26 -> 2.4104518
B12: 2nd Lien | D12: {=INDEX(Financing!D12:H12,,FinStructure)} -> 300 | E12: =IF(ISERROR(D12/$D$21),0,D12/$D$21) -> 0.042025979 | F12: =IF(ISERROR(D12/$G$33),0,D12/$G$33) -> 0.47025863 | G12: =F12+G11 -> 4.3890806 | H12: =DebtSched!E64*10000 -> 450 | I12: Tender / Call Premiums | K12: {=INDEX(Financing!D25:H25,,FinStructure)} -> 20 | L12: =IF(ISERROR(K12/$K$21),0,K12/$K$21) -> 0.0028017319 | M12: Enterprise Value | O12: =SUM(O7:O11) -> 6698.4417
B13: Senior Notes | D13: {=INDEX(Financing!D13:H13,,FinStructure)} -> 1000 | E13: =IF(ISERROR(D13/$D$21),0,D13/$D$21) -> 0.1400866 | F13: =IF(ISERROR(D13/$G$33),0,D13/$G$33) -> 1.5675288 | G13: =F13+G12 -> 5.9566093 | H13: =DebtSched!E78 -> 0.0875 | I13: Financing Fees | K13: {=INDEX(Financing!D26:H26,,FinStructure)} -> 140 | L13: =IF(ISERROR(K13/$K$21),0,K13/$K$21) -> 0.019612124
B14: Senior Subordinated Notes | D14: {=INDEX(Financing!D14:H14,,FinStructure)} -> 1000 | E14: =IF(ISERROR(D14/$D$21),0,D14/$D$21) -> 0.1400866 | F14: =IF(ISERROR(D14/$G$33),0,D14/$G$33) -> 1.5675288 | G14: =F14+G13 -> 7.5241381 | H14: =DebtSched!E89 -> 0.09 | I14: Other Fees and Expenses | K14: {=INDEX(Financing!D27:H27,,FinStructure)} -> 30 | L14: =IF(ISERROR(K14/$K$21),0,K14/$K$21) -> 0.0042025979 | M14: Transaction Multiples | P14: Settings
B15: Equity Contribution | D15: {=INDEX(Financing!D15:H15,,FinStructure)} -> 2088.4417 | E15: =IF(ISERROR(D15/$D$21),0,D15/$D$21) -> 0.29256268 | F15: =IF(ISERROR(D15/$G$33),0,D15/$G$33) -> 3.2736924 | G15: =F15+G14 -> 10.79783 | M15: Enterprise Value / Sales | P15: Financing Structure | R15: 3
B16: Cash on Hand | D16: {=INDEX(Financing!D16:H16,,FinStructure)} -> 250 | E16: =IF(ISERROR(D16/$D$21),0,D16/$D$21) -> 0.035021649 | F16: =IF(ISERROR(D16/$G$33),0,D16/$G$33) -> 0.39188219 | G16: =F16+G15 -> 11.189713 | M16: =" LTM "&TEXT(G26,"mm/dd/yyyy") -> LTM 09/30/2024 | N16: =G27 -> 3200 | O16: =IF(ISERROR($O$12/N16),0,$O$12/N16) -> 2.093263 | P16: Operating Scenario | R16: =RetAnalysis!D65 -> 1
E17: =IF(ISERROR(D17/$D$21),0,D17/$D$21) -> 0 | F17: =IF(ISERROR(D17/$G$33),0,D17/$G$33) -> 0 | G17: =F17+G16 -> 11.189713 | M17: =" "&H26&"E" -> 2024E | N17: =H27 -> 3238.4 | O17: =IF(ISERROR($O$12/N17),0,$O$12/N17) -> 2.0684417 | P17: Cash Balance | R17: 1 | S17: *Cash balance indicates whether cash balance should be used to make optional repayments
E18: =IF(ISERROR(D18/$D$21),0,D18/$D$21) -> 0 | F18: =IF(ISERROR(D18/$G$33),0,D18/$G$33) -> 0 | G18: =F18+G17 -> 11.189713 | M18: Enterprise Value / EBITDA | P18: Cash Flow Sweep | R18: 1 | S18: *Cash sweep indicates whether to use available cash to make optional repayments
E19: =IF(ISERROR(D19/$D$21),0,D19/$D$21) -> 0 | F19: =IF(ISERROR(D19/$G$33),0,D19/$G$33) -> 0 | G19: =F19+G18 -> 11.189713 | M19: =M16 -> LTM 09/30/2024 | N19: =G33 -> 637.94682 | O19: =IF(ISERROR($O$12/N19),0,$O$12/N19) -> 10.5
E20: =IF(ISERROR(D20/$D$21),0,D20/$D$21) -> 0 | F20: =IF(ISERROR(D20/$G$33),0,D20/$G$33) -> 0 | G20: =F20+G19 -> 11.189713 | M20: =M17 -> 2024E | N20: =H33 -> 650.72629 | O20: =IF(ISERROR($O$12/N20),0,$O$12/N20) -> 10.293793
B21: Total Sources | D21: =SUM(D9:D20) -> 7138.4417 | E21: =SUM(E9:E20) -> 1 | F21: =SUM(F9:F20) -> 11.189713 | G21: =IF(ISERROR(D21/G33),0,D21/G33) -> 11.189713 | I21: Total Uses | K21: =SUM(K9:K20) -> 7138.4417 | L21: =SUM(L9:L20) -> 1
B23: Transaction Summary
D24: Historical Period | I24: Projection Period
G25: LTM | H25: Pro forma | I25: 1 | J25: =I25+1 -> 2 | K25: =J25+1 -> 3 | L25: =K25+1 -> 4 | M25: =L25+1 -> 5 | N25: =M25+1 -> 6 | O25: =N25+1 -> 7 | P25: =O25+1 -> 8 | Q25: =P25+1 -> 9 | R25: =Q25+1 -> 10
D26: =E26-1 -> 2021 | E26: =F26-1 -> 2022 | F26: =H26-1 -> 2023 | G26: 45565 | H26: =YEAR(G26) -> 2024 | I26: =$H$26+I25 -> 2025 | J26: =$H$26+J25 -> 2026 | K26: =$H$26+K25 -> 2027 | L26: =$H$26+L25 -> 2028 | M26: =$H$26+M25 -> 2029 | N26: =$H$26+N25 -> 2030 | O26: =$H$26+O25 -> 2031 | P26: =$H$26+P25 -> 2032 | ... R26: =$H$26+R25 -> 2034
B27: Sales | D27: =IncStmt!E6 -> 2520 | E27: =IncStmt!F6 -> 2780 | F27: =IncStmt!G6 -> 3070 | G27: =IncStmt!H6 -> 3200 | H27: =IncStmt!I6 -> 3238.4 | I27: =IncStmt!J6 -> 3335.552 | J27: =IncStmt!K6 -> 3418.9408 | K27: =IncStmt!L6 -> 3555.6984 | ... R27: =IncStmt!S6 -> 4567.55
B28: % growth | D28: =IncStmt!E7 -> NA | E28: =IncStmt!F7 -> 0.1031746 | F28: =IncStmt!G7 -> 0.10431655 | G28: =IncStmt!H7 -> NA | H28: =IncStmt!I7 -> 0.05485342 | I28: =IncStmt!J7 -> 0.03 | J28: =IncStmt!K7 -> 0.025 | K28: =IncStmt!L7 -> 0.04 | ... R28: =IncStmt!S7 -> 0.035
B30: Gross Profit | D30: =IncStmt!E10 -> 957.6 | E30: =IncStmt!F10 -> 1084.2 | F30: =IncStmt!G10 -> 1228 | G30: =IncStmt!H10 -> 1258.1832 | H30: =IncStmt!I10 -> 1277.165 | I30: =IncStmt!J10 -> 1334.2208 | J30: =IncStmt!K10 -> 1367.5763 | K30: =IncStmt!L10 -> 1422.2794 | ... R30: =IncStmt!S10 -> 1827.02
B31: % margin | D31: =IncStmt!E11 -> 0.38 | E31: =IncStmt!F11 -> 0.39 | F31: =IncStmt!G11 -> 0.4 | G31: =IncStmt!H11 -> 0.39318224 | H31: =IncStmt!I11 -> 0.39438148 | I31: =IncStmt!J11 -> 0.4 | J31: =IncStmt!K11 -> 0.4 | K31: =IncStmt!L11 -> 0.4 | ... R31: =IncStmt!S11 -> 0.4
B33: EBITDA | D33: =IncStmt!E17 -> 476.28 | E33: =IncStmt!F17 -> 556 | F33: =IncStmt!G17 -> 644.7 | G33: =IncStmt!H17 -> 637.94682 | H33: =IncStmt!I17 -> 650.72629 | I33: =IncStmt!J17 -> 733.82144 | J33: =IncStmt!K17 -> 752.16698 | K33: =IncStmt!L17 -> 782.25366 | ... R33: =IncStmt!S17 -> 1004.861
B34: % margin | D34: =IncStmt!E18 -> 0.189 | E34: =IncStmt!F18 -> 0.2 | F34: =IncStmt!G18 -> 0.21 | G34: =IncStmt!H18 -> 0.19935838 | H34: =IncStmt!I18 -> 0.20094068 | I34: =IncStmt!J18 -> 0.22 | J34: =IncStmt!K18 -> 0.22 | K34: =IncStmt!L18 -> 0.22 | ... R34: =IncStmt!S18 -> 0.22
B36: Capital Expenditures | D36: 136.4 | E36: 114 | F36: 144 | G36: 152.3 | H36: 155.3 | I36: =-CFStmt!F24 -> 166.7776 | J36: =-CFStmt!G24 -> 170.94704 | K36: =-CFStmt!H24 -> 177.78492 | L36: =-CFStmt!I24 -> 185.78524 | M36: =-CFStmt!J24 -> 192.28773 | N36: =-CFStmt!K24 -> 199.0178 | O36: =-CFStmt!L24 -> 205.98342 | P36: =-CFStmt!M24 -> 213.19284 | ... R36: =-CFStmt!O24 -> 228.3775
B37: % sales | D37: =IF(ISERROR(D36/D27),0,D36/D27) -> 0.054126984 | E37: =IF(ISERROR(E36/E27),0,E36/E27) -> 0.041007194 | F37: =IF(ISERROR(F36/F27),0,F36/F27) -> 0.046905537 | G37: =IF(ISERROR(G36/G27),0,G36/G27) -> 0.04759375 | H37: =IF(ISERROR(H36/H27),0,H36/H27) -> 0.047955781 | I37: =IF(ISERROR(I36/I27),0,I36/I27) -> 0.05 | J37: =IF(ISERROR(J36/J27),0,J36/J27) -> 0.05 | K37: =IF(ISERROR(K36/K27),0,K36/K27) -> 0.05 | ... R37: =IF(ISERROR(R36/R27),0,R36/R27) -> 0.05
B39: Cash Interest Expense | H39: =IncStmt!I34 -> 426.18427 | I39: =IncStmt!J34 -> 408.46027 | J39: =IncStmt!K34 -> 384.63129 | K39: =IncStmt!L34 -> 358.57525 | L39: =IncStmt!M34 -> 343.70773 | M39: =IncStmt!N34 -> 326.88661 | N39: =IncStmt!O34 -> 307.7182 | O39: =IncStmt!P34 -> 281.71713 | ... R39: =IncStmt!S34 -> 219.76056
B40: Total Interest Expense | H40: =IncStmt!I36 -> 444.44142 | I40: =IncStmt!J36 -> 426.71742 | J40: =IncStmt!K36 -> 402.88843 | K40: =IncStmt!L36 -> 376.83239 | L40: =IncStmt!M36 -> 359.96487 | M40: =IncStmt!N36 -> 343.14375 | N40: =IncStmt!O36 -> 323.97534 | O40: =IncStmt!P36 -> 296.72427 | ... R40: =IncStmt!S36 -> 225.66056
XX1000: 127155

Sheet IncStmt
B1: =Summary!$B$3 -> ($ in millions, fiscal year ending December 31)
B2: Income Statement
E3: Historical Period | J3: Projection Period
H4: LTM | I4: Pro Forma | J4: 1 | K4: =J4+1 -> 2 | L4: =K4+1 -> 3 | M4: =L4+1 -> 4 | N4: =M4+1 -> 5 | O4: =N4+1 -> 6 | P4: =O4+1 -> 7 | Q4: =P4+1 -> 8 | R4: =Q4+1 -> 9 | S4: =R4+1 -> 10
E5: =F5-1 -> 2021 | F5: =G5-1 -> 2022 | G5: =I5-1 -> 2023 | H5: =Summary!G26 -> 45565 | I5: =YEAR($H$5) -> 2024 | J5: =$I$5+J4 -> 2025 | K5: =$I$5+K4 -> 2026 | L5: =$I$5+L4 -> 2027 | M5: =$I$5+M4 -> 2028 | N5: =$I$5+N4 -> 2029 | O5: =$I$5+O4 -> 2030 | P5: =$I$5+P4 -> 2031 | Q5: =$I$5+Q4 -> 2032 | ... S5: =$I$5+S4 -> 2034
B6: Sales | E6: 2520 | F6: 2780 | G6: 3070 | H6: 3200 | I6: =H6*1.012 -> 3238.4 | J6: =I6*(1+J46) -> 3335.552 | K6: =J6*(1+K46) -> 3418.9408 | L6: =K6*(1+L46) -> 3555.6984 | M6: =L6*(1+M46) -> 3715.7049 | N6: =M6*(1+N46) -> 3845.7545 | O6: =N6*(1+O46) -> 3980.3559 | P6: =O6*(1+P46) -> 4119.6684 | Q6: =P6*(1+Q46) -> 4263.8568 | ... S6: =R6*(1+S46) -> 4567.55
B7: % growth | E7: NA | F7: =IF(ISERROR(F6/E6-1),0,F6/E6-1) -> 0.1031746 | G7: =IF(ISERROR(G6/F6-1),0,G6/F6-1) -> 0.10431655 | H7: NA | I7: =IF(ISERROR(I6/G6-1),0,I6/G6-1) -> 0.05485342 | J7: =IF(ISERROR(J6/I6-1),0,J6/I6-1) -> 0.03 | K7: =IF(ISERROR(K6/J6-1),0,K6/J6-1) -> 0.025 | L7: =IF(ISERROR(L6/K6-1),0,L6/K6-1) -> 0.04 | M7: =IF(ISERROR(M6/L6-1),0,M6/L6-1) -> 0.045 | N7: =IF(ISERROR(N6/M6-1),0,N6/M6-1) -> 0.035 | O7: =IF(ISERROR(O6/N6-1),0,O6/N6-1) -> 0.035 | P7: =IF(ISERROR(P6/O6-1),0,P6/O6-1) -> 0.035 | Q7: =IF(ISERROR(Q6/P6-1),0,Q6/P6-1) -> 0.035 | ... S7: =IF(ISERROR(S6/R6-1),0,S6/R6-1) -> 0.035
B9: Cost of Goods Sold | E9: 1562.4 | F9: 1695.8 | G9: 1842 | H9: 1941.8168 | I9: =H9*1.01 -> 1961.235 | J9: =J6*J47 -> 2001.3312 | K9: =K6*K47 -> 2051.3645 | L9: =L6*L47 -> 2133.4191 | M9: =M6*M47 -> 2229.4229 | N9: =N6*N47 -> 2307.4527 | O9: =O6*O47 -> 2388.2136 | P9: =P6*P47 -> 2471.801 | Q9: =Q6*Q47 -> 2558.3141 | ... S9: =S6*S47 -> 2740.53
B10: Gross Profit | E10: =E6-E9 -> 957.6 | F10: =F6-F9 -> 1084.2 | G10: =G6-G9 -> 1228 | H10: =H6-H9 -> 1258.1832 | I10: =I6-I9 -> 1277.165 | J10: =J6-J9 -> 1334.2208 | K10: =K6-K9 -> 1367.5763 | L10: =L6-L9 -> 1422.2794 | ... S10: =S6-S9 -> 1827.02
B11: % margin | E11: =IF(ISERROR(E10/E6),0,E10/E6) -> 0.38 | F11: =IF(ISERROR(F10/F6),0,F10/F6) -> 0.39 | G11: =IF(ISERROR(G10/G6),0,G10/G6) -> 0.4 | H11: =IF(ISERROR(H10/H6),0,H10/H6) -> 0.39318224 | I11: =IF(ISERROR(I10/I6),0,I10/I6) -> 0.39438148 | J11: =IF(ISERROR(J10/J6),0,J10/J6) -> 0.4 | K11: =IF(ISERROR(K10/K6),0,K10/K6) -> 0.4 | L11: =IF(ISERROR(L10/L6),0,L10/L6) -> 0.4 | ... S11: =IF(ISERROR(S10/S6),0,S10/S6) -> 0.4
B13: Selling, General & Administrative | E13: 481.32 | F13: 528.2 | G13: 583.3 | H13: 620.23634 | I13: =H13*1.01 -> 626.4387 | J13: =J6*J48 -> 600.39936 | K13: =K6*K48 -> 615.40934 | L13: =L6*L48 -> 640.02572 | M13: =M6*M48 -> 668.82688 | N13: =N6*N48 -> 692.23582 | O13: =O6*O48 -> 716.46407 | P13: =P6*P48 -> 741.54031 | Q13: =Q6*Q48 -> 767.49422 | ... S13: =S6*S48 -> 822.159
B14: % sales | E14: =IF(ISERROR(E13/E6),0,E13/E6) -> 0.191 | F14: =IF(ISERROR(F13/F6),0,F13/F6) -> 0.19 | G14: =IF(ISERROR(G13/G6),0,G13/G6) -> 0.19 | H14: =IF(ISERROR(H13/H6),0,H13/H6) -> 0.19382386 | I14: =IF(ISERROR(I13/I6),0,I13/I6) -> 0.1934408 | J14: =IF(ISERROR(J13/J6),0,J13/J6) -> 0.18 | K14: =IF(ISERROR(K13/K6),0,K13/K6) -> 0.18 | L14: =IF(ISERROR(L13/L6),0,L13/L6) -> 0.18 | ... S14: =IF(ISERROR(S13/S6),0,S13/S6) -> 0.18
B16: Other Expense / (Income) | E16: 0 | F16: 0 | G16: 0 | H16: 0 | I16: =H16 -> 0 | J16: =J6*J49 -> 0 | K16: =K6*K49 -> 0 | L16: =L6*L49 -> 0 | M16: =M6*M49 -> 0 | N16: =N6*N49 -> 0 | O16: =O6*O49 -> 0 | P16: =P6*P49 -> 0 | Q16: =Q6*Q49 -> 0 | ... S16: =S6*S49 -> 0
B17: EBITDA | E17: =E10-E13-E16 -> 476.28 | F17: =F10-F13-F16 -> 556 | G17: =G10-G13-G16 -> 644.7 | H17: =H10-H13-H16 -> 637.94682 | I17: =I10-I13-I16 -> 650.72629 | J17: =J10-J13-J16 -> 733.82144 | K17: =K10-K13-K16 -> 752.16698 | L17: =L10-L13-L16 -> 782.25366 | ... S17: =S10-S13-S16 -> 1004.861
B18: % margin | E18: =IF(ISERROR(E17/E6),0,E17/E6) -> 0.189 | F18: =IF(ISERROR(F17/F6),0,F17/F6) -> 0.2 | G18: =IF(ISERROR(G17/G6),0,G17/G6) -> 0.21 | H18: =IF(ISERROR(H17/H6),0,H17/H6) -> 0.19935838 | I18: =IF(ISERROR(I17/I6),0,I17/I6) -> 0.20094068 | J18: =IF(ISERROR(J17/J6),0,J17/J6) -> 0.22 | K18: =IF(ISERROR(K17/K6),0,K17/K6) -> 0.22 | L18: =IF(ISERROR(L17/L6),0,L17/L6) -> 0.22 | ... S18: =IF(ISERROR(S17/S6),0,S17/S6) -> 0.22
B20: Depreciation | E20: 114 | F20: 118 | G20: 140 | H20: 145 | I20: =H20 -> 145 | J20: =J6*J50 -> 166.7776 | K20: =K6*K50 -> 170.94704 | L20: =L6*L50 -> 177.78492 | M20: =M6*M50 -> 185.78524 | N20: =N6*N50 -> 192.28773 | O20: =O6*O50 -> 199.0178 | P20: =P6*P50 -> 205.98342 | Q20: =Q6*Q50 -> 213.19284 | ... S20: =S6*S50 -> 228.3775
B21: Amortization | E21: 39 | F21: 42 | G21: 46.5 | H21: 49 | I21: =H21 -> 49 | J21: =J6*J51 -> 66.71104 | K21: =K6*K51 -> 68.378816 | L21: =L6*L51 -> 71.113969 | M21: =M6*M51 -> 74.314097 | N21: =N6*N51 -> 76.915091 | O21: =O6*O51 -> 79.607119 | P21: =P6*P51 -> 82.393368 | Q21: =Q6*Q51 -> 85.277136 | ... S21: =S6*S51 -> 91.351
B22: EBIT | E22: =E17-SUM(E20:E21) -> 323.28 | F22: =F17-SUM(F20:F21) -> 396 | G22: =G17-SUM(G20:G21) -> 458.2 | H22: =H17-SUM(H20:H21) -> 443.94682 | I22: =I17-SUM(I20:I21) -> 456.72629 | J22: =J17-SUM(J20:J21) -> 500.3328 | K22: =K17-SUM(K20:K21) -> 512.84112 | L22: =L17-SUM(L20:L21) -> 533.35476 | ... S22: =S17-SUM(S20:S21) -> 685.1325
B23: % margin | E23: =IF(ISERROR(E22/E6),0,E22/E6) -> 0.12828571 | F23: =IF(ISERROR(F22/F6),0,F22/F6) -> 0.14244604 | G23: =IF(ISERROR(G22/G6),0,G22/G6) -> 0.14925081 | H23: =IF(ISERROR(H22/H6),0,H22/H6) -> 0.13873338 | I23: =IF(ISERROR(I22/I6),0,I22/I6) -> 0.14103455 | J23: =IF(ISERROR(J22/J6),0,J22/J6) -> 0.15 | K23: =IF(ISERROR(K22/K6),0,K22/K6) -> 0.15 | L23: =IF(ISERROR(L22/L6),0,L22/L6) -> 0.15 | ... S23: =IF(ISERROR(S22/S6),0,S22/S6) -> 0.15
B25: Interest Expense
B26: Revolver | I26: =BalSheet!H24*(IF(DebtSched!E$6>DebtSched!E19,DebtSched!E$6,DebtSched!E19)+DebtSched!E18) -> 0 | J26: =DebtSched!F28 -> 0.25474824 | K26: =DebtSched!G28 -> 0.24216808 | L26: =DebtSched!H28 -> 0 | M26: =DebtSched!I28 -> 0 | N26: =DebtSched!J28 -> 0 | O26: =DebtSched!K28 -> 0 | P26: =DebtSched!L28 -> 45.396712 | Q26: =DebtSched!M28 -> 115.2324 | ... S26: =DebtSched!O28 -> 132.06056 | T26: (1 point for entire row)
B27: Term Loan A | I27: =BalSheet!H25*(IF(DebtSched!E$6>DebtSched!E35,DebtSched!E$6,DebtSched!E35)+DebtSched!E34) -> 42.5 | J27: =DebtSched!F45 -> 37.96875 | K27: =DebtSched!G45 -> 31.277345 | L27: =DebtSched!H45 -> 23.875251 | M27: =DebtSched!I45 -> 16.647727 | N27: =DebtSched!J45 -> 6.2688249 | O27: =DebtSched!K45 -> 0 | P27: =DebtSched!L45 -> 0 | Q27: =DebtSched!M45 -> 0 | ... S27: =DebtSched!O45 -> 0 | T27: (1 point for entire row)
B28: Term Loan B | I28: =BalSheet!H26*(IF(DebtSched!E$6>DebtSched!E50,DebtSched!E$6,DebtSched!E50)+DebtSched!E49) -> 175 | J28: =DebtSched!F60 -> 166.165 | K28: =DebtSched!G60 -> 156.615 | L28: =DebtSched!H60 -> 145.275 | M28: =DebtSched!I60 -> 143.785 | N28: =DebtSched!J60 -> 140.41778 | O28: =DebtSched!K60 -> 127.5182 | P28: =DebtSched!L60 -> 58.620417 | Q28: =DebtSched!M60 -> 0 | ... S28: =DebtSched!O60 -> 0 | T28: (1 point for entire row)
B29: 2nd Lien | I29: =BalSheet!H28*(DebtSched!E6+DebtSched!E64) -> 28.5 | J29: =DebtSched!F74 -> 23.8875 | K29: =DebtSched!G74 -> 16.3125 | L29: =DebtSched!H74 -> 9.225 | M29: =DebtSched!I74 -> 3.075 | N29: =DebtSched!J74 -> 0 | O29: =DebtSched!K74 -> 0 | P29: =DebtSched!L74 -> 0 | Q29: =DebtSched!M74 -> 0 | ... S29: =DebtSched!O74 -> 0 | T29: (1 point for entire row)
B30: Senior Notes | I30: =J30 -> 87.5 | J30: =DebtSched!F85 -> 87.5 | K30: =DebtSched!G85 -> 87.5 | L30: =DebtSched!H85 -> 87.5 | M30: =DebtSched!I85 -> 87.5 | N30: =DebtSched!J85 -> 87.5 | O30: =DebtSched!K85 -> 87.5 | P30: =DebtSched!L85 -> 87.5 | Q30: =DebtSched!M85 -> 87.5 | ... S30: =DebtSched!O85 -> 87.5 | T30: (1 point for entire row)
B31: Senior Subordinated Notes | I31: =J31 -> 90 | J31: =DebtSched!F96 -> 90 | K31: =DebtSched!G96 -> 90 | L31: =DebtSched!H96 -> 90 | M31: =DebtSched!I96 -> 90 | N31: =DebtSched!J96 -> 90 | O31: =DebtSched!K96 -> 90 | P31: =DebtSched!L96 -> 90 | Q31: =DebtSched!M96 -> 90 | ... S31: =DebtSched!O96 -> 0 | T31: (1 point for entire row)
B32: Commitment Fee on Unused Revolver | I32: =J32 -> 2.4842748 | J32: =DebtSched!F29 -> 2.4842748 | K32: =DebtSched!G29 -> 2.4842748 | L32: =DebtSched!H29 -> 2.5 | M32: =DebtSched!I29 -> 2.5 | N32: =DebtSched!J29 -> 2.5 | O32: =DebtSched!K29 -> 2.5 | P32: =DebtSched!L29 -> 0 | Q32: =DebtSched!M29 -> 0 | ... S32: =DebtSched!O29 -> 0 | T32: (1 point for entire row)
B33: Administrative Agent Fee | I33: =J33 -> 0.2 | J33: =DebtSched!F30 -> 0.2 | K33: =DebtSched!G30 -> 0.2 | L33: =DebtSched!H30 -> 0.2 | M33: =DebtSched!I30 -> 0.2 | N33: =DebtSched!J30 -> 0.2 | O33: =DebtSched!K30 -> 0.2 | P33: =DebtSched!L30 -> 0.2 | Q33: =DebtSched!M30 -> 0.2 | ... S33: =DebtSched!O30 -> 0.2 | T33: (1 point for entire row)
B34: Cash Interest Expense | I34: =SUM(I26:I33) -> 426.18427 | J34: =SUM(J26:J33) -> 408.46027 | K34: =SUM(K26:K33) -> 384.63129 | L34: =SUM(L26:L33) -> 358.57525 | M34: =SUM(M26:M33) -> 343.70773 | N34: =SUM(N26:N33) -> 326.88661 | O34: =SUM(O26:O33) -> 307.7182 | P34: =SUM(P26:P33) -> 281.71713 | ... S34: =SUM(S26:S33) -> 219.76056 | T34: (1 point for entire row)
B35: Amortization of Deferred Financing Fees | I35: =J35 -> 18.257143 | J35: =Financing!E58 -> 18.257143 | K35: =Financing!F58 -> 18.257143 | L35: =Financing!G58 -> 18.257143 | M35: =Financing!H58 -> 16.257143 | N35: =Financing!I58 -> 16.257143 | O35: =Financing!J58 -> 16.257143 | P35: =Financing!K58 -> 15.007143 | Q35: =Financing!L58 -> 9.65 | ... S35: =Financing!N58 -> 5.9 | T35: (1 point for entire row)
B36: Total Interest Expense | I36: =I34+I35 -> 444.44142 | J36: =SUM(J34:J35) -> 426.71742 | K36: =SUM(K34:K35) -> 402.88843 | L36: =SUM(L34:L35) -> 376.83239 | M36: =SUM(M34:M35) -> 359.96487 | N36: =SUM(N34:N35) -> 343.14375 | O36: =SUM(O34:O35) -> 323.97534 | P36: =SUM(P34:P35) -> 296.72427 | Q36: =SUM(Q34:Q35) -> 302.5824 | ... S36: =SUM(S34:S35) -> 225.66056 | T36: (1 point for entire row)
B37: (Interest Income) | J37: =((CFStmt!F41+CFStmt!F42)/2)*IncStmt!J52 -> 0 | K37: =((CFStmt!G41+CFStmt!G42)/2)*IncStmt!K52 -> 0 | L37: =((CFStmt!H41+CFStmt!H42)/2)*IncStmt!L52 -> 0 | M37: =((CFStmt!I41+CFStmt!I42)/2)*IncStmt!M52 -> 0 | N37: =((CFStmt!J41+CFStmt!J42)/2)*IncStmt!N52 -> 0 | O37: =((CFStmt!K41+CFStmt!K42)/2)*IncStmt!O52 -> 0 | P37: =((CFStmt!L41+CFStmt!L42)/2)*IncStmt!P52 -> 0 | Q37: =((CFStmt!M41+CFStmt!M42)/2)*IncStmt!Q52 -> 0 | ... S37: =((CFStmt!O41+CFStmt!O42)/2)*IncStmt!S52 -> 0 | T37: (1 point for entire row)
B38: Net Interest Expense | J38: =J36-J37 -> 426.71742 | K38: =K36-K37 -> 402.88843 | L38: =L36-L37 -> 376.83239 | M38: =M36-M37 -> 359.96487 | N38: =N36-N37 -> 343.14375 | O38: =O36-O37 -> 323.97534 | P38: =P36-P37 -> 296.72427 | Q38: =Q36-Q37 -> 302.5824 | ... S38: =S36-S37 -> 225.66056 | T38: (1 point for entire row)
B40: Earnings Before Taxes | J40: =J22-J38 -> 73.615384 | K40: =K22-K38 -> 109.95269 | L40: =L22-L38 -> 156.52237 | M40: =M22-M38 -> 197.39086 | N40: =N22-N38 -> 233.71943 | O40: =O22-O38 -> 273.07805 | P40: =P22-P38 -> 321.22599 | Q40: =Q22-Q38 -> 336.99612 | ... S40: =S22-S38 -> 459.47194
B41: Income Taxes | J41: =J40*J53 -> 18.403846 | K41: =K40*K53 -> 27.488172 | L41: =L40*L53 -> 39.130593 | M41: =M40*M53 -> 49.347715 | N41: =N40*N53 -> 58.429857 | O41: =O40*O53 -> 68.269512 | P41: =P40*P53 -> 80.306497 | Q41: =Q40*Q53 -> 84.24903 | ... S41: =S40*S53 -> 114.86799
B42: Net Income | J42: =J40-J41 -> 55.211538 | K42: =K40-K41 -> 82.464517 | L42: =L40-L41 -> 117.39178 | M42: =M40-M41 -> 148.04314 | N42: =N40-N41 -> 175.28957 | O42: =O40-O41 -> 204.80854 | P42: =P40-P41 -> 240.91949 | Q42: =Q40-Q41 -> 252.74709 | ... S42: =S40-S41 -> 344.60396
B43: % margin | J43: =J42/J6 -> 0.016552444 | K43: =K42/K6 -> 0.024119902 | L43: =L42/L6 -> 0.033015111 | M43: =M42/M6 -> 0.039842547 | N43: =N42/N6 -> 0.045580021 | O43: =O42/O6 -> 0.051454829 | P43: =P42/P6 -> 0.058480311 | Q43: =Q42/Q6 -> 0.059276637 | ... S43: =S42/S6 -> 0.075446127
B45: Income Statement Assumptions
B46: Sales (% growth) | E46: NA | F46: =F7 -> 0.1031746 | G46: =G7 -> 0.10431655 | H46: =H7 -> NA | I46: =I7 -> 0.05485342 | J46: =Assumptions1!F8 -> 0.03 | K46: =Assumptions1!G8 -> 0.025 | L46: =Assumptions1!H8 -> 0.04 | M46: =Assumptions1!I8 -> 0.045 | N46: =Assumptions1!J8 -> 0.035 | O46: =Assumptions1!K8 -> 0.035 | P46: =Assumptions1!L8 -> 0.035 | Q46: =Assumptions1!M8 -> 0.035 | ... S46: =Assumptions1!O8 -> 0.035
B47: Cost of Goods Sold (% margin) | E47: =IF(ISERROR(E9/E6),0,E9/E6) -> 0.62 | F47: =IF(ISERROR(F9/F6),0,F9/F6) -> 0.61 | G47: =IF(ISERROR(G9/G6),0,G9/G6) -> 0.6 | H47: =IF(ISERROR(H9/H6),0,H9/H6) -> 0.60681776 | I47: =IF(ISERROR(I9/I6),0,I9/I6) -> 0.60561852 | J47: =Assumptions1!F14 -> 0.6 | K47: =Assumptions1!G14 -> 0.6 | L47: =Assumptions1!H14 -> 0.6 | M47: =Assumptions1!I14 -> 0.6 | N47: =Assumptions1!J14 -> 0.6 | O47: =Assumptions1!K14 -> 0.6 | P47: =Assumptions1!L14 -> 0.6 | Q47: =Assumptions1!M14 -> 0.6 | ... S47: =Assumptions1!O14 -> 0.6
...

Sheet BalSheet
B1: =Summary!$B$3 -> ($ in millions, fiscal year ending December 31)
B2: Balance Sheet
I3: Projection Period
E4: Opening | F4: Adjustments | H4: Pro Forma | I4: 1 | J4: =I4+1 -> 2 | K4: =J4+1 -> 3 | L4: =K4+1 -> 4 | M4: =L4+1 -> 5 | N4: =M4+1 -> 6 | O4: =N4+1 -> 7 | P4: =O4+1 -> 8 | Q4: =P4+1 -> 9 | R4: =Q4+1 -> 10
E5: =H5 -> 2024 | F5: + | G5: - | H5: =IncStmt!I5 -> 2024 | I5: =$H$5+I4 -> 2025 | J5: =$H$5+J4 -> 2026 | K5: =$H$5+K4 -> 2027 | L5: =$H$5+L4 -> 2028 | M5: =$H$5+M4 -> 2029 | N5: =$H$5+N4 -> 2030 | O5: =$H$5+O4 -> 2031 | P5: =$H$5+P4 -> 2032 | ... R5: =$H$5+R4 -> 2034
B6: Cash and Cash Equivalents | E6: 250 | G6: =IF(OR(FinStructure=1,FinStructure=2,FinStructure=3,FinStructure=4),-E6,0) -> -250 | H6: =SUM(E6:G6) -> 0 | I6: =CFStmt!F42 -> 0 | J6: =CFStmt!G42 -> 0 | K6: =CFStmt!H42 -> 0 | L6: =CFStmt!I42 -> 0 | M6: =CFStmt!J42 -> 0 | N6: =CFStmt!K42 -> 0 | O6: =CFStmt!L42 -> 0 | P6: =CFStmt!M42 -> 0 | ... R6: =CFStmt!O42 -> 0
B7: Accounts Receivable | E7: 450 | H7: =SUM(E7:G7) -> 450 | I7: =IncStmt!J6*BalSheet!I50/365 -> 434.99253 | J7: =IncStmt!K6*BalSheet!J50/365 -> 445.86735 | K7: =IncStmt!L6*BalSheet!K50/365 -> 463.70204 | L7: =IncStmt!M6*BalSheet!L50/365 -> 484.56863 | M7: =IncStmt!N6*BalSheet!M50/365 -> 501.52854 | N7: =IncStmt!O6*BalSheet!N50/365 -> 519.08203 | O7: =IncStmt!P6*BalSheet!O50/365 -> 537.24991 | P7: =IncStmt!Q6*BalSheet!P50/365 -> 556.05365 | ... R7: =IncStmt!S6*BalSheet!R50/365 -> 595.65857
B8: Inventories | E8: 600 | H8: =SUM(E8:G8) -> 600 | I8: =IncStmt!J9*BalSheet!I51/365 -> 580.11189 | J8: =IncStmt!K9*BalSheet!J51/365 -> 594.61469 | K8: =IncStmt!L9*BalSheet!K51/365 -> 618.39928 | L8: =IncStmt!M9*BalSheet!L51/365 -> 646.22725 | M8: =IncStmt!N9*BalSheet!M51/365 -> 668.8452 | N8: =IncStmt!O9*BalSheet!N51/365 -> 692.25478 | O8: =IncStmt!P9*BalSheet!O51/365 -> 716.4837 | P8: =IncStmt!Q9*BalSheet!P51/365 -> 741.56063 | ... R8: =IncStmt!S9*BalSheet!R51/365 -> 794.37828
B9: Prepaids and Other Current Assets | E9: 175 | H9: =SUM(E9:G9) -> 175 | I9: =IncStmt!J6*BalSheet!H52 -> 180.25 | J9: =IncStmt!K6*BalSheet!I52 -> 174.36598 | K9: =IncStmt!L6*BalSheet!J52 -> 181.34062 | L9: =IncStmt!M6*BalSheet!K52 -> 189.50095 | M9: =IncStmt!N6*BalSheet!L52 -> 196.13348 | N9: =IncStmt!O6*BalSheet!M52 -> 202.99815 | O9: =IncStmt!P6*BalSheet!N52 -> 210.10309 | P9: =IncStmt!Q6*BalSheet!O52 -> 217.4567 | ... R9: =IncStmt!S6*BalSheet!Q52 -> 232.94505
B10: Total Current Assets | E10: =SUM(E6:E9) -> 1475 | H10: =SUM(H6:H9) -> 1225 | I10: =SUM(I6:I9) -> 1195.3544 | J10: =SUM(J6:J9) -> 1214.848 | K10: =SUM(K6:K9) -> 1263.4419 | L10: =SUM(L6:L9) -> 1320.2968 | M10: =SUM(M6:M9) -> 1366.5072 | N10: =SUM(N6:N9) -> 1414.335 | O10: =SUM(O6:O9) -> 1463.8367 | ... R10: =SUM(R6:R9) -> 1622.9819
B12: Property, Plant, and Equipment, net | E12: 2500 | H12: =SUM(E12:G12) -> 2500 | I12: =H12-CFStmt!F8-CFStmt!F24 -> 2500 | J12: =I12-CFStmt!G8-CFStmt!G24 -> 2500 | K12: =J12-CFStmt!H8-CFStmt!H24 -> 2500 | L12: =K12-CFStmt!I8-CFStmt!I24 -> 2500 | M12: =L12-CFStmt!J8-CFStmt!J24 -> 2500 | N12: =M12-CFStmt!K8-CFStmt!K24 -> 2500 | O12: =N12-CFStmt!L8-CFStmt!L24 -> 2500 | P12: =O12-CFStmt!M8-CFStmt!M24 -> 2500 | ... R12: =Q12-CFStmt!O8-CFStmt!O24 -> 2500
B13: Goodwill | E13: 1000 | F13: =IF(OR(FinStructure=1,FinStructure=2,FinStructure=3,FinStructure=4),Summary!K9 - (BalSheet!E38-BalSheet!E13),0) -> 2948.4417 | G13: =IF(OR(FinStructure=1,FinStructure=2,FinStructure=3,FinStructure=4),-BalSheet!E13,0) -> -1000 | H13: =SUM(E13:G13) -> 2948.4417 | I13: =H13 -> 2948.4417 | J13: =I13 -> 2948.4417 | K13: =J13 -> 2948.4417 | L13: =K13 -> 2948.4417 | M13: =L13 -> 2948.4417 | N13: =M13 -> 2948.4417 | O13: =N13 -> 2948.4417 | P13: =O13 -> 2948.4417 | ... R13: =Q13 -> 2948.4417
B14: Intangible Assets | E14: 875 | H14: =SUM(E14:G14) -> 875 | I14: =H14-IncStmt!J21 -> 808.28896 | J14: =I14-IncStmt!K21 -> 739.91014 | K14: =J14-IncStmt!L21 -> 668.79618 | L14: =K14-IncStmt!M21 -> 594.48208 | M14: =L14-IncStmt!N21 -> 517.56699 | N14: =M14-IncStmt!O21 -> 437.95987 | O14: =N14-IncStmt!P21 -> 355.5665 | P14: =O14-IncStmt!Q21 -> 270.28936 | ... R14: =Q14-IncStmt!S21 -> 90.676529
B15: Other Assets | E15: 150 | H15: =SUM(E15:G15) -> 150 | I15: =H15 -> 150 | J15: =I15 -> 150 | K15: =J15 -> 150 | L15: =K15 -> 150 | M15: =L15 -> 150 | N15: =M15 -> 150 | O15: =N15 -> 150 | P15: =O15 -> 150 | ... R15: =Q15 -> 150
B16: Deferred Financing Fees | E16: 0 | F16: =IF(OR(FinStructure=1,FinStructure=2,FinStructure=3,FinStructure=4),Summary!K13,0) -> 140 | H16: =SUM(E16:G16) -> 140 | I16: =H16-IncStmt!J35 -> 121.74286 | J16: =I16-IncStmt!K35 -> 103.48571 | K16: =J16-IncStmt!L35 -> 85.228571 | L16: =K16-IncStmt!M35 -> 68.971429 | M16: =L16-IncStmt!N35 -> 52.714286 | N16: =M16-IncStmt!O35 -> 36.457143 | O16: =N16-IncStmt!P35 -> 21.45 | P16: =O16-IncStmt!Q35 -> 11.8 | ... R16: =Q16-IncStmt!S35 -> 2.3092639e-14
B17: Total Assets | E17: =E10+SUM(E12:E16) -> 6000 | H17: =H10+SUM(H12:H16) -> 7838.4417 | I17: =I10+SUM(I12:I16) -> 7723.8279 | J17: =J10+SUM(J12:J16) -> 7656.6855 | K17: =K10+SUM(K12:K16) -> 7615.9083 | L17: =L10+SUM(L12:L16) -> 7582.192 | M17: =M10+SUM(M12:M16) -> 7535.2301 | N17: =N10+SUM(N12:N16) -> 7487.1936 | O17: =O10+SUM(O12:O16) -> 7439.2948 | ... R17: =R10+SUM(R12:R16) -> 7312.1001
B19: Accounts Payable | E19: 215 | H19: =SUM(E19:G19) -> 215 | I19: =IncStmt!J9*BalSheet!I55/365 -> 207.80946 | J19: =IncStmt!K9*BalSheet!J55/365 -> 213.0047 | K19: =IncStmt!L9*BalSheet!K55/365 -> 221.52488 | L19: =IncStmt!M9*BalSheet!L55/365 -> 231.4935 | M19: =IncStmt!N9*BalSheet!M55/365 -> 239.59578 | N19: =IncStmt!O9*BalSheet!N55/365 -> 247.98163 | O19: =IncStmt!P9*BalSheet!O55/365 -> 256.66098 | P19: =IncStmt!Q9*BalSheet!P55/365 -> 265.64412 | ... R19: =IncStmt!S9*BalSheet!R55/365 -> 284.56462
B20: Accrued Liabilities | E20: 275 | H20: =SUM(E20:G20) -> 275 | I20: =IncStmt!J6*BalSheet!I56 -> 266.84416 | J20: =IncStmt!K6*BalSheet!J56 -> 273.51526 | K20: =IncStmt!L6*BalSheet!K56 -> 284.45587 | L20: =IncStmt!M6*BalSheet!L56 -> 297.25639 | M20: =IncStmt!N6*BalSheet!M56 -> 307.66036 | N20: =IncStmt!O6*BalSheet!N56 -> 318.42848 | O20: =IncStmt!P6*BalSheet!O56 -> 329.57347 | P20: =IncStmt!Q6*BalSheet!P56 -> 341.10854 | ... R20: =IncStmt!S6*BalSheet!R56 -> 365.404
B21: Other Current Liabilities | E21: 100 | H21: =SUM(E21:G21) -> 100 | I21: =IncStmt!J6*BalSheet!I57 -> 96.731008 | J21: =IncStmt!K6*BalSheet!J57 -> 99.149283 | K21: =IncStmt!L6*BalSheet!K57 -> 103.11525 | L21: =IncStmt!M6*BalSheet!L57 -> 107.75544 | M21: =IncStmt!N6*BalSheet!M57 -> 111.52688 | N21: =IncStmt!O6*BalSheet!N57 -> 115.43032 | O21: =IncStmt!P6*BalSheet!O57 -> 119.47038 | P21: =IncStmt!Q6*BalSheet!P57 -> 123.65185 | ... R21: =IncStmt!S6*BalSheet!R57 -> 132.45895
B22: Total Current Liabilities | E22: =SUM(E19:E21) -> 590 | H22: =SUM(H19:H21) -> 590 | I22: =SUM(I19:I21) -> 571.38463 | J22: =SUM(J19:J21) -> 585.66924 | K22: =SUM(K19:K21) -> 609.09601 | L22: =SUM(L19:L21) -> 636.50533 | M22: =SUM(M19:M21) -> 658.78302 | N22: =SUM(N19:N21) -> 681.84043 | O22: =SUM(O19:O21) -> 705.70484 | ... R22: =SUM(R19:R21) -> 782.42757
B24: =IncStmt!B26 -> Revolver | E24: 0 | F24: =Summary!D9 -> 0 | H24: =SUM(E24:G24) -> 0 | I24: =DebtSched!F25 -> 6.2900801 | J24: =DebtSched!G25 -> 0 | K24: =DebtSched!H25 -> 0 | L24: =DebtSched!I25 -> 0 | M24: =DebtSched!J25 -> 0 | N24: =DebtSched!K25 -> 0 | O24: =DebtSched!L25 -> 1261.0198 | P24: =DebtSched!M25 -> 1939.8802 | ... R24: =DebtSched!O25 -> 2127.4592
B25: =IncStmt!B27 -> Term Loan A | E25: 0 | F25: =Summary!D10 -> 500 | H25: =SUM(E25:G25) -> 500 | I25: =DebtSched!F42 -> 437.5 | J25: =DebtSched!G42 -> 374.89858 | K25: =DebtSched!H42 -> 288.30284 | L25: =DebtSched!I42 -> 174.13402 | M25: =DebtSched!J42 -> 0 | N25: =DebtSched!K42 -> 0 | O25: =DebtSched!L42 -> 0 | P25: =DebtSched!M42 -> 0 | ... R25: =DebtSched!O42 -> 0
B26: =IncStmt!B28 -> Term Loan B | E26: 0 | F26: =Summary!D11 -> 2000 | H26: =SUM(E26:G26) -> 2000 | I26: =DebtSched!F57 -> 1980 | J26: =DebtSched!G57 -> 1960 | K26: =DebtSched!H57 -> 1940 | L26: =DebtSched!I57 -> 1920 | M26: =DebtSched!J57 -> 1849.6049 | N26: =DebtSched!K57 -> 1573.7025 | O26: =DebtSched!L57 -> 0 | P26: =DebtSched!M57 -> 0 | ... R26: =DebtSched!O57 -> 0
B27: Existing Term Loan | E27: 1000 | G27: =IF(OR(FinStructure=1,FinStructure=2,FinStructure=3,FinStructure=4),-BalSheet!E27,0) -> -1000 | H27: =SUM(E27:G27) -> 0 | I27: =$H$27 -> 0 | J27: =$H$27 -> 0 | K27: =$H$27 -> 0 | L27: =$H$27 -> 0 | M27: =$H$27 -> 0 | N27: =$H$27 -> 0 | O27: =$H$27 -> 0 | P27: =$H$27 -> 0 | ... R27: =$H$27 -> 0
B28: =Summary!B12 -> 2nd Lien | E28: 0 | F28: =Summary!D12 -> 300 | H28: =SUM(E28:G28) -> 300 | I28: =DebtSched!F71 -> 225 | J28: =DebtSched!G71 -> 150 | K28: =DebtSched!H71 -> 75 | L28: =DebtSched!I71 -> 0 | M28: =DebtSched!J71 -> 0 | N28: =DebtSched!K71 -> 0 | O28: =DebtSched!L71 -> 0 | P28: =DebtSched!M71 -> 0 | ... R28: =DebtSched!O71 -> 0
B29: =Summary!B13 -> Senior Notes | E29: 0 | F29: =Summary!D13 -> 1000 | H29: =SUM(E29:G29) -> 1000 | I29: =DebtSched!F83 -> 1000 | J29: =DebtSched!G83 -> 1000 | K29: =DebtSched!H83 -> 1000 | L29: =DebtSched!I83 -> 1000 | M29: =DebtSched!J83 -> 1000 | N29: =DebtSched!K83 -> 1000 | O29: =DebtSched!L83 -> 1000 | P29: =DebtSched!M83 -> 1000 | ... R29: =DebtSched!O83 -> 0
B30: Existing Senior Notes | E30: 500 | G30: =IF(OR(FinStructure=1,FinStructure=2,FinStructure=3,FinStructure=4),-E30,0) -> -500 | H30: =SUM(E30:G30) -> 0 | I30: =$H$30 -> 0 | J30: =$H$30 -> 0 | K30: =$H$30 -> 0 | L30: =$H$30 -> 0 | M30: =$H$30 -> 0 | N30: =$H$30 -> 0 | O30: =$H$30 -> 0 | P30: =$H$30 -> 0 | ... R30: =$H$30 -> 0
B31: =Summary!B14 -> Senior Subordinated Notes | E31: 0 | F31: =Summary!D14 -> 1000 | H31: =SUM(E31:G31) -> 1000 | I31: =DebtSched!F94 -> 1000 | J31: =DebtSched!G94 -> 1000 | K31: =DebtSched!H94 -> 1000 | L31: =DebtSched!I94 -> 1000 | M31: =DebtSched!J94 -> 1000 | N31: =DebtSched!K94 -> 1000 | O31: =DebtSched!L94 -> 1000 | P31: =DebtSched!M94 -> 0 | ... R31: =DebtSched!O94 -> 0
B32: Other Debt | E32: 0 | H32: =SUM(E32:G32) -> 0 | I32: =H32 -> 0 | J32: =I32 -> 0 | K32: =J32 -> 0 | L32: =K32 -> 0 | M32: =L32 -> 0 | N32: =M32 -> 0 | O32: =N32 -> 0 | P32: =O32 -> 0 | ... R32: =Q32 -> 0
B33: Deferred Income Taxes | E33: 300 | H33: =SUM(E33:G33) -> 300 | I33: =H33 -> 300 | J33: =I33 -> 300 | K33: =J33 -> 300 | L33: =K33 -> 300 | M33: =L33 -> 300 | N33: =M33 -> 300 | O33: =N33 -> 300 | P33: =O33 -> 300 | ... R33: =Q33 -> 300
B34: Other Long-term Liabilities | E34: 110 | H34: =SUM(E34:G34) -> 110 | I34: =H34 -> 110 | J34: =I34 -> 110 | K34: =J34 -> 110 | L34: =K34 -> 110 | M34: =L34 -> 110 | N34: =M34 -> 110 | O34: =N34 -> 110 | P34: =O34 -> 110 | ... R34: =Q34 -> 110
B35: Total Liabilities | E35: =E22+SUM(E24:E34) -> 2500 | H35: =H22+SUM(H24:H34) -> 5800 | I35: =I22+SUM(I24:I34) -> 5630.1747 | J35: =J22+SUM(J24:J34) -> 5480.5678 | K35: =K22+SUM(K24:K34) -> 5322.3989 | L35: =L22+SUM(L24:L34) -> 5140.6394 | M35: =M22+SUM(M24:M34) -> 4918.3879 | N35: =N22+SUM(N24:N34) -> 4665.5429 | O35: =O22+SUM(O24:O34) -> 4376.7246 | ... R35: =R22+SUM(R24:R34) -> 3319.8868
B37: Noncontrolling Interest | E37: 0 | H37: =SUM(E37:G37) -> 0 | I37: =H37 -> 0 | J37: =I37 -> 0 | K37: =J37 -> 0 | L37: =K37 -> 0 | M37: =L37 -> 0 | N37: =M37 -> 0 | O37: =N37 -> 0 | P37: =O37 -> 0 | ... R37: =Q37 -> 0
B38: Shareholders' Equity | E38: 3500 | F38: =Summary!D15-Summary!K12-Summary!K14 -> 2038.4417 | G38: =IF(OR(FinStructure=1,FinStructure=2,FinStructure=3,FinStructure=4),-E38,0) -> -3500 | H38: =SUM(E38:G38) -> 2038.4417 | I38: =H38+IncStmt!J42 -> 2093.6532 | J38: =I38+IncStmt!K42 -> 2176.1177 | K38: =J38+IncStmt!L42 -> 2293.5095 | L38: =K38+IncStmt!M42 -> 2441.5526 | M38: =L38+IncStmt!N42 -> 2616.8422 | N38: =M38+IncStmt!O42 -> 2821.6507 | O38: =N38+IncStmt!P42 -> 3062.5702 | P38: =O38+IncStmt!Q42 -> 3315.3173 | ... R38: =Q38+IncStmt!S42 -> 3992.2133
B39: Total Shareholders' Equity | E39: =SUM(E37:E38) -> 3500 | H39: =SUM(H37:H38) -> 2038.4417 | I39: =SUM(I37:I38) -> 2093.6532 | J39: =SUM(J37:J38) -> 2176.1177 | K39: =SUM(K37:K38) -> 2293.5095 | L39: =SUM(L37:L38) -> 2441.5526 | M39: =SUM(M37:M38) -> 2616.8422 | N39: =SUM(N37:N38) -> 2821.6507 | O39: =SUM(O37:O38) -> 3062.5702 | ... R39: =SUM(R37:R38) -> 3992.2133
B41: Total Liabilities and Equity | E41: =E35+E39 -> 6000 | H41: =H35+H39 -> 7838.4417 | I41: =I35+I39 -> 7723.8279 | J41: =J35+J39 -> 7656.6855 | K41: =K35+K39 -> 7615.9083 | L41: =L35+L39 -> 7582.192 | M41: =M35+M39 -> 7535.2301 | N41: =N35+N39 -> 7487.1936 | O41: =O35+O39 -> 7439.2948 | ... R41: =R35+R39 -> 7312.1001
B43: Balance Check | E43: =E17-E41 -> 0 | H43: =H17-H41 -> 0 | I43: =I17-I41 -> 0 | J43: =J17-J41 -> 0 | K43: =K17-K41 -> 0 | L43: =L17-L41 -> 0 | M43: =M17-M41 -> 0 | N43: =N17-N41 -> 0 | O43: =O17-O41 -> 0 | ... R43: =R17-R41 -> 0
B45: Net Working Capital | E45: =SUM(E7:E9)-SUM(E19:E21) -> 635 | H45: =SUM(H7:H9)-SUM(H19:H21) -> 635 | I45: =SUM(I7:I9)-SUM(I19:I21) -> 623.9698 | J45: =SUM(J7:J9)-SUM(J19:J21) -> 629.17878 | K45: =SUM(K7:K9)-SUM(K19:K21) -> 654.34593 | L45: =SUM(L7:L9)-SUM(L19:L21) -> 683.79149 | M45: =SUM(M7:M9)-SUM(M19:M21) -> 707.7242 | N45: =SUM(N7:N9)-SUM(N19:N21) -> 732.49454 | O45: =SUM(O7:O9)-SUM(O19:O21) -> 758.13185 | ... R45: =SUM(R7:R9)-SUM(R19:R21) -> 840.55434
B46: (Increase) / Decrease in Net Working Capital | I46: =H45-I45 -> 11.030199 | J46: =I45-J45 -> -5.2089758 | K46: =J45-K45 -> -25.167151 | L46: =K45-L45 -> -29.445567 | M46: =L45-M45 -> -23.932702 | N46: =M45-N45 -> -24.770347 | O46: =N45-O45 -> -25.637309 | P46: =O45-P45 -> -26.534615 | ... R46: =Q45-R45 -> -28.424543
B48: Balance Sheet Assumptions
...

Sheet CFStmt
B1: =Summary!$B$3 -> ($ in millions, fiscal year ending December 31)
B2: Cash Flow Statement
F3: Projection Period
F4: 1 | G4: =F4+1 -> 2 | H4: =G4+1 -> 3 | I4: =H4+1 -> 4 | J4: =I4+1 -> 5 | K4: =J4+1 -> 6 | L4: =K4+1 -> 7 | M4: =L4+1 -> 8 | N4: =M4+1 -> 9 | O4: =N4+1 -> 10
F5: =IncStmt!$I$5+F4 -> 2025 | G5: =IncStmt!$I$5+G4 -> 2026 | H5: =IncStmt!$I$5+H4 -> 2027 | I5: =IncStmt!$I$5+I4 -> 2028 | J5: =IncStmt!$I$5+J4 -> 2029 | K5: =IncStmt!$I$5+K4 -> 2030 | L5: =IncStmt!$I$5+L4 -> 2031 | M5: =IncStmt!$I$5+M4 -> 2032 | ... O5: =IncStmt!$I$5+O4 -> 2034
B6: Operating Activities
B7: Net Income | F7: =IncStmt!J42 -> 55.211538 | G7: =IncStmt!K42 -> 82.464517 | H7: =IncStmt!L42 -> 117.39178 | I7: =IncStmt!M42 -> 148.04314 | J7: =IncStmt!N42 -> 175.28957 | K7: =IncStmt!O42 -> 204.80854 | L7: =IncStmt!P42 -> 240.91949 | M7: =IncStmt!Q42 -> 252.74709 | ... O7: =IncStmt!S42 -> 344.60396
B8: Plus: Depreciation | F8: =IncStmt!J20 -> 166.7776 | G8: =IncStmt!K20 -> 170.94704 | H8: =IncStmt!L20 -> 177.78492 | I8: =IncStmt!M20 -> 185.78524 | J8: =IncStmt!N20 -> 192.28773 | K8: =IncStmt!O20 -> 199.0178 | L8: =IncStmt!P20 -> 205.98342 | M8: =IncStmt!Q20 -> 213.19284 | ... O8: =IncStmt!S20 -> 228.3775
B9: Plus: Amortization | F9: =IncStmt!J21 -> 66.71104 | G9: =IncStmt!K21 -> 68.378816 | H9: =IncStmt!L21 -> 71.113969 | I9: =IncStmt!M21 -> 74.314097 | J9: =IncStmt!N21 -> 76.915091 | K9: =IncStmt!O21 -> 79.607119 | L9: =IncStmt!P21 -> 82.393368 | M9: =IncStmt!Q21 -> 85.277136 | ... O9: =IncStmt!S21 -> 91.351
B10: Plus: Amortization of Financing Fees | F10: =IncStmt!J35 -> 18.257143 | G10: =IncStmt!K35 -> 18.257143 | H10: =IncStmt!L35 -> 18.257143 | I10: =IncStmt!M35 -> 16.257143 | J10: =IncStmt!N35 -> 16.257143 | K10: =IncStmt!O35 -> 16.257143 | L10: =IncStmt!P35 -> 15.007143 | M10: =IncStmt!Q35 -> 9.65 | ... O10: =IncStmt!S35 -> 5.9
B12: Changes in Working Capital Accounts
B13: (Inc.) / Dec. in Accounts Receivable | F13: =BalSheet!H7-BalSheet!I7 -> 15.007465 | G13: =BalSheet!I7-BalSheet!J7 -> -10.874813 | H13: =BalSheet!J7-BalSheet!K7 -> -17.834694 | I13: =BalSheet!K7-BalSheet!L7 -> -20.866592 | J13: =BalSheet!L7-BalSheet!M7 -> -16.959902 | K13: =BalSheet!M7-BalSheet!N7 -> -17.553499 | L13: =BalSheet!N7-BalSheet!O7 -> -18.167871 | M13: =BalSheet!O7-BalSheet!P7 -> -18.803747 | ... O13: =BalSheet!Q7-BalSheet!R7 -> -20.143044
B14: (Inc.) / Dec. in Inventories | F14: =BalSheet!H8-BalSheet!I8 -> 19.888107 | G14: =BalSheet!I8-BalSheet!J8 -> -14.502797 | H14: =BalSheet!J8-BalSheet!K8 -> -23.784588 | I14: =BalSheet!K8-BalSheet!L8 -> -27.827968 | J14: =BalSheet!L8-BalSheet!M8 -> -22.617954 | K14: =BalSheet!M8-BalSheet!N8 -> -23.409582 | L14: =BalSheet!N8-BalSheet!O8 -> -24.228917 | M14: =BalSheet!O8-BalSheet!P8 -> -25.076929 | ... O14: =BalSheet!Q8-BalSheet!R8 -> -26.863034
B15: (Inc.) / Dec. in Prepaid and Other Current Assets | F15: =BalSheet!H9-BalSheet!I9 -> -5.25 | G15: =BalSheet!I9-BalSheet!J9 -> 5.8840192 | H15: =BalSheet!J9-BalSheet!K9 -> -6.9746392 | I15: =BalSheet!K9-BalSheet!L9 -> -8.1603279 | J15: =BalSheet!L9-BalSheet!M9 -> -6.6325332 | K15: =BalSheet!M9-BalSheet!N9 -> -6.8646718 | L15: =BalSheet!N9-BalSheet!O9 -> -7.1049354 | M15: =BalSheet!O9-BalSheet!P9 -> -7.3536081 | ... O15: =BalSheet!Q9-BalSheet!R9 -> -7.8773688
B17: Inc. / (Dec.) in Accounts Receivable | F17: =BalSheet!I19-BalSheet!H19 -> -7.1905412 | G17: =BalSheet!J19-BalSheet!I19 -> 5.1952365 | H17: =BalSheet!K19-BalSheet!J19 -> 8.5201878 | I17: =BalSheet!L19-BalSheet!K19 -> 9.9686197 | J17: =BalSheet!M19-BalSheet!L19 -> 8.1022726 | K17: =BalSheet!N19-BalSheet!M19 -> 8.3858521 | L17: =BalSheet!O19-BalSheet!N19 -> 8.679357 | M17: =BalSheet!P19-BalSheet!O19 -> 8.9831345 | ... O17: =BalSheet!R19-BalSheet!Q19 -> 9.6229582
B18: Inc. / (Dec.) in Accrued Liabilities | F18: =BalSheet!I20-BalSheet!H20 -> -8.15584 | G18: =BalSheet!J20-BalSheet!I20 -> 6.671104 | H18: =BalSheet!K20-BalSheet!J20 -> 10.940611 | I18: =BalSheet!L20-BalSheet!K20 -> 12.800514 | J18: =BalSheet!M20-BalSheet!L20 -> 10.403974 | K18: =BalSheet!N20-BalSheet!M20 -> 10.768113 | L18: =BalSheet!O20-BalSheet!N20 -> 11.144997 | M18: =BalSheet!P20-BalSheet!O20 -> 11.535072 | ... O18: =BalSheet!R20-BalSheet!Q20 -> 12.356657
B19: Inc. / (Dec.) in Other Current Liabilities | F19: =BalSheet!I21-BalSheet!H21 -> -3.268992 | G19: =BalSheet!J21-BalSheet!I21 -> 2.4182752 | H19: =BalSheet!K21-BalSheet!J21 -> 3.9659713 | I19: =BalSheet!L21-BalSheet!K21 -> 4.6401865 | J19: =BalSheet!M21-BalSheet!L21 -> 3.7714404 | K19: =BalSheet!N21-BalSheet!M21 -> 3.9034408 | L19: =BalSheet!O21-BalSheet!N21 -> 4.0400613 | M19: =BalSheet!P21-BalSheet!O21 -> 4.1814634 | ... O19: =BalSheet!R21-BalSheet!Q21 -> 4.4792882
B20: (Inc.) / Dec. in Net Working Capital | F20: =SUM(F13:F19) -> 11.030199 | G20: =SUM(G13:G19) -> -5.2089758 | H20: =SUM(H13:H19) -> -25.167151 | I20: =SUM(I13:I19) -> -29.445567 | J20: =SUM(J13:J19) -> -23.932702 | K20: =SUM(K13:K19) -> -24.770347 | L20: =SUM(L13:L19) -> -25.637309 | M20: =SUM(M13:M19) -> -26.534615 | ... O20: =SUM(O13:O19) -> -28.424543
B21: Cash Flow from Operating Activities | F21: =SUM(F7:F10)+F20 -> 317.98752 | G21: =SUM(G7:G10)+G20 -> 334.83854 | H21: =SUM(H7:H10)+H20 -> 359.38066 | I21: =SUM(I7:I10)+I20 -> 394.95406 | J21: =SUM(J7:J10)+J20 -> 436.81683 | K21: =SUM(K7:K10)+K20 -> 474.92025 | L21: =SUM(L7:L10)+L20 -> 518.66611 | M21: =SUM(M7:M10)+M20 -> 534.33245 | ... O21: =SUM(O7:O10)+O20 -> 641.80791
B23: Investing Activities
B24: Capital Expenditures | F24: =-F48*IncStmt!J6 -> -166.7776 | G24: =-G48*IncStmt!K6 -> -170.94704 | H24: =-H48*IncStmt!L6 -> -177.78492 | I24: =-I48*IncStmt!M6 -> -185.78524 | J24: =-J48*IncStmt!N6 -> -192.28773 | K24: =-K48*IncStmt!O6 -> -199.0178 | L24: =-L48*IncStmt!P6 -> -205.98342 | M24: =-M48*IncStmt!Q6 -> -213.19284 | ... O24: =-O48*IncStmt!S6 -> -228.3775
B25: Other Investing Activities | F25: 0 | G25: 0 | H25: 0 | I25: 0 | J25: 0 | K25: 0 | L25: 0 | M25: 0 | N25: 0 | O25: 0
B26: Cash Flow from Investing Activities | F26: =SUM(F24:F25) -> -166.7776 | G26: =SUM(G24:G25) -> -170.94704 | H26: =SUM(H24:H25) -> -177.78492 | I26: =SUM(I24:I25) -> -185.78524 | J26: =SUM(J24:J25) -> -192.28773 | K26: =SUM(K24:K25) -> -199.0178 | L26: =SUM(L24:L25) -> -205.98342 | M26: =SUM(M24:M25) -> -213.19284 | ... O26: =SUM(O24:O25) -> -228.3775
B28: Financing Activities
B29: Revolving Credit Facility | F29: =DebtSched!F24 -> 6.2900801 | G29: =DebtSched!G24 -> -6.2900801 | H29: =DebtSched!H24 -> 0 | I29: =DebtSched!I24 -> 0 | J29: =DebtSched!J24 -> 0 | K29: =DebtSched!K24 -> 0 | L29: =DebtSched!L24 -> 1261.0198 | M29: =DebtSched!M24 -> 678.86039 | ... O29: =DebtSched!O24 -> 586.56959 | P29: (1 point for the row)
B30: Term Loan A | F30: =DebtSched!F40+DebtSched!F41 -> -62.5 | G30: =DebtSched!G40+DebtSched!G41 -> -62.60142 | H30: =DebtSched!H40+DebtSched!H41 -> -86.595738 | I30: =DebtSched!I40+DebtSched!I41 -> -114.16882 | J30: =DebtSched!J40+DebtSched!J41 -> -174.13402 | K30: =DebtSched!K40+DebtSched!K41 -> 0 | L30: =DebtSched!L40+DebtSched!L41 -> 0 | M30: =DebtSched!M40+DebtSched!M41 -> 0 | ... O30: =DebtSched!O40+DebtSched!O41 -> 0 | P30: (1 point for the row)
B31: Term Loan B | F31: =DebtSched!F55+DebtSched!F56 -> -20 | G31: =DebtSched!G55+DebtSched!G56 -> -20 | H31: =DebtSched!H55+DebtSched!H56 -> -20 | I31: =DebtSched!I55+DebtSched!I56 -> -20 | J31: =DebtSched!J55+DebtSched!J56 -> -70.395079 | K31: =DebtSched!K55+DebtSched!K56 -> -275.90245 | L31: =DebtSched!L55+DebtSched!L56 -> -1573.7025 | M31: =DebtSched!M55+DebtSched!M56 -> 0 | ... O31: =DebtSched!O55+DebtSched!O56 -> 0 | P31: (1 point for the row)
B32: 2nd Lien | F32: =DebtSched!F70 -> -75 | G32: =DebtSched!G70 -> -75 | H32: =DebtSched!H70 -> -75 | I32: =DebtSched!I70 -> -75 | J32: =DebtSched!J70 -> 0 | K32: =DebtSched!K70 -> 0 | L32: =DebtSched!L70 -> 0 | M32: =DebtSched!M70 -> 0 | ... O32: =DebtSched!O70 -> 0 | P32: (1 point for the row)
B33: Senior Notes | F33: =DebtSched!F82 -> 0 | G33: =DebtSched!G82 -> 0 | H33: =DebtSched!H82 -> 0 | I33: =DebtSched!I82 -> 0 | J33: =DebtSched!J82 -> 0 | K33: =DebtSched!K82 -> 0 | L33: =DebtSched!L82 -> 0 | M33: =DebtSched!M82 -> 0 | ... O33: =DebtSched!O82 -> -1000 | P33: (1 point for the row)
B34: Senior Subordinated Notes | F34: =DebtSched!F93 -> 0 | G34: =DebtSched!G93 -> 0 | H34: =DebtSched!H93 -> 0 | I34: =DebtSched!I93 -> 0 | J34: =DebtSched!J93 -> 0 | K34: =DebtSched!K93 -> 0 | L34: =DebtSched!L93 -> 0 | M34: =DebtSched!M93 -> -1000 | ... O34: =DebtSched!O93 -> 0 | P34: (1 point for the row)
B35: Other Debt
B36: Dividends
B37: Equity Issuance (Repurchase)
B38: Cash Flow from Financing Activities | F38: =SUM(F29:F37) -> -151.20992 | G38: =SUM(G29:G37) -> -163.8915 | H38: =SUM(H29:H37) -> -181.59574 | I38: =SUM(I29:I37) -> -209.16882 | J38: =SUM(J29:J37) -> -244.5291 | K38: =SUM(K29:K37) -> -275.90245 | L38: =SUM(L29:L37) -> -312.68269 | M38: =SUM(M29:M37) -> -321.13961 | ... O38: =SUM(O29:O37) -> -413.43041
B40: Excess Cash for the Period | F40: =F21+F26+F38 -> 0 | G40: =G21+G26+G38 -> 0 | H40: =H21+H26+H38 -> 0 | I40: =I21+I26+I38 -> 0 | J40: =J21+J26+J38 -> 0 | K40: =K21+K26+K38 -> 0 | L40: =L21+L26+L38 -> 0 | M40: =M21+M26+M38 -> 0 | ... O40: =O21+O26+O38 -> 0
B41: Beginning Cash Balance | F41: =BalSheet!H6 -> 0 | G41: =BalSheet!I6 -> 0 | H41: =BalSheet!J6 -> 0 | I41: =BalSheet!K6 -> 0 | J41: =BalSheet!L6 -> 0 | K41: =BalSheet!M6 -> 0 | L41: =BalSheet!N6 -> 0 | M41: =BalSheet!O6 -> 0 | ... O41: =BalSheet!Q6 -> 0
B42: Ending Cash Balance | F42: =F40+F41 -> 0 | G42: =G40+G41 -> 0 | H42: =H40+H41 -> 0 | I42: =I40+I41 -> 0 | J42: =J40+J41 -> 0 | K42: =K40+K41 -> 0 | L42: =L40+L41 -> 0 | M42: =M40+M41 -> 0 | ... O42: =O40+O41 -> 0
B47: Cash Flow Statement Assumptions
B48: Capital Expenditures (% of sales) | F48: =Assumptions1!F45 -> 0.05 | G48: =Assumptions1!G45 -> 0.05 | H48: =Assumptions1!H45 -> 0.05 | I48: =Assumptions1!I45 -> 0.05 | J48: =Assumptions1!J45 -> 0.05 | K48: =Assumptions1!K45 -> 0.05 | L48: =Assumptions1!L45 -> 0.05 | M48: =Assumptions1!M45 -> 0.05 | ... O48: =Assumptions1!O45 -> 0.05
XX1000: 127155

Sheet RetAnalysis
B1: =Summary!$B$3 -> ($ in millions, fiscal year ending December 31)
B2: Returns Analysis
G3: Projection Period
F4: =IncStmt!$I$4 -> Pro Forma | G4: 1 | H4: =G4+1 -> 2 | I4: =H4+1 -> 3 | J4: =I4+1 -> 4 | K4: =J4+1 -> 5 | L4: =K4+1 -> 6 | M4: =L4+1 -> 7 | N4: =M4+1 -> 8 | O4: =N4+1 -> 9 | P4: =O4+1 -> 10
F5: =IncStmt!$I$5 -> 2024 | G5: =IncStmt!$I$5+G4 -> 2025 | H5: =IncStmt!$I$5+H4 -> 2026 | I5: =IncStmt!$I$5+I4 -> 2027 | J5: =IncStmt!$I$5+J4 -> 2028 | K5: =IncStmt!$I$5+K4 -> 2029 | L5: =IncStmt!$I$5+L4 -> 2030 | M5: =IncStmt!$I$5+M4 -> 2031 | N5: =IncStmt!$I$5+N4 -> 2032 | ... P5: =IncStmt!$I$5+P4 -> 2034
B6: Entry EBITDA Multiple | E6: 10.5
B7: Initial Equity Investment | F7: =Summary!D15 -> 2088.4417
B8: EBITDA | G8: =IncStmt!J17 -> 733.82144 | H8: =IncStmt!K17 -> 752.16698 | I8: =IncStmt!L17 -> 782.25366 | J8: =IncStmt!M17 -> 817.45507 | K8: =IncStmt!N17 -> 846.066 | L8: =IncStmt!O17 -> 875.67831 | M8: =IncStmt!P17 -> 906.32705 | N8: =IncStmt!Q17 -> 938.04849 | ... P8: =IncStmt!S17 -> 1004.861 | Q8: (1 point for the row)
B9: Exit EBITDA Multiple | E9: 10.5
B10: Enterprise Value at Exit | G10: =G8*$E$9 -> 7705.1251 | H10: =H8*$E$9 -> 7897.7532 | I10: =I8*$E$9 -> 8213.6634 | J10: =J8*$E$9 -> 8583.2782 | K10: =K8*$E$9 -> 8883.693 | L10: =L8*$E$9 -> 9194.6222 | M10: =M8*$E$9 -> 9516.434 | N10: =N8*$E$9 -> 9849.5092 | ... P10: =P8*$E$9 -> 10551.04 | Q10: (1 point for the row)
B12: Less: Net Debt
B13: Revolving Credit Facility | G13: =BalSheet!I24 -> 6.2900801 | H13: =BalSheet!J24 -> 0 | I13: =BalSheet!K24 -> 0 | J13: =BalSheet!L24 -> 0 | K13: =BalSheet!M24 -> 0 | L13: =BalSheet!N24 -> 0 | M13: =BalSheet!O24 -> 1261.0198 | N13: =BalSheet!P24 -> 1939.8802 | ... P13: =BalSheet!R24 -> 2127.4592 | Q13: (1 point for the row)
B14: Term Loan A | G14: =BalSheet!I25 -> 437.5 | H14: =BalSheet!J25 -> 374.89858 | I14: =BalSheet!K25 -> 288.30284 | J14: =BalSheet!L25 -> 174.13402 | K14: =BalSheet!M25 -> 0 | L14: =BalSheet!N25 -> 0 | M14: =BalSheet!O25 -> 0 | N14: =BalSheet!P25 -> 0 | ... P14: =BalSheet!R25 -> 0 | Q14: (1 point for the row)
B15: Term Loan B | G15: =BalSheet!I26 -> 1980 | H15: =BalSheet!J26 -> 1960 | I15: =BalSheet!K26 -> 1940 | J15: =BalSheet!L26 -> 1920 | K15: =BalSheet!M26 -> 1849.6049 | L15: =BalSheet!N26 -> 1573.7025 | M15: =BalSheet!O26 -> 0 | N15: =BalSheet!P26 -> 0 | ... P15: =BalSheet!R26 -> 0 | Q15: (1 point for the row)
B16: 2nd Lien | G16: =BalSheet!I28 -> 225 | H16: =BalSheet!J28 -> 150 | I16: =BalSheet!K28 -> 75 | J16: =BalSheet!L28 -> 0 | K16: =BalSheet!M28 -> 0 | L16: =BalSheet!N28 -> 0 | M16: =BalSheet!O28 -> 0 | N16: =BalSheet!P28 -> 0 | ... P16: =BalSheet!R28 -> 0 | Q16: (1 point for the row)
B17: Senior Notes | G17: =BalSheet!I29 -> 1000 | H17: =BalSheet!J29 -> 1000 | I17: =BalSheet!K29 -> 1000 | J17: =BalSheet!L29 -> 1000 | K17: =BalSheet!M29 -> 1000 | L17: =BalSheet!N29 -> 1000 | M17: =BalSheet!O29 -> 1000 | N17: =BalSheet!P29 -> 1000 | ... P17: =BalSheet!R29 -> 0 | Q17: (1 point for the row)
B18: Senior Subordinated Notes | G18: =BalSheet!I31 -> 1000 | H18: =BalSheet!J31 -> 1000 | I18: =BalSheet!K31 -> 1000 | J18: =BalSheet!L31 -> 1000 | K18: =BalSheet!M31 -> 1000 | L18: =BalSheet!N31 -> 1000 | M18: =BalSheet!O31 -> 1000 | N18: =BalSheet!P31 -> 0 | ... P18: =BalSheet!R31 -> 0 | Q18: (1 point for the row)
B19: Other Debt | G19: =BalSheet!I32 -> 0 | H19: =BalSheet!J32 -> 0 | I19: =BalSheet!K32 -> 0 | J19: =BalSheet!L32 -> 0 | K19: =BalSheet!M32 -> 0 | L19: =BalSheet!N32 -> 0 | M19: =BalSheet!O32 -> 0 | N19: =BalSheet!P32 -> 0 | ... P19: =BalSheet!R32 -> 0 | Q19: (1 point for the row)
B20: Total Debt | G20: =SUM(G13:G19) -> 4648.7901 | H20: =SUM(H13:H19) -> 4484.8986 | I20: =SUM(I13:I19) -> 4303.3028 | J20: =SUM(J13:J19) -> 4094.134 | K20: =SUM(K13:K19) -> 3849.6049 | L20: =SUM(L13:L19) -> 3573.7025 | M20: =SUM(M13:M19) -> 3261.0198 | N20: =SUM(N13:N19) -> 2939.8802 | ... P20: =SUM(P13:P19) -> 2127.4592 | Q20: (1 point for the row)
B21: Less: Cash and Cash Equivalents | G21: =BalSheet!I6 -> 0 | H21: =BalSheet!J6 -> 0 | I21: =BalSheet!K6 -> 0 | J21: =BalSheet!L6 -> 0 | K21: =BalSheet!M6 -> 0 | L21: =BalSheet!N6 -> 0 | M21: =BalSheet!O6 -> 0 | N21: =BalSheet!P6 -> 0 | ... P21: =BalSheet!R6 -> 0 | Q21: (1 point for the row)
B22: Net Debt | G22: =G20-G21 -> 4648.7901 | H22: =H20-H21 -> 4484.8986 | I22: =I20-I21 -> 4303.3028 | J22: =J20-J21 -> 4094.134 | K22: =K20-K21 -> 3849.6049 | L22: =L20-L21 -> 3573.7025 | M22: =M20-M21 -> 3261.0198 | N22: =N20-N21 -> 2939.8802 | ... P22: =P20-P21 -> 2127.4592 | Q22: (1 point for the row)
B24: Equity Value at Exit | G24: =G10-G22 -> 3056.335 | H24: =H10-H22 -> 3412.8547 | I24: =I10-I22 -> 3910.3605 | J24: =J10-J22 -> 4489.1442 | K24: =K10-K22 -> 5034.088 | L24: =L10-L22 -> 5620.9198 | M24: =M10-M22 -> 6255.4142 | N24: =N10-N22 -> 6909.629 | ... P24: =P10-P22 -> 8423.5813 | Q24: (1 point for the row)
B26: Cash Return | G26: =IF(ISERROR(G24/$F$7),0,G24/$F$7) -> 1.4634524 | H26: =IF(ISERROR(H24/$F$7),0,H24/$F$7) -> 1.6341633 | I26: =IF(ISERROR(I24/$F$7),0,I24/$F$7) -> 1.872382 | J26: =IF(ISERROR(J24/$F$7),0,J24/$F$7) -> 2.1495186 | K26: =IF(ISERROR(K24/$F$7),0,K24/$F$7) -> 2.4104518 | L26: =IF(ISERROR(L24/$F$7),0,L24/$F$7) -> 2.6914421 | M26: =IF(ISERROR(M24/$F$7),0,M24/$F$7) -> 2.9952545 | N26: =IF(ISERROR(N24/$F$7),0,N24/$F$7) -> 3.3085095 | ... P26: =IF(ISERROR(P24/$F$7),0,P24/$F$7) -> 4.0334291
G28: =G4 -> 1 | H28: =H4 -> 2 | I28: =I4 -> 3 | J28: =J4 -> 4 | K28: =K4 -> 5 | L28: =L4 -> 6 | M28: =M4 -> 7 | N28: =N4 -> 8 | ... P28: =P4 -> 10
E29: Exit Year | G29: =G5 -> 2025 | H29: =H5 -> 2026 | I29: =I5 -> 2027 | J29: =J5 -> 2028 | K29: =K5 -> 2029 | L29: =L5 -> 2030 | M29: =M5 -> 2031 | N29: =N5 -> 2032 | ... P29: =P5 -> 2034
B30: Initial Equity Investment | G30: =-$F$7 -> -2088.4417 | H30: =-$F$7 -> -2088.4417 | I30: =-$F$7 -> -2088.4417 | J30: =-$F$7 -> -2088.4417 | K30: =-$F$7 -> -2088.4417 | L30: =-$F$7 -> -2088.4417 | M30: =-$F$7 -> -2088.4417 | N30: =-$F$7 -> -2088.4417 | ... P30: =-$F$7 -> -2088.4417 | Q30: (10 points for G30:P40)
B31: Equity Proceeds | E31: 1 | G31: =IF($E31<G$28,0,IF($E31=G$28,G$24,"")) -> 3056.335 | H31: =IF($E31<H$28,0,IF($E31=H$28,H$24,"")) -> 0 | I31: =IF($E31<I$28,0,IF($E31=I$28,I$24,"")) -> 0 | J31: =IF($E31<J$28,0,IF($E31=J$28,J$24,"")) -> 0 | K31: =IF($E31<K$28,0,IF($E31=K$28,K$24,"")) -> 0 | L31: =IF($E31<L$28,0,IF($E31=L$28,L$24,"")) -> 0 | M31: =IF($E31<M$28,0,IF($E31=M$28,M$24,"")) -> 0 | N31: =IF($E31<N$28,0,IF($E31=N$28,N$24,"")) -> 0 | ... P31: =IF($E31<P$28,0,IF($E31=P$28,P$24,"")) -> 0
E32: =E31+1 -> 2 | G32: =IF($E32<G$28,0,IF($E32=G$28,G$24,"")) | H32: =IF($E32<H$28,0,IF($E32=H$28,H$24,"")) -> 3412.8547 | I32: =IF($E32<I$28,0,IF($E32=I$28,I$24,"")) -> 0 | J32: =IF($E32<J$28,0,IF($E32=J$28,J$24,"")) -> 0 | K32: =IF($E32<K$28,0,IF($E32=K$28,K$24,"")) -> 0 | L32: =IF($E32<L$28,0,IF($E32=L$28,L$24,"")) -> 0 | M32: =IF($E32<M$28,0,IF($E32=M$28,M$24,"")) -> 0 | N32: =IF($E32<N$28,0,IF($E32=N$28,N$24,"")) -> 0 | ... P32: =IF($E32<P$28,0,IF($E32=P$28,P$24,"")) -> 0
E33: =E32+1 -> 3 | G33: =IF($E33<G$28,0,IF($E33=G$28,G$24,"")) | H33: =IF($E33<H$28,0,IF($E33=H$28,H$24,"")) | I33: =IF($E33<I$28,0,IF($E33=I$28,I$24,"")) -> 3910.3605 | J33: =IF($E33<J$28,0,IF($E33=J$28,J$24,"")) -> 0 | K33: =IF($E33<K$28,0,IF($E33=K$28,K$24,"")) -> 0 | L33: =IF($E33<L$28,0,IF($E33=L$28,L$24,"")) -> 0 | M33: =IF($E33<M$28,0,IF($E33=M$28,M$24,"")) -> 0 | N33: =IF($E33<N$28,0,IF($E33=N$28,N$24,"")) -> 0 | ... P33: =IF($E33<P$28,0,IF($E33=P$28,P$24,"")) -> 0
E34: =E33+1 -> 4 | G34: =IF($E34<G$28,0,IF($E34=G$28,G$24,"")) | H34: =IF($E34<H$28,0,IF($E34=H$28,H$24,"")) | I34: =IF($E34<I$28,0,IF($E34=I$28,I$24,"")) | J34: =IF($E34<J$28,0,IF($E34=J$28,J$24,"")) -> 4489.1442 | K34: =IF($E34<K$28,0,IF($E34=K$28,K$24,"")) -> 0 | L34: =IF($E34<L$28,0,IF($E34=L$28,L$24,"")) -> 0 | M34: =IF($E34<M$28,0,IF($E34=M$28,M$24,"")) -> 0 | N34: =IF($E34<N$28,0,IF($E34=N$28,N$24,"")) -> 0 | ... P34: =IF($E34<P$28,0,IF($E34=P$28,P$24,"")) -> 0
E35: =E34+1 -> 5 | G35: =IF($E35<G$28,0,IF($E35=G$28,G$24,"")) | H35: =IF($E35<H$28,0,IF($E35=H$28,H$24,"")) | I35: =IF($E35<I$28,0,IF($E35=I$28,I$24,"")) | J35: =IF($E35<J$28,0,IF($E35=J$28,J$24,"")) | K35: =IF($E35<K$28,0,IF($E35=K$28,K$24,"")) -> 5034.088 | L35: =IF($E35<L$28,0,IF($E35=L$28,L$24,"")) -> 0 | M35: =IF($E35<M$28,0,IF($E35=M$28,M$24,"")) -> 0 | N35: =IF($E35<N$28,0,IF($E35=N$28,N$24,"")) -> 0 | ... P35: =IF($E35<P$28,0,IF($E35=P$28,P$24,"")) -> 0
E36: =E35+1 -> 6 | G36: =IF($E36<G$28,0,IF($E36=G$28,G$24,"")) | H36: =IF($E36<H$28,0,IF($E36=H$28,H$24,"")) | I36: =IF($E36<I$28,0,IF($E36=I$28,I$24,"")) | J36: =IF($E36<J$28,0,IF($E36=J$28,J$24,"")) | K36: =IF($E36<K$28,0,IF($E36=K$28,K$24,"")) | L36: =IF($E36<L$28,0,IF($E36=L$28,L$24,"")) -> 5620.9198 | M36: =IF($E36<M$28,0,IF($E36=M$28,M$24,"")) -> 0 | N36: =IF($E36<N$28,0,IF($E36=N$28,N$24,"")) -> 0 | ... P36: =IF($E36<P$28,0,IF($E36=P$28,P$24,"")) -> 0
E37: =E36+1 -> 7 | G37: =IF($E37<G$28,0,IF($E37=G$28,G$24,"")) | H37: =IF($E37<H$28,0,IF($E37=H$28,H$24,"")) | I37: =IF($E37<I$28,0,IF($E37=I$28,I$24,"")) | J37: =IF($E37<J$28,0,IF($E37=J$28,J$24,"")) | K37: =IF($E37<K$28,0,IF($E37=K$28,K$24,"")) | L37: =IF($E37<L$28,0,IF($E37=L$28,L$24,"")) | M37: =IF($E37<M$28,0,IF($E37=M$28,M$24,"")) -> 6255.4142 | N37: =IF($E37<N$28,0,IF($E37=N$28,N$24,"")) -> 0 | ... P37: =IF($E37<P$28,0,IF($E37=P$28,P$24,"")) -> 0
E38: =E37+1 -> 8 | G38: =IF($E38<G$28,0,IF($E38=G$28,G$24,"")) | H38: =IF($E38<H$28,0,IF($E38=H$28,H$24,"")) | I38: =IF($E38<I$28,0,IF($E38=I$28,I$24,"")) | J38: =IF($E38<J$28,0,IF($E38=J$28,J$24,"")) | K38: =IF($E38<K$28,0,IF($E38=K$28,K$24,"")) | L38: =IF($E38<L$28,0,IF($E38=L$28,L$24,"")) | M38: =IF($E38<M$28,0,IF($E38=M$28,M$24,"")) | N38: =IF($E38<N$28,0,IF($E38=N$28,N$24,"")) -> 6909.629 | ... P38: =IF($E38<P$28,0,IF($E38=P$28,P$24,"")) -> 0
E39: =E38+1 -> 9 | G39: =IF($E39<G$28,0,IF($E39=G$28,G$24,"")) | H39: =IF($E39<H$28,0,IF($E39=H$28,H$24,"")) | I39: =IF($E39<I$28,0,IF($E39=I$28,I$24,"")) | J39: =IF($E39<J$28,0,IF($E39=J$28,J$24,"")) | K39: =IF($E39<K$28,0,IF($E39=K$28,K$24,"")) | L39: =IF($E39<L$28,0,IF($E39=L$28,L$24,"")) | M39: =IF($E39<M$28,0,IF($E39=M$28,M$24,"")) | N39: =IF($E39<N$28,0,IF($E39=N$28,N$24,"")) | ... P39: =IF($E39<P$28,0,IF($E39=P$28,P$24,"")) -> 0
E40: =E39+1 -> 10 | G40: =IF($E40<G$28,0,IF($E40=G$28,G$24,"")) | H40: =IF($E40<H$28,0,IF($E40=H$28,H$24,"")) | I40: =IF($E40<I$28,0,IF($E40=I$28,I$24,"")) | J40: =IF($E40<J$28,0,IF($E40=J$28,J$24,"")) | K40: =IF($E40<K$28,0,IF($E40=K$28,K$24,"")) | L40: =IF($E40<L$28,0,IF($E40=L$28,L$24,"")) | M40: =IF($E40<M$28,0,IF($E40=M$28,M$24,"")) | N40: =IF($E40<N$28,0,IF($E40=N$28,N$24,"")) | ... P40: =IF($E40<P$28,0,IF($E40=P$28,P$24,"")) -> 8423.5813
B41: IRR | G41: =IF(ISERROR(IRR(G30:G40,0.1)),"NA",IRR(G30:G40,0.1)) -> 0.46345244 | H41: =IF(ISERROR(IRR(H30:H40,0.1)),"NA",IRR(H30:H40,0.1)) -> 0.27834396 | I41: =IF(ISERROR(IRR(I30:I40,0.1)),"NA",IRR(I30:I40,0.1)) -> 0.23253185 | J41: =IF(ISERROR(IRR(J30:J40,0.1)),"NA",IRR(J30:J40,0.1)) -> 0.21083594 | K41: =IF(ISERROR(IRR(K30:K40,0.1)),"NA",IRR(K30:K40,0.1)) -> 0.19239375 | L41: =IF(ISERROR(IRR(L30:L40,0.1)),"NA",IRR(L30:L40,0.1)) -> 0.17940828 | M41: =IF(ISERROR(IRR(M30:M40,0.1)),"NA",IRR(M30:M40,0.1)) -> 0.16966626 | N41: =IF(ISERROR(IRR(N30:N40,0.1)),"NA",IRR(N30:N40,0.1)) -> 0.16132573 | ... P41: =IF(ISERROR(IRR(P30:P40,0.1)),"NA",IRR(P30:P40,0.1)) -> 0.14965476
C43: (7 points for data table) | K43: (10 points for data table)
C44: IRR Assuming Exit after Year 5 | K44: ="IRR Assuming "&TEXT(EntryMultiple,"0.0x")&" Entry Multiple" -> IRR Assuming 10.5x Entry Multiple
D45: Exit Multiple | L45: Exit Year
...

Sheet DebtSched
B1: =Summary!$B$3 -> ($ in millions, fiscal year ending December 31)
B2: Debt Schedule
F3: Projection Period
E4: =IncStmt!$I$4 -> Pro Forma | F4: 1 | G4: =F4+1 -> 2 | H4: =G4+1 -> 3 | I4: =H4+1 -> 4 | J4: =I4+1 -> 5 | K4: =J4+1 -> 6 | L4: =K4+1 -> 7 | M4: =L4+1 -> 8 | N4: =M4+1 -> 9 | O4: =N4+1 -> 10
E5: =IncStmt!$I$5 -> 2024 | F5: =IncStmt!$I$5+F4 -> 2025 | G5: =IncStmt!$I$5+G4 -> 2026 | H5: =IncStmt!$I$5+H4 -> 2027 | I5: =IncStmt!$I$5+I4 -> 2028 | J5: =IncStmt!$I$5+J4 -> 2029 | K5: =IncStmt!$I$5+K4 -> 2030 | L5: =IncStmt!$I$5+L4 -> 2031 | M5: =IncStmt!$I$5+M4 -> 2032 | ... O5: =IncStmt!$I$5+O4 -> 2034
B6: Forward SOFR Curve | E6: 0.05 | F6: 0.046 | G6: 0.042 | H6: 0.037 | I6: 0.037 | J6: 0.037 | K6: 0.037 | L6: 0.037 | M6: 0.037 | N6: 0.037 | O6: 0.037
B7: Minimum Cash Balance | D7: 0
B9: Cash Flow from Operating Activities | F9: =CFStmt!F21 -> 317.98752 | G9: =CFStmt!G21 -> 334.83854 | H9: =CFStmt!H21 -> 359.38066 | I9: =CFStmt!I21 -> 394.95406 | J9: =CFStmt!J21 -> 436.81683 | K9: =CFStmt!K21 -> 474.92025 | L9: =CFStmt!L21 -> 518.66611 | M9: =CFStmt!M21 -> 534.33245 | ... O9: =CFStmt!O21 -> 641.80791
B10: Cash Flow from Investing Activities | F10: =CFStmt!F26 -> -166.7776 | G10: =CFStmt!G26 -> -170.94704 | H10: =CFStmt!H26 -> -177.78492 | I10: =CFStmt!I26 -> -185.78524 | J10: =CFStmt!J26 -> -192.28773 | K10: =CFStmt!K26 -> -199.0178 | L10: =CFStmt!L26 -> -205.98342 | M10: =CFStmt!M26 -> -213.19284 | ... O10: =CFStmt!O26 -> -228.3775
