Workbook

Sheet DCF
A1: Home Depot
A2: Discounted Cash Flow Analysis
A3: For the Years Ended
A4: Millions of Dollars | Q4: Name | R4: Email
N5: Terminal
B6: =2023 -> 2023 | C6: =+B6+1 -> 2024 | D6: =+C6+1 -> 2025 | E6: =+D6+1 -> 2026 | F6: =+E6+1 -> 2027 | G6: =+F6+1 -> 2028 | H6: =+G6+1 -> 2029 | I6: =+H6+1 -> 2030 | J6: =+I6+1 -> 2031 | ... M6: =+L6+1 -> 2034 | N6: Value | Q6: Sharang Mantri | R6: smantri3@illinois.edu
B7: -------------- | C7: -------------- | D7: -------------- | E7: -------------- | F7: -------------- | G7: -------------- | H7: -------------- | I7: -------------- | J7: -------------- | K7: -------------- | L7: -------------- | M7: -------------- | N7: --------------
A8: Revenue | B8: 152669 | C8: 159514 | D8: =C8*(1+D56) -> 163980.39 | E8: =D8*(1+E56) -> 169719.71 | F8: =E8*(1+F56) -> 177357.09 | G8: =F8*(1+G56) -> 185338.16 | H8: =G8*(1+H56) -> 193678.38 | I8: =H8*(1+I56) -> 201425.51 | J8: =I8*(1+J56) -> 209482.53 | K8: =J8*(1+K56) -> 217861.84 | ... M8: =L8*(1+M56) -> 235639.36 | Q8: Mike Feistel | R8: feistel2@illinois.edu
A9: Cost of Goods Sold | B9: 101135 | C9: 105904 | D9: =D8*D57 -> 109210.94 | E9: =E8*E57 -> 112863.6 | F9: =F8*F57 -> 117499.07 | G9: =G8*G57 -> 122323.19 | H9: =H8*H57 -> 127827.73 | I9: =I8*I57 -> 131933.71 | J9: =J8*J57 -> 136163.65 | K9: =K8*K57 -> 141065.54 | ... M9: =M8*M57 -> 152576.49
B10: -------------- | C10: -------------- | D10: -------------- | E10: -------------- | F10: -------------- | G10: -------------- | H10: -------------- | I10: -------------- | J10: -------------- | K10: -------------- | L10: -------------- | M10: -------------- | Q10: Shreya Ahuja | R10: shreyaa8@illinois.edu
A11: Gross Margin | B11: =+B8-B9 -> 51534 | C11: =+C8-C9 -> 53610 | D11: =D8-D9 -> 54769.451 | E11: =E8-E9 -> 56856.101 | F11: =F8-F9 -> 59858.019 | G11: =G8-G9 -> 63014.975 | H11: =H8-H9 -> 65850.649 | I11: =I8-I9 -> 69491.802 | J11: =J8-J9 -> 73318.887 | K11: =K8-K9 -> 76796.297 | ... M11: =M8-M9 -> 83062.875
Q12: Priyanka Chandramohan | R12: pc45@illinois.edu
A13: Operating Expenses:
A14: SG&A | B14: 26598 | C14: 28748 | D14: =D8*D62 -> 29516.471 | E14: =E8*E62 -> 30379.827 | F14: =F8*F62 -> 31622.77 | G14: =G8*G62 -> 32619.516 | H14: =H8*H62 -> 33409.52 | I14: =I8*I62 -> 34745.901 | J14: =J8*J62 -> 36135.737 | K14: =K8*K62 -> 37581.167 | ... M14: =M8*M62 -> 40529.97
A15: Depriciation & Amortization | B15: =B115 -> 3247 | C15: =C115 -> 3336 | D15: =D115 -> 3301.0231 | E15: =E115 -> 3364.8054 | F15: =F115 -> 3407.0101 | G15: =G115 -> 3448.1959 | H15: =H115 -> 3472.7219 | I15: =I115 -> 3526.8525 | ... M15: =M115 -> 3807.2916
B16: -------------- | C16: -------------- | D16: -------------- | E16: -------------- | F16: -------------- | G16: -------------- | H16: -------------- | I16: -------------- | J16: -------------- | K16: -------------- | L16: -------------- | M16: --------------
A17: Total Operating Expenses | B17: =SUM(B14:B16) -> 29845 | C17: =SUM(C14:C16) -> 32084 | D17: =SUM(D14:D15) -> 32817.494 | E17: =SUM(E14:E15) -> 33744.633 | F17: =SUM(F14:F15) -> 35029.78 | G17: =SUM(G14:G15) -> 36067.712 | H17: =SUM(H14:H15) -> 36882.242 | I17: =SUM(I14:I15) -> 38272.754 | J17: =SUM(J14:J15) -> 39723.972 | K17: =SUM(K14:K15) -> 41238.324 | ... M17: =SUM(M14:M15) -> 44337.262
B18: -------------- | C18: -------------- | D18: -------------- | E18: -------------- | F18: -------------- | G18: -------------- | H18: -------------- | I18: -------------- | J18: -------------- | K18: -------------- | L18: -------------- | M18: --------------
A19: Operating Income | B19: =+B11-B17 -> 21689 | C19: =+C11-C17+425 -> 21951 | D19: =D11-D17 -> 21951.957 | E19: =E11-E17 -> 23111.469 | F19: =F11-F17 -> 24828.239 | G19: =G11-G17 -> 26947.263 | H19: =H11-H17 -> 28968.407 | I19: =I11-I17 -> 31219.049 | J19: =J11-J17 -> 33594.916 | K19: =K11-K17 -> 35557.973 | ... M19: =M11-M17 -> 38725.613
A21: Other Income/(Expense) | B21: =+B8*B69 -> 0 | C21: =+C8*C69 -> 0 | D21: =D69*D8 -> 0 | E21: =E69*E8 -> 0 | F21: =F69*F8 -> 0 | G21: =G69*G8 -> 0 | H21: =H69*H8 -> 0 | I21: =I69*I8 -> 0 | J21: =J69*J8 -> 0 | K21: =K69*K8 -> 0 | ... M21: =M69*M8 -> 0
B22: -------------- | C22: -------------- | D22: -------------- | E22: -------------- | F22: -------------- | G22: -------------- | H22: -------------- | I22: -------------- | J22: -------------- | K22: -------------- | L22: -------------- | M22: --------------
A23: Pretax Income | B23: 19627 | C23: 19831 | D23: =SUM(D19:D21) -> 21951.957 | E23: =SUM(E19:E21) -> 23111.469 | F23: =SUM(F19:F21) -> 24828.239 | G23: =SUM(G19:G21) -> 26947.263 | H23: =SUM(H19:H21) -> 28968.407 | I23: =SUM(I19:I21) -> 31219.049 | J23: =SUM(J19:J21) -> 33594.916 | K23: =SUM(K19:K21) -> 35557.973 | ... M23: =SUM(M19:M21) -> 38725.613
A24: Income Taxes | B24: 4795 | C24: 4493 | D24: =D23*D72 -> 5378.2295 | E24: =E23*E72 -> 5662.3098 | F24: =F23*F72 -> 6082.9186 | G24: =G23*G72 -> 6602.0793 | H24: =H23*H72 -> 7097.2596 | I24: =I23*I72 -> 7648.6669 | J24: =J23*J72 -> 8230.7543 | K24: =K23*K72 -> 8711.7033 | ... M24: =M23*M72 -> 9487.7752
B25: -------------- | C25: -------------- | D25: -------------- | E25: -------------- | F25: -------------- | G25: -------------- | H25: -------------- | I25: -------------- | J25: -------------- | K25: -------------- | L25: -------------- | M25: --------------
A26: Net Income | B26: =+B23-B24 -> 14832 | C26: =+C23-C24 -> 15338 | D26: =D23-D24 -> 16573.728 | E26: =E23-E24 -> 17449.159 | F26: =F23-F24 -> 18745.32 | G26: =G23-G24 -> 20345.183 | H26: =H23-H24 -> 21871.147 | I26: =I23-I24 -> 23570.382 | J26: =J23-J24 -> 25364.161 | K26: =K23-K24 -> 26846.269 | ... M26: =M23-M24 -> 29237.838
A28: + Depreciation & Amortization | B28: =B115 -> 3247 | C28: =C115 -> 3336 | D28: =D115 -> 3301.0231 | E28: =E115 -> 3364.8054 | F28: =F115 -> 3407.0101 | G28: =G115 -> 3448.1959 | H28: =H115 -> 3472.7219 | I28: =I115 -> 3526.8525 | ... M28: =M115 -> 3807.2916
A29: - Capital Expenditures | B29: -3200 | C29: -3500 | D29: =-D8*D78 -> -4099.5098 | E29: =-E8*E78 -> -3818.6934 | F29: =-F8*F78 -> -3547.1418 | G29: =-G8*G78 -> -3706.7632 | H29: =-H8*H78 -> -3873.5676 | I29: =-I8*I78 -> -3625.6593 | J29: =-J8*J78 -> -3770.6856 | K29: =-K8*K78 -> -3921.513 | ... M29: =-M8*M78 -> -4123.6888
A30: - Working Capital Additions | B30: 1464 | C30: 1208 | D30: =(C8-D8)*$B$80 -> -200.98764 | E30: =(D8-E8)*$B$80 -> -258.26912 | F30: =(E8-F8)*$B$80 -> -343.6824 | G30: =(F8-G8)*$B$80 -> -359.14811 | H30: =(G8-H8)*$B$80 -> -375.30978 | I30: =(H8-I8)*$B$80 -> -348.62108 | J30: =(I8-J8)*$B$80 -> -362.56593 | K30: =(J8-K8)*$B$80 -> -377.06856 | ... M30: =(L8-M8)*$B$80 -> -407.83736
B31: -------------- | C31: -------------- | D31: -------------- | E31: -------------- | F31: -------------- | G31: -------------- | H31: -------------- | I31: -------------- | J31: -------------- | K31: -------------- | L31: -------------- | M31: --------------
A32: Free Cash Flow | B32: =+B26+SUM(B28:B31) -> 16343 | C32: =+C26+SUM(C28:C31) -> 16382 | D32: =(D26+SUM(D28:D30))*0.75 -> 11680.69 | E32: =E26+SUM(E28:E30) -> 16737.002 | F32: =F26+SUM(F28:F30) -> 18261.506 | G32: =G26+SUM(G28:G30) -> 19727.468 | H32: =H26+SUM(H28:H30) -> 21094.992 | I32: =I26+SUM(I28:I30) -> 23122.954 | J32: =J26+SUM(J28:J30) -> 24819.144 | K32: =K26+SUM(K28:K30) -> 26204.846 | L32: =L26+SUM(L28:L30) -> 27433.44 | M32: =M26+SUM(M28:M30) -> 28513.603 | N32: =M26*(1-0.0075/0.2648)/(B90-0.0075) -> 417874.39
A33: Present Value Factor | D33: =1/(1+$B$90)^(D91/12) -> 0.99094463 | E33: =1/(1+$B$90)^(E91/12) -> 0.94688305 | F33: =1/(1+$B$90)^(F91/12) -> 0.88042318 | G33: =1/(1+$B$90)^(G91/12) -> 0.81862799 | H33: =1/(1+$B$90)^(H91/12) -> 0.76117009 | I33: =1/(1+$B$90)^(I91/12) -> 0.70774505 | J33: =1/(1+$B$90)^(J91/12) -> 0.65806981 | K33: =1/(1+$B$90)^(K91/12) -> 0.61188117 | ... N33: =1/(1+$B$90)^(N91/12) -> 0.5100995
D34: -------------- | E34: -------------- | F34: -------------- | G34: -------------- | H34: -------------- | I34: -------------- | J34: -------------- | K34: -------------- | L34: -------------- | M34: -------------- | N34: --------------
A35: PV Free Cash Flow | D35: =D32*D33 -> 11574.917 | E35: =E32*E33 -> 15847.983 | F35: =+F32*F33 -> 16077.853 | G35: =+G32*G33 -> 16149.457 | H35: =+H32*H33 -> 16056.877 | I35: =+I32*I33 -> 16365.156 | J35: =+J32*J33 -> 16332.729 | K35: =+K32*K33 -> 16034.252 | L35: =+L32*L33 -> 15607.828 | M35: =+M32*M33 -> 15083.754 | N35: =+N32*N33 -> 213157.52
D36: --------------
A37: Value of Firm | D37: =SUM(D35:N35) -> 368288.33
A38: Less: Debt Outstanding | D38: -53383
A39: Plus: Cash | D39: 1659
D40: --------------
A41: Equity Value | D41: =SUM(D37:D39) -> 316564.33
A42: Shares Outstanding | D42: 993
...

Sheet Multiples
B2: EV | C2: =DCF!D47*DCF!D42-DCF!D38-DCF!D39 -> 406800.94 | F2: EV/EBITDA | G2: =C2/C3 -> 15.925249
B3: EBITDA | C3: 25544.4
B4: Price | C4: =DCF!D47 -> 357.58 | F4: P/E | G4: =C4/C5 -> 23.743692
B5: EPS | C5: 15.06
B7: IC 24 | C7: 72356 | F7: Profit Margin | G7: =C11/C12 -> 0.1010714
B8: IC 25 Estimated | C8: =C7-DCF!D30-DCF!D29-DCF!D28 -> 73355.474 | F8: Turnover | G8: =C12/C9 -> 2.2507547
B9: Avg IC | C9: =AVERAGE(C7:C8) -> 72855.737
F10: ROIC Est FY25 | G10: =G8*G7 -> 0.22748693
B11: NI to all Stakeholders | C11: =DCF!D26 -> 16573.728
B12: Revenue | C12: =DCF!D8 -> 163980.39
