Workbook

Sheet Assumption
A2: Option Selection
A3: Operating Scenario | C3: 1
D4: Projected
D5: 2025 | E5: =D5+1 -> 2026 | F5: =E5+1 -> 2027 | G5: =F5+1 -> 2028 | H5: =G5+1 -> 2029 | I5: =H5+1 -> 2030 | J5: =I5+1 -> 2031 | K5: =J5+1 -> 2032 | L5: =K5+1 -> 2033 | M5: =L5+1 -> 2034 | R5: Name | S5: Email
R7: Sharang Mantri | S7: smantri3@illinois.edu
A8: Total Revenue Growth | D8: =CHOOSE($C$3,D9,D10,#REF!) -> 0.01 | E8: =CHOOSE($C$3,E9,E10,#REF!) -> 0.03 | F8: =CHOOSE($C$3,F9,F10,#REF!) -> 0.03 | G8: =CHOOSE($C$3,G9,G10,#REF!) -> 0.03 | H8: =CHOOSE($C$3,H9,H10,#REF!) -> 0.03 | I8: =CHOOSE($C$3,I9,I10,#REF!) -> 0.03 | J8: =CHOOSE($C$3,J9,J10,#REF!) -> 0.03 | K8: =CHOOSE($C$3,K9,K10,#REF!) -> 0.03 | ... M8: =CHOOSE($C$3,M9,M10,#REF!) -> 0.03
A9: Base | D9: 0.01 | E9: 0.03 | F9: 0.03 | G9: 0.03 | H9: 0.03 | I9: 0.03 | J9: 0.03 | K9: 0.03 | L9: 0.03 | M9: 0.03 | R9: Mike Feistel | S9: feistel2@illinois.edu
A10: Bull | D10: 0.04 | E10: 0.05 | F10: 0.05 | G10: 0.05 | H10: 0.035 | I10: 0.03 | J10: 0.03 | K10: 0.03 | L10: 0.03 | M10: 0.03
R11: Shreya Ahuja | S11: shreyaa8@illinois.edu
A12: Gross Margin | D12: =1-D13 -> 0.336 | E12: =1-E13 -> 0.336 | F12: =1-F13 -> 0.336 | G12: =1-G13 -> 0.336 | H12: =1-H13 -> 0.336 | I12: =1-I13 -> 0.336 | J12: =1-J13 -> 0.336 | K12: =1-K13 -> 0.336 | ... M12: =1-M13 -> 0.336
A13: COGS | D13: {=INDEX(D14:D15,$C$3)} -> 0.664 | E13: {=INDEX(E14:E15,$C$3)} -> 0.664 | F13: {=INDEX(F14:F15,$C$3)} -> 0.664 | G13: {=INDEX(G14:G15,$C$3)} -> 0.664 | H13: {=INDEX(H14:H15,$C$3)} -> 0.664 | I13: {=INDEX(I14:I15,$C$3)} -> 0.664 | J13: {=INDEX(J14:J15,$C$3)} -> 0.664 | K13: {=INDEX(K14:K15,$C$3)} -> 0.664 | ... M13: {=INDEX(M14:M15,$C$3)} -> 0.664 | R13: Priyanka Chandramohan | S13: pc45@illinois.edu
A14: Base | D14: 0.664 | E14: 0.664 | F14: 0.664 | G14: 0.664 | H14: 0.664 | I14: 0.664 | J14: 0.664 | K14: 0.664 | L14: 0.664 | M14: 0.664
A15: Bull | D15: 0.664 | E15: 0.664 | F15: 0.664 | G15: 0.664 | H15: 0.664 | I15: 0.664 | J15: 0.664 | K15: 0.664 | L15: 0.664 | M15: 0.664
A18: Operating Expense | D18: =Assumption!D21+Assumption!D26 -> 0.2205 | E18: =Assumption!E21+Assumption!E26 -> 0.213 | F18: =Assumption!F21+Assumption!F26 -> 0.2098 | G18: =Assumption!G21+Assumption!G26 -> 0.2075 | H18: =Assumption!H21+Assumption!H26 -> 0.2047 | I18: =Assumption!I21+Assumption!I26 -> 0.202 | J18: =Assumption!J21+Assumption!J26 -> 0.1972 | K18: =Assumption!K21+Assumption!K26 -> 0.1945 | ... M18: =Assumption!M21+Assumption!M26 -> 0.1945
A19: Operating Income | D19: =DCF!D67 -> 0.12411073 | E19: =DCF!E67 -> 0.12694921 | F19: =DCF!F67 -> 0.13044972 | G19: =DCF!G67 -> 0.13301417 | H19: =DCF!H67 -> 0.13604442 | I19: =DCF!I67 -> 0.13894222 | J19: =DCF!J67 -> 0.14200927 | K19: =DCF!K67 -> 0.14494429 | ... M19: =DCF!M67 -> 0.14532471
A21: SG&A | D21: {=INDEX(D22:D23,$C$3)} -> 0.1905 | E21: {=INDEX(E22:E23,$C$3)} -> 0.188 | F21: {=INDEX(F22:F23,$C$3)} -> 0.1848 | G21: {=INDEX(G22:G23,$C$3)} -> 0.1825 | H21: {=INDEX(H22:H23,$C$3)} -> 0.1797 | I21: {=INDEX(I22:I23,$C$3)} -> 0.177 | J21: {=INDEX(J22:J23,$C$3)} -> 0.1742 | K21: {=INDEX(K22:K23,$C$3)} -> 0.1715 | ... M21: {=INDEX(M22:M23,$C$3)} -> 0.1715
A22: Base | D22: 0.1905 | E22: 0.188 | F22: 0.1848 | G22: 0.1825 | H22: 0.1797 | I22: 0.177 | J22: 0.1742 | K22: 0.1715 | L22: 0.1715 | M22: 0.1715
A23: Bull | D23: 0.1882 | E23: 0.184 | F23: 0.1795 | G23: 0.1752 | H23: 0.1705 | I23: 0.1657 | J23: 0.1628 | K23: 0.1628 | L23: 0.1628 | M23: 0.1628
A26: Capex | D26: {=INDEX(D27:D28,$C$3)} -> 0.03 | E26: {=INDEX(E27:E28,$C$3)} -> 0.025 | F26: {=INDEX(F27:F28,$C$3)} -> 0.025 | G26: {=INDEX(G27:G28,$C$3)} -> 0.025 | H26: {=INDEX(H27:H28,$C$3)} -> 0.025 | I26: {=INDEX(I27:I28,$C$3)} -> 0.025 | J26: {=INDEX(J27:J28,$C$3)} -> 0.023 | K26: {=INDEX(K27:K28,$C$3)} -> 0.023 | ... M26: {=INDEX(M27:M28,$C$3)} -> 0.023
A27: Base | D27: 0.03 | E27: 0.025 | F27: 0.025 | G27: 0.025 | H27: 0.025 | I27: 0.025 | J27: 0.023 | K27: 0.023 | L27: 0.023 | M27: 0.023
A28: Bull | D28: 0.029 | E28: 0.024 | F28: 0.024 | G28: 0.024 | H28: 0.023 | I28: 0.023 | J28: 0.022 | K28: 0.022 | L28: 0.022 | M28: 0.022
A30: Other Income | D30: {=INDEX(D31:D32,$C$3)} -> 0 | E30: 0 | F30: {=INDEX(F31:F32,$C$3)} -> 0 | G30: {=INDEX(G31:G32,$C$3)} -> 0 | H30: {=INDEX(H31:H32,$C$3)} -> 0 | I30: {=INDEX(I31:I32,$C$3)} -> 0 | J30: {=INDEX(J31:J32,$C$3)} -> 0 | K30: {=INDEX(K31:K32,$C$3)} -> 0 | L30: {=INDEX(L31:L32,$C$3)} -> 0 | M30: {=INDEX(M31:M32,$C$3)} -> 0
A31: Base | D31: 0 | E31: 0 | F31: 0 | G31: 0 | H31: 0 | I31: 0 | J31: 0 | K31: 0 | L31: 0 | M31: 0
A32: Bull | D32: 0 | E32: 0 | F32: 0 | G32: 0 | H32: 0 | I32: 0 | J32: 0 | K32: 0 | L32: 0 | M32: 0

Sheet DCF
A1: Lowe's Inc.
A2: Discounted Cash Flow Analysis
A3: For the Years Ended January 31, 2025
A4: Millions of Dollars
N5: Terminal
B6: =2023 -> 2023 | C6: =+B6+1 -> 2024 | D6: =+C6+1 -> 2025 | E6: =+D6+1 -> 2026 | F6: =+E6+1 -> 2027 | G6: =+F6+1 -> 2028 | H6: =+G6+1 -> 2029 | I6: =+H6+1 -> 2030 | J6: =+I6+1 -> 2031 | ... M6: =+L6+1 -> 2034 | N6: Value
B7: -------------- | C7: -------------- | D7: -------------- | E7: -------------- | F7: -------------- | G7: -------------- | H7: -------------- | I7: -------------- | J7: -------------- | K7: -------------- | L7: -------------- | M7: -------------- | N7: --------------
A8: Revenue | B8: 86377 | C8: 83674 | D8: =C8*(1+D56) -> 84510.74 | E8: =D8*(1+E56) -> 87046.062 | F8: =E8*(1+F56) -> 89657.444 | G8: =F8*(1+G56) -> 92347.167 | H8: =G8*(1+H56) -> 95117.582 | I8: =H8*(1+I56) -> 97971.11 | J8: =I8*(1+J56) -> 100910.24 | K8: =J8*(1+K56) -> 103937.55 | ... M8: =L8*(1+M56) -> 110267.35
A9: Cost of Goods Sold | B9: 57327 | C9: 55554 | D9: =D8*D57 -> 56115.131 | E9: =E8*E57 -> 57798.585 | F9: =F8*F57 -> 59532.543 | G9: =G8*G57 -> 61318.519 | H9: =H8*H57 -> 63158.075 | I9: =I8*I57 -> 65052.817 | J9: =J8*J57 -> 67004.401 | K9: =K8*K57 -> 69014.534 | ... M9: =M8*M57 -> 73217.519
B10: -------------- | C10: -------------- | D10: -------------- | E10: -------------- | F10: -------------- | G10: -------------- | H10: -------------- | I10: -------------- | J10: -------------- | K10: -------------- | L10: -------------- | M10: --------------
A11: Gross Margin | B11: =+B8-B9 -> 29050 | C11: =+C8-C9 -> 28120 | D11: =D8-D9 -> 28395.609 | E11: =E8-E9 -> 29247.477 | F11: =F8-F9 -> 30124.901 | G11: =G8-G9 -> 31028.648 | H11: =H8-H9 -> 31959.508 | I11: =I8-I9 -> 32918.293 | J11: =J8-J9 -> 33905.842 | K11: =K8-K9 -> 34923.017 | ... M11: =M8-M9 -> 37049.829
A13: Operating Expenses:
A14: SG&A | B14: 15633 | C14: 15922 | D14: =D8*D62 -> 16099.296 | E14: =E8*E62 -> 16364.66 | F14: =F8*F62 -> 16568.696 | G14: =G8*G62 -> 16853.358 | H14: =H8*H62 -> 17092.63 | I14: =I8*I62 -> 17340.886 | J14: =J8*J62 -> 17578.564 | K14: =K8*K62 -> 17825.29 | ... M14: =M8*M62 -> 18910.85
A15: Depriciation & Amortization | B15: 1923 | C15: 1972 | D15: =D114 -> 1807.6233 | E15: =E114 -> 1832.388 | F15: =F114 -> 1860.4169 | G15: =G114 -> 1891.808 | H15: =H114 -> 1926.6621 | I15: =I114 -> 1965.0832 | J15: =J114 -> 1997.0871 | K15: =K114 -> 2032.5724 | ... M15: =M114 -> 2114.4082
B16: -------------- | C16: -------------- | D16: -------------- | E16: -------------- | F16: -------------- | G16: -------------- | H16: -------------- | I16: -------------- | J16: -------------- | K16: -------------- | L16: -------------- | M16: --------------
A17: Total Operating Expenses | B17: =SUM(B14:B16) -> 17556 | C17: =SUM(C14:C16) -> 17894 | D17: =SUM(D14:D15) -> 17906.919 | E17: =SUM(E14:E15) -> 18197.048 | F17: =SUM(F14:F15) -> 18429.113 | G17: =SUM(G14:G15) -> 18745.166 | H17: =SUM(H14:H15) -> 19019.292 | I17: =SUM(I14:I15) -> 19305.97 | J17: =SUM(J14:J15) -> 19575.651 | K17: =SUM(K14:K15) -> 19857.862 | ... M17: =SUM(M14:M15) -> 21025.258
B18: -------------- | C18: -------------- | D18: -------------- | E18: -------------- | F18: -------------- | G18: -------------- | H18: -------------- | I18: -------------- | J18: -------------- | K18: -------------- | L18: -------------- | M18: --------------
A19: Operating Income | B19: =+B11-B17 -> 11494 | C19: =+C11-C17 -> 10226 | D19: =D11-D17 -> 10488.689 | E19: =E11-E17 -> 11050.429 | F19: =F11-F17 -> 11695.789 | G19: =G11-G17 -> 12283.482 | H19: =H11-H17 -> 12940.216 | I19: =I11-I17 -> 13612.323 | J19: =J11-J17 -> 14330.19 | K19: =K11-K17 -> 15065.155 | ... M19: =M11-M17 -> 16024.57
A21: Other Income/(Expense) | B21: =+B8*B69 -> 0 | C21: =+C8*C69 -> 0 | D21: =D69*D8 -> 0 | E21: =E69*E8 -> 0 | F21: =F69*F8 -> 0 | G21: =G69*G8 -> 0 | H21: =H69*H8 -> 0 | I21: =I69*I8 -> 0 | J21: =J69*J8 -> 0 | K21: =K69*K8 -> 0 | ... M21: =M69*M8 -> 0
B22: -------------- | C22: -------------- | D22: -------------- | E22: -------------- | F22: -------------- | G22: -------------- | H22: -------------- | I22: -------------- | J22: -------------- | K22: -------------- | L22: -------------- | M22: --------------
A23: Pretax Income | B23: 10112 | C23: 8913 | D23: =SUM(D19:D21) -> 10488.689 | E23: =SUM(E19:E21) -> 11050.429 | F23: =SUM(F19:F21) -> 11695.789 | G23: =SUM(G19:G21) -> 12283.482 | H23: =SUM(H19:H21) -> 12940.216 | I23: =SUM(I19:I21) -> 13612.323 | J23: =SUM(J19:J21) -> 14330.19 | K23: =SUM(K19:K21) -> 15065.155 | ... M23: =SUM(M19:M21) -> 16024.57
A24: Income Taxes | B24: 2450 | C24: 2154 | D24: =D23*D72 -> 2622.1724 | E24: =E23*E72 -> 2762.6073 | F24: =F23*F72 -> 2923.9472 | G24: =G23*G72 -> 3070.8705 | H24: =H23*H72 -> 3235.054 | I24: =I23*I72 -> 3403.0808 | J24: =J23*J72 -> 3582.5476 | K24: =K23*K72 -> 3766.2887 | ... M24: =M23*M72 -> 4006.1426
B25: -------------- | C25: -------------- | D25: -------------- | E25: -------------- | F25: -------------- | G25: -------------- | H25: -------------- | I25: -------------- | J25: -------------- | K25: -------------- | L25: -------------- | M25: --------------
A26: Net Income | B26: =+B23-B24 -> 7662 | C26: =+C23-C24 -> 6759 | D26: =D23-D24 -> 7866.5171 | E26: =E23-E24 -> 8287.8219 | F26: =F23-F24 -> 8771.8415 | G26: =G23-G24 -> 9212.6116 | H26: =H23-H24 -> 9705.162 | I26: =I23-I24 -> 10209.242 | J26: =J23-J24 -> 10747.643 | K26: =K23-K24 -> 11298.866 | ... M26: =M23-M24 -> 12018.428
A28: + Depreciation & Amortization | B28: =B114 -> 1923 | C28: =C114 -> 1972 | D28: =D114 -> 1807.6233 | E28: =E114 -> 1832.388 | F28: =F114 -> 1860.4169 | G28: =G114 -> 1891.808 | H28: =H114 -> 1926.6621 | I28: =I114 -> 1965.0832 | ... M28: =M114 -> 2114.4082
A29: - Capital Expenditures | B29: -1927 | C29: -1964 | D29: =-D8*D78 -> -2535.3222 | E29: =-E8*E78 -> -2176.1516 | F29: =-F8*F78 -> -2241.4361 | G29: =-G8*G78 -> -2308.6792 | H29: =-H8*H78 -> -2377.9396 | I29: =-I8*I78 -> -2449.2777 | J29: =-J8*J78 -> -2320.9356 | K29: =-K8*K78 -> -2390.5637 | ... M29: =-M8*M78 -> -2536.149
A30: - Working Capital Additions | B30: -1524 | C30: -147 | D30: =(C8-D8)*$B$80 -> -30.95938 | E30: =(D8-E8)*$B$80 -> -93.806921 | F30: =(E8-F8)*$B$80 -> -96.621129 | G30: =(F8-G8)*$B$80 -> -99.519763 | H30: =(G8-H8)*$B$80 -> -102.50536 | I30: =(H8-I8)*$B$80 -> -105.58052 | J30: =(I8-J8)*$B$80 -> -108.74793 | K30: =(J8-K8)*$B$80 -> -112.01037 | ... M30: =(L8-M8)*$B$80 -> -118.8318
B31: -------------- | C31: -------------- | D31: -------------- | E31: -------------- | F31: -------------- | G31: -------------- | H31: -------------- | I31: -------------- | J31: -------------- | K31: -------------- | L31: -------------- | M31: --------------
A32: Free Cash Flow | B32: =+B26+SUM(B28:B31) -> 6134 | C32: =+C26+SUM(C28:C31) -> 6620 | D32: =(D26+SUM(D28:D30))*0.75 -> 5330.8941 | E32: =E26+SUM(E28:E30) -> 7850.2514 | F32: =F26+SUM(F28:F30) -> 8294.2012 | G32: =G26+SUM(G28:G30) -> 8696.2207 | H32: =H26+SUM(H28:H30) -> 9151.3792 | I32: =I26+SUM(I28:I30) -> 9619.4674 | J32: =J26+SUM(J28:J30) -> 10315.046 | K32: =K26+SUM(K28:K30) -> 10828.864 | L32: =L26+SUM(L28:L30) -> 11148.254 | M32: =M26+SUM(M28:M30) -> 11477.855 | N32: =M26*(1-0.0075/0.2888)/(B90-0.0075) -> 185423.04
A33: Present Value Factor | D33: =1/(1+$B$90)^(D91/12) -> 0.99150503 | E33: =1/(1+$B$90)^(E91/12) -> 0.95010046 | F33: =1/(1+$B$90)^(F91/12) -> 0.88741935 | G33: =1/(1+$B$90)^(G91/12) -> 0.82887352 | H33: =1/(1+$B$90)^(H91/12) -> 0.77419014 | I33: =1/(1+$B$90)^(I91/12) -> 0.72311439 | J33: =1/(1+$B$90)^(J91/12) -> 0.67540827 | K33: =1/(1+$B$90)^(K91/12) -> 0.63084947 | ... N33: =1/(1+$B$90)^(N91/12) -> 0.53189287
D34: -------------- | E34: -------------- | F34: -------------- | G34: -------------- | H34: -------------- | I34: -------------- | J34: -------------- | K34: -------------- | L34: -------------- | M34: -------------- | N34: --------------
A35: PV Free Cash Flow | D35: =D32*D33 -> 5285.6083 | E35: =E32*E33 -> 7458.5275 | F35: =+F32*F33 -> 7360.4346 | G35: =+G32*G33 -> 7208.0671 | H35: =+H32*H33 -> 7084.9075 | I35: =+I32*I33 -> 6955.9753 | J35: =+J32*J33 -> 6966.8675 | K35: =+K32*K33 -> 6831.3834 | L35: =+L32*L33 -> 6568.8895 | M35: =+M32*M33 -> 6316.9178 | N35: =+N32*N33 -> 98625.19
D36: --------------
A37: Value of Firm | D37: =SUM(D35:N35) -> 166662.77
A38: Less: Debt Outstanding | D38: -35487
A39: Plus: Cash | D39: 1761
D40: --------------
A41: Equity Value | D41: =SUM(D37:D39) -> 132936.77
A42: Shares Outstanding | D42: 568
D43: --------------
...

Sheet Multiples
B2: EV | C2: =DCF!D47*DCF!D42-DCF!D38-DCF!D39 -> 159202.88 | F2: EV/EBITDA | G2: =C2/C3 -> 12.898013
B3: EBITDA | C3: 12343.21
B4: Price | C4: =DCF!D47 -> 220.91 | F4: P/E | G4: =C4/C5 -> 17.960163
B5: EPS | C5: 12.3
B7: IC 24 | C7: 26931 | F7: Profit Margin | G7: =C11/C12 -> 0.093083046
B8: IC 25 Estimated | C8: =C7-DCF!D29-DCF!D30-DCF!D28 -> 27689.658 | F8: Turnover | G8: =C12/C9 -> 3.0944607
B9: Avg IC | C9: =AVERAGE(C7:C8) -> 27310.329
F10: ROIC Est FY25 | G10: =G8*G7 -> 0.28804183
B11: NI to all Stakeholders | C11: =DCF!D26 -> 7866.5171
B12: Revenue | C12: =DCF!D8 -> 84510.74
