Workbook
Name g: Sheet2!$B$108
Name roic: Sheet2!$B$109

Sheet Sheet1
B2: Option Selection
B3: Operating Scenario | D3: 3
I4: Projected
E5: 2026 | F5: 2027 | G5: =F5+1 -> 2028 | H5: =G5+1 -> 2029 | I5: =H5+1 -> 2030 | J5: =I5+1 -> 2031 | K5: =J5+1 -> 2032 | L5: =K5+1 -> 2033 | M5: =L5+1 -> 2034 | N5: =M5+1 -> 2035
A8: Total Revenue Growth | E8: =CHOOSE($D$3,E9,E10,E11) -> 0.15 | F8: =CHOOSE($D$3,F9,F10,F11) -> 0.13 | G8: =CHOOSE($D$3,G9,G10,G11) -> 0.12 | H8: =CHOOSE($D$3,H9,H10,H11) -> 0.11 | I8: =CHOOSE($D$3,I9,I10,I11) -> 0.11 | J8: =CHOOSE($D$3,J9,J10,J11) -> 0.11 | K8: =CHOOSE($D$3,K9,K10,K11) -> 0.1 | L8: =CHOOSE($D$3,L9,L10,L11) -> 0.1 | ... N8: =CHOOSE($D$3,N9,N10,N11) -> 0.09
A9: Base | E9: 0.16 | F9: 0.16 | G9: 0.16 | H9: 0.15 | I9: 0.14 | J9: 0.13 | K9: 0.12 | L9: 0.12 | M9: 0.11 | N9: 0.11
A10: Bull | E10: 0.18 | F10: 0.2 | G10: 0.18 | H10: =H9+2% -> 0.17 | I10: =I9+2% -> 0.16 | J10: =J9+2% -> 0.15 | K10: 0.13 | L10: 0.12 | M10: =M9+1% -> 0.12 | N10: =N9+1% -> 0.12
A11: Bear | E11: 0.15 | F11: 0.13 | G11: 0.12 | H11: 0.11 | I11: 0.11 | J11: 0.11 | K11: 0.1 | L11: 0.1 | M11: 0.09 | N11: 0.09
A13: Gross Margin | E13: =1-E14 -> 0.685 | F13: =1-F14 -> 0.7 | G13: =1-G14 -> 0.69 | H13: =1-H14 -> 0.7 | I13: =1-I14 -> 0.71 | J13: =1-J14 -> 0.72 | K13: =1-K14 -> 0.73 | L13: =1-L14 -> 0.735 | ... N13: =1-N14 -> 0.735
A14: COGS | E14: {=INDEX(E15:E18,$D$3)} -> 0.315 | F14: 0.3 | G14: {=INDEX(G15:G18,$D$3)} -> 0.31 | H14: {=INDEX(H15:H18,$D$3)} -> 0.3 | I14: {=INDEX(I15:I18,$D$3)} -> 0.29 | J14: {=INDEX(J15:J18,$D$3)} -> 0.28 | K14: {=INDEX(K15:K18,$D$3)} -> 0.27 | L14: {=INDEX(L15:L18,$D$3)} -> 0.265 | M14: {=INDEX(M15:M18,$D$3)} -> 0.265 | N14: {=INDEX(N15:N18,$D$3)} -> 0.265
A15: Base | E15: 0.31 | F15: 0.305 | G15: 0.3 | H15: 0.29 | I15: 0.28 | J15: 0.27 | K15: 0.25 | L15: 0.25 | M15: 0.25 | N15: 0.25
A16: Bull | E16: 0.305 | F16: 0.29 | G16: 0.28 | H16: 0.27 | I16: 0.26 | J16: 0.25 | K16: 0.245 | L16: 0.245 | M16: 0.245 | N16: 0.245
A17: Bear | E17: 0.315 | F17: 0.32 | G17: 0.31 | H17: =H15+1% -> 0.3 | I17: =I15+1% -> 0.29 | J17: 0.28 | K17: 0.27 | L17: 0.265 | M17: 0.265 | N17: 0.265
A19: Operating Expense
A21: SG&A | E21: {=INDEX(E22:E24,$D$3)} -> 0.116 | F21: {=INDEX(F22:F24,$D$3)} -> 0.12 | G21: {=INDEX(G22:G24,$D$3)} -> 0.12 | H21: {=INDEX(H22:H24,$D$3)} -> 0.11 | I21: {=INDEX(I22:I24,$D$3)} -> 0.1075 | J21: {=INDEX(J22:J24,$D$3)} -> 0.105 | K21: {=INDEX(K22:K24,$D$3)} -> 0.105 | L21: {=INDEX(L22:L24,$D$3)} -> 0.105 | ... N21: {=INDEX(N22:N24,$D$3)} -> 0.105
A22: Base | E22: 0.1155 | F22: 0.115 | G22: 0.11 | H22: 0.105 | I22: 0.1015 | J22: 0.1 | K22: 0.1 | L22: 0.1 | M22: 0.1 | N22: 0.1
A23: Bull | E23: 0.11 | F23: 0.11 | G23: 0.105 | H23: 0.1 | I23: 0.1 | J23: 0.1 | K23: 0.1 | L23: 0.1 | M23: 0.1 | N23: 0.1
A24: Bear | E24: 0.116 | F24: 0.12 | G24: 0.12 | H24: 0.11 | I24: 0.1075 | J24: 0.105 | K24: 0.105 | L24: 0.105 | M24: 0.105 | N24: 0.105
A26: R&D | E26: {=INDEX(E27:E29,$D$3)} -> 0.12 | F26: {=INDEX(F27:F29,$D$3)} -> 0.1275 | G26: {=INDEX(G27:G29,$D$3)} -> 0.125 | H26: {=INDEX(H27:H29,$D$3)} -> 0.125 | I26: {=INDEX(I27:I29,$D$3)} -> 0.125 | J26: {=INDEX(J27:J29,$D$3)} -> 0.12 | K26: {=INDEX(K27:K29,$D$3)} -> 0.12 | L26: {=INDEX(L27:L29,$D$3)} -> 0.12 | ... N26: {=INDEX(N27:N29,$D$3)} -> 0.12
A27: Base | E27: 0.118 | F27: 0.117 | G27: 0.115 | H27: 0.115 | I27: 0.115 | J27: 0.11 | K27: 0.11 | L27: 0.11 | M27: 0.11 | N27: 0.11
A28: Bull | E28: 0.115 | F28: 0.115 | G28: 0.113 | H28: 0.112 | I28: 0.11 | J28: 0.11 | K28: 0.11 | L28: 0.11 | M28: 0.11 | N28: 0.11
A29: Bear | E29: 0.12 | F29: 0.1275 | G29: 0.125 | H29: 0.125 | I29: 0.125 | J29: 0.12 | K29: 0.12 | L29: 0.12 | M29: 0.12 | N29: 0.12
A31: CapEx | E31: {=INDEX(E32:E34,$D$3)} -> 0.305 | F31: {=INDEX(F32:F34,$D$3)} -> 0.29 | G31: {=INDEX(G32:G34,$D$3)} -> 0.25 | H31: {=INDEX(H32:H34,$D$3)} -> 0.19 | I31: {=INDEX(I32:I34,$D$3)} -> 0.175 | J31: {=INDEX(J32:J34,$D$3)} -> 0.16 | K31: {=INDEX(K32:K34,$D$3)} -> 0.15 | L31: {=INDEX(L32:L34,$D$3)} -> 0.14 | ... N31: {=INDEX(N32:N34,$D$3)} -> 0.12
A32: Base | E32: 0.3 | F32: 0.29 | G32: 0.25 | H32: 0.185 | I32: 0.17 | J32: 0.155 | K32: 0.14 | L32: 0.135 | M32: 0.125 | N32: 0.115
A33: Bull | E33: =E32-0.5% -> 0.295 | F33: =F32-0.5% -> 0.285 | G33: 0.24 | H33: 0.175 | I33: 0.155 | J33: 0.145 | K33: 0.14 | L33: 0.125 | M33: 0.115 | N33: 0.11
A34: Bear | E34: =E32+0.5% -> 0.305 | F34: 0.29 | G34: 0.25 | H34: =H32+0.5% -> 0.19 | I34: =I32+0.5% -> 0.175 | J34: =J32+0.5% -> 0.16 | K34: 0.15 | L34: =L32+0.5% -> 0.14 | M34: =M32+0.5% -> 0.13 | N34: =N32+0.5% -> 0.12
A36: Other Income | E36: {=INDEX(E37:E39,$D$3)} -> 0 | F36: {=INDEX(F37:F39,$D$3)} -> 0 | G36: {=INDEX(G37:G39,$D$3)} -> 0 | H36: {=INDEX(H37:H39,$D$3)} -> 0 | I36: {=INDEX(I37:I39,$D$3)} -> 0 | J36: {=INDEX(J37:J39,$D$3)} -> 0 | K36: {=INDEX(K37:K39,$D$3)} -> 0 | L36: {=INDEX(L37:L39,$D$3)} -> 0 | ... N36: {=INDEX(N37:N39,$D$3)} -> 0
A37: Base | E37: {=INDEX(E38:E40,$D$3)} -> 0 | F37: {=INDEX(F38:F40,$D$3)} -> 0 | G37: {=INDEX(G38:G40,$D$3)} -> 0 | H37: {=INDEX(H38:H40,$D$3)} -> 0 | I37: {=INDEX(I38:I40,$D$3)} -> 0 | J37: {=INDEX(J38:J40,$D$3)} -> 0 | K37: {=INDEX(K38:K40,$D$3)} -> 0 | L37: {=INDEX(L38:L40,$D$3)} -> 0 | ... N37: {=INDEX(N38:N40,$D$3)} -> 0
A38: Bull | E38: {=INDEX(E39:E41,$D$3)} -> 0 | F38: {=INDEX(F39:F41,$D$3)} -> 0 | G38: {=INDEX(G39:G41,$D$3)} -> 0 | H38: {=INDEX(H39:H41,$D$3)} -> 0 | I38: {=INDEX(I39:I41,$D$3)} -> 0 | J38: {=INDEX(J39:J41,$D$3)} -> 0 | K38: {=INDEX(K39:K41,$D$3)} -> 0 | L38: {=INDEX(L39:L41,$D$3)} -> 0 | ... N38: {=INDEX(N39:N41,$D$3)} -> 0
A39: Bear | E39: {=INDEX(E40:E42,$D$3)} -> 0 | F39: {=INDEX(F40:F42,$D$3)} -> 0 | G39: {=INDEX(G40:G42,$D$3)} -> 0 | H39: {=INDEX(H40:H42,$D$3)} -> 0 | I39: {=INDEX(I40:I42,$D$3)} -> 0 | J39: {=INDEX(J40:J42,$D$3)} -> 0 | K39: {=INDEX(K40:K42,$D$3)} -> 0 | L39: {=INDEX(L40:L42,$D$3)} -> 0 | ... N39: {=INDEX(N40:N42,$D$3)} -> 0

Sheet Sheet2
A4: Working Capital | B4: 31860 | C4: 37250 | D4: 44010 | E4: 43842
B5: 2022 | C5: 2023 | D5: 2024 | E5: 2025 | F5: 2025_Q1 | G5: 2026_Q1 | H5: 2026 | J5: =H5+1 -> 2027 | K5: =J5+1 -> 2028 | L5: =K5+1 -> 2029 | M5: =L5+1 -> 2030 | N5: =M5+1 -> 2031 | O5: =N5+1 -> 2032 | P5: =O5+1 -> 2033 | Q5: =P5+1 -> 2034 | R5: =Q5+1 -> 2035
A7: Revenue | C7: 211915 | D7: 245122 | E7: 281724 | F7: 65585 | G7: 77673 | H7: =E7*(1+I49) -> 323982.6 | J7: =H7*(1+J49) -> 366100.34 | K7: =J7*(1+K49) -> 410032.38 | L7: =K7*(1+L49) -> 455135.94 | M7: =L7*(1+M49) -> 505200.89 | N7: =M7*(1+N49) -> 560772.99 | O7: =N7*(1+O49) -> 616850.29 | P7: =O7*(1+P49) -> 678535.32 | Q7: =P7*(1+Q49) -> 739603.5 | R7: =Q7*(1+R49) -> 806167.81
A8: Cost of Goods Sold | C8: 65863 | D8: 74114 | E8: 87831 | F8: 20099 | G8: 24043 | H8: =H7*I50 -> 102054.52 | J8: =J7*J50 -> 109830.1 | K8: =K7*K50 -> 127110.04 | L8: =L7*L50 -> 136540.78 | M8: =M7*M50 -> 146508.26 | N8: =N7*N50 -> 157016.44 | O8: =O7*O50 -> 166549.58 | P8: =P7*P50 -> 179811.86 | Q8: =Q7*Q50 -> 195994.93 | R8: =R7*R50 -> 213634.47
A10: Gross Margin | C10: 146052 | D10: 171008 | E10: 193893 | F10: 45486 | G10: 53630 | H10: =H7-H8 -> 221928.08 | J10: =J7-J8 -> 256270.24 | K10: =K7-K8 -> 282922.34 | L10: =L7-L8 -> 318595.16 | M10: =M7-M8 -> 358692.63 | N10: =N7-N8 -> 403756.55 | O10: =O7-O8 -> 450300.71 | P10: =P7-P8 -> 498723.46 | Q10: =Q7-Q8 -> 543608.57 | R10: =R7-R8 -> 592533.34
A12: Operating Expenses:
A13: SG&A | C13: 30334 | D13: 32065 | E13: 32877 | F13: =5717+1673 -> 7390 | G13: =5717+1806 -> 7523 | H13: =H7*I55 -> 37581.982 | J13: =J7*J55 -> 43932.041 | K13: =K7*K55 -> 49203.885 | L13: =L7*L55 -> 50064.953 | M13: =M7*M55 -> 54309.096 | N13: =N7*N55 -> 58881.164 | O13: =O7*O55 -> 64769.281 | P13: =P7*P55 -> 71246.209 | Q13: =Q7*Q55 -> 77658.367 | R13: =R7*R55 -> 84647.62
A14: R&D | C14: 27195 | D14: 29510 | E14: 32488 | F14: 7544 | G14: 8146 | H14: =H7*I56 -> 38877.912 | J14: =J7*J56 -> 46677.793 | K14: =K7*K56 -> 51254.047 | L14: =L7*L56 -> 56891.993 | M14: =M7*M56 -> 63150.112 | N14: =N7*N56 -> 67292.759 | O14: =O7*O56 -> 74022.035 | P14: =P7*P56 -> 81424.238 | Q14: =Q7*Q56 -> 88752.42 | R14: =R7*R56 -> 96740.138
A17: Total Operating Expenses | C17: =SUM(C13:C15) -> 57529 | D17: =SUM(D13:D15) -> 61575 | E17: =SUM(E13:E15) -> 65365 | F17: =SUM(F13:F15) -> 14934 | G17: =SUM(G13:G15) -> 15669 | H17: =SUM(H13:H15) -> 76459.894 | J17: =SUM(J13:J15) -> 90609.834 | K17: =SUM(K13:K15) -> 100457.93 | L17: =SUM(L13:L15) -> 106956.95 | M17: =SUM(M13:M15) -> 117459.21 | N17: =SUM(N13:N15) -> 126173.92 | O17: =SUM(O13:O15) -> 138791.32 | P17: =SUM(P13:P15) -> 152670.45 | Q17: =SUM(Q13:Q15) -> 166410.79 | R17: =SUM(R13:R15) -> 181387.76
A19: Operating Income | C19: =C10-C17 -> 88523 | D19: =D10-D17 -> 109433 | E19: =E10-E17 -> 128528 | F19: 30552 | G19: 37961 | H19: =H10-H17 -> 145468.19 | J19: =J10-J17 -> 165660.4 | K19: =K10-K17 -> 182464.41 | L19: =L10-L17 -> 211638.21 | M19: =M10-M17 -> 241233.43 | N19: =N10-N17 -> 277582.63 | O19: =O10-O17 -> 311509.4 | P19: =P10-P17 -> 346053.01 | Q19: =Q10-Q17 -> 377197.78 | R19: =R10-R17 -> 411145.59
A21: Other Income/(Expense) | C21: 788 | D21: -1646 | E21: -4901 | F21: -3660 | H21: =H7*I62 -> 0 | J21: =J7*J62 -> 0 | K21: =K7*K62 -> 0 | L21: =L7*L62 -> 0 | M21: =M7*M62 -> 0 | N21: =N7*N62 -> 0 | O21: =O7*O62 -> 0 | P21: =P7*P62 -> 0 | Q21: =Q7*Q62 -> 0 | R21: =R7*R62 -> 0
A23: Pretax Income | C23: =SUM(C19:C21) -> 89311 | D23: =SUM(D19:D21) -> 107787 | E23: =SUM(E19:E21) -> 123627 | F23: 30269 | G23: 34301 | H23: =H19+H21 -> 145468.19 | J23: =J19+J21 -> 165660.4 | K23: =K19+K21 -> 182464.41 | L23: =L19+L21 -> 211638.21 | M23: =M19+M21 -> 241233.43 | N23: =N19+N21 -> 277582.63 | O23: =O19+O21 -> 311509.4 | P23: =P19+P21 -> 346053.01 | Q23: =Q19+Q21 -> 377197.78 | R23: =R19+R21 -> 411145.59
A24: Income Taxes | C24: =C23-C26 -> 16950 | D24: =D23-D26 -> 19651 | E24: =E23-E26 -> 21795 | F24: =F23-F26 -> 5602 | G24: =G23-G26 -> 3468 | H24: =H23*I65 -> 27638.956 | J24: =J23*J65 -> 31475.477 | K24: =K23*K65 -> 34668.238 | L24: =L23*L65 -> 40211.26 | M24: =M23*M65 -> 45834.351 | N24: =N23*N65 -> 52740.7 | O24: =O23*O65 -> 59186.785 | P24: =P23*P65 -> 65750.073 | Q24: =Q23*Q65 -> 71667.579 | R24: =R23*R65 -> 78117.661
A26: Net Income | C26: 72361 | D26: 88136 | E26: 101832 | F26: 24667 | G26: =30833 -> 30833 | H26: =H23-H24 -> 117829.23 | J26: =J23-J24 -> 134184.93 | K26: =K23-K24 -> 147796.17 | L26: =L23-L24 -> 171426.95 | M26: =M23-M24 -> 195399.08 | N26: =N23-N24 -> 224841.93 | O26: =O23-O24 -> 252322.61 | P26: =P23-P24 -> 280302.94 | Q26: =Q23-Q24 -> 305530.21 | R26: =R23-R24 -> 333027.92
A28: + Depreciation & Amortization | C28: 13861 | D28: 22287 | E28: 34153 | G28: =13061 -> 13061 | H28: =I105 -> 42337.647 | J28: =J105 -> 61176.634 | K28: =K105 -> 66362.97 | L28: =L105 -> 70630.081 | M28: =M105 -> 74804.623 | N28: =N105 -> 79579.519 | O28: =O105 -> 84634.8 | P28: =P105 -> 89936.822 | Q28: =Q105 -> 95354.195 | R28: =R105 -> 100830.74
A29: - Capital Expenditures | C29: -28107 | D29: -44477 | E29: -64551 | G29: -19394 | H29: =-H7*H71 -> -98814.693 | J29: =-J7*J71 -> -106169.1 | K29: =-K7*K71 -> -102508.09 | L29: =-L7*L71 -> -86475.829 | M29: =-M7*M71 -> -88410.156 | N29: =-N7*N71 -> -89723.679 | O29: =-O7*O71 -> -92527.544 | P29: =-P7*P71 -> -94994.945 | Q29: =-Q7*Q71 -> -96148.455 | R29: =-R7*R71 -> -96740.138
A30: - Working Capital Additions | C30: =-(C4-B4) -> -5390 | D30: =-(D4-C4) -> -6760 | E30: =-(E4-D4) -> 168 | G30: -12109 | H30: =(E7-H7)*AVERAGE($C$73:$E$73) -> -7197.2265 | J30: =(H7-J7)*AVERAGE($C$73:$E$73) -> -7173.2357 | K30: =(J7-K7)*AVERAGE($C$73:$E$73) -> -7482.2367 | L30: =(K7-L7)*AVERAGE($C$73:$E$73) -> -7681.763 | M30: =(L7-M7)*AVERAGE($C$73:$E$73) -> -8526.7569 | N30: =(M7-N7)*AVERAGE($C$73:$E$73) -> -9464.7002 | O30: =(N7-O7)*AVERAGE($C$73:$E$73) -> -9550.7429 | P30: =(O7-P7)*AVERAGE($C$73:$E$73) -> -10505.817 | Q30: =(P7-Q7)*AVERAGE($C$73:$E$73) -> -10400.759 | R30: =(Q7-R7)*AVERAGE($C$73:$E$73) -> -11336.827
A32: Free Cash Flow | C32: =C26+SUM(C28:C30) -> 52725 | D32: =D26+SUM(D28:D30) -> 59186 | E32: =E26+SUM(E28:E30) -> 71602 | H32: =SUM(H26:H30)*0.75 -> 40616.22 | J32: =J26+J28+J29+J30 -> 82019.226 | K32: =K26+K28+K29+K30 -> 104168.81 | L32: =L26+L28+L29+L30 -> 147899.44 | M32: =M26+M28+M29+M30 -> 173266.79 | N32: =N26+N28+N29+N30 -> 205233.07 | O32: =O26+O28+O29+O30 -> 234879.13 | P32: =P26+P28+P29+P30 -> 264739 | Q32: =Q26+Q28+Q29+Q30 -> 294335.19 | R32: =R26+R28+R29+R30 -> 325781.69 | S32: =R26*(1-g/roic)/(D83-g) -> 4267520.7
A33: Present Value Factor | H33: 0.96978668 | J33: =1/(1+$D$83)^(J84/12) -> 0.90279135 | K33: =1/(1+$D$83)^(K84/12) -> 0.83187352 | L33: =1/(1+$D$83)^(L84/12) -> 0.76652657 | M33: =1/(1+$D$83)^(M84/12) -> 0.70631288 | N33: =1/(1+$D$83)^(N84/12) -> 0.65082921 | O33: =1/(1+$D$83)^(O84/12) -> 0.599704 | P33: =1/(1+$D$83)^(P84/12) -> 0.55259488 | Q33: =1/(1+$D$83)^(Q84/12) -> 0.50918637 | ... S33: =1/(1+$D$83)^(S84/12) -> 0.45038264
A35: PV Free Cash Flow | H35: =H32*H33 -> 39389.069 | J35: =J32*J33 -> 74046.248 | K35: =K32*K33 -> 86655.275 | L35: =L32*L33 -> 113368.85 | M35: =M32*M33 -> 122380.56 | N35: =N32*N33 -> 133571.68 | O35: =O32*O33 -> 140857.95 | P35: =P32*P33 -> 146293.42 | Q35: =Q32*Q33 -> 149871.47 | ... S35: =S32*S33 -> 1922017.2
A37: Value of Firm | E37: =SUM(J35:S35)+H35 -> 3081304.5
A38: Less: Debt Outstanding | E38: -43208
A39: Plus: Cash | E39: 102012
A41: Equity Value | E41: =E37+E38+E39 -> 3140108.5
A42: Shares Outstanding | E42: 7466
A44: Value Per Share | E44: =E41/E42 -> 420.5878
A46: Market Price | E46: 476.39
A47: % change | E47: =(E44-E46)/E46 -> -0.11713553
I48: =I5 -> 0 | J48: =J5 -> 2027 | K48: =K5 -> 2028 | L48: =L5 -> 2029 | M48: =M5 -> 2030 | N48: =N5 -> 2031 | O48: =O5 -> 2032 | P48: =P5 -> 2033 | ... R48: =R5 -> 2035
A49: Revenue Growth | I49: =Sheet1!E8 -> 0.15 | J49: =Sheet1!F8 -> 0.13 | K49: =Sheet1!G8 -> 0.12 | L49: =Sheet1!H8 -> 0.11 | M49: =Sheet1!I8 -> 0.11 | N49: =Sheet1!J8 -> 0.11 | O49: =Sheet1!K8 -> 0.1 | P49: =Sheet1!L8 -> 0.1 | ... R49: =Sheet1!N8 -> 0.09
A50: Cost of Goods Sold | C50: =(C8/C7) -> 0.31079914 | D50: =(D8/D7) -> 0.30235556 | E50: =(E8/E7) -> 0.31176258 | F50: =(F8/F7) -> 0.30645727 | G50: =(G8/G7) -> 0.30954128 | H50: =(H8/H7) -> 0.315 | I50: =Sheet1!E14 -> 0.315 | J50: =Sheet1!F14 -> 0.3 | K50: =Sheet1!G14 -> 0.31 | L50: =Sheet1!H14 -> 0.3 | M50: =Sheet1!I14 -> 0.29 | N50: =Sheet1!J14 -> 0.28 | O50: =Sheet1!K14 -> 0.27 | P50: =Sheet1!L14 -> 0.265 | ... R50: =Sheet1!N14 -> 0.265
A52: Gross Margin | I52: =Sheet1!E13 -> 0.685 | J52: =Sheet1!F13 -> 0.7 | K52: =Sheet1!G13 -> 0.69 | L52: =Sheet1!H13 -> 0.7 | M52: =Sheet1!I13 -> 0.71 | N52: =Sheet1!J13 -> 0.72 | O52: =Sheet1!K13 -> 0.73 | P52: =Sheet1!L13 -> 0.735 | ... R52: =Sheet1!N13 -> 0.735
A54: Operating Expenses:
A55: SG&A | C55: =(C13/C7) -> 0.1431423 | D55: =(D13/D7) -> 0.13081241 | E55: =(E13/E7) -> 0.11669932 | H55: =(H13/H7) -> 0.116 | I55: =Sheet1!E21 -> 0.116 | J55: =Sheet1!F21 -> 0.12 | K55: =Sheet1!G21 -> 0.12 | L55: =Sheet1!H21 -> 0.11 | M55: =Sheet1!I21 -> 0.1075 | N55: =Sheet1!J21 -> 0.105 | O55: =Sheet1!K21 -> 0.105 | P55: =Sheet1!L21 -> 0.105 | ... R55: =Sheet1!N21 -> 0.105
A56: R&D | C56: =(C14/C7) -> 0.12832975 | D56: =(D14/D7) -> 0.12038903 | E56: =(E14/E7) -> 0.11531854 | H56: =(H14/H7) -> 0.12 | I56: =Sheet1!E26 -> 0.12 | J56: =Sheet1!F26 -> 0.1275 | K56: =Sheet1!G26 -> 0.125 | L56: =Sheet1!H26 -> 0.125 | M56: =Sheet1!I26 -> 0.125 | N56: =Sheet1!J26 -> 0.12 | O56: =Sheet1!K26 -> 0.12 | P56: =Sheet1!L26 -> 0.12 | ... R56: =Sheet1!N26 -> 0.12
A58: Total Operating Expenses | I58: =H17/H7 -> 0.236 | J58: =J17/J7 -> 0.2475 | K58: =K17/K7 -> 0.245 | L58: =L17/L7 -> 0.235 | M58: =M17/M7 -> 0.2325 | N58: =N17/N7 -> 0.225 | O58: =O17/O7 -> 0.225 | P58: =P17/P7 -> 0.225 | Q58: =Q17/Q7 -> 0.225 | R58: =R17/R7 -> 0.225
A60: Operating Income | C60: =(C19/C7) -> 0.41772881 | D60: =(D19/D7) -> 0.446443 | E60: =(E19/E7) -> 0.45621956 | H60: =(H19/H7) -> 0.449 | I60: =H19/H7 -> 0.449 | J60: =J19/J7 -> 0.4525 | K60: =K19/K7 -> 0.445 | L60: =L19/L7 -> 0.465 | M60: =M19/M7 -> 0.4775 | N60: =N19/N7 -> 0.495 | O60: =O19/O7 -> 0.505 | P60: =P19/P7 -> 0.51 | Q60: =Q19/Q7 -> 0.51 | R60: =R19/R7 -> 0.51
A62: Other Income/(Expense) | I62: =Sheet1!E36 -> 0 | J62: =Sheet1!F36 -> 0 | K62: =Sheet1!G36 -> 0 | L62: =Sheet1!H36 -> 0 | M62: =Sheet1!I36 -> 0 | N62: =Sheet1!J36 -> 0 | O62: =Sheet1!K36 -> 0 | P62: =Sheet1!L36 -> 0 | ... R62: =Sheet1!N36 -> 0
A64: Pretax Income | I64: =H23/H7 -> 0.449 | J64: =J23/J7 -> 0.4525 | K64: =K23/K7 -> 0.445 | L64: =L23/L7 -> 0.465 | M64: =M23/M7 -> 0.4775 | N64: =N23/N7 -> 0.495 | O64: =O23/O7 -> 0.505 | P64: =P23/P7 -> 0.51 | Q64: =Q23/Q7 -> 0.51 | R64: =R23/R7 -> 0.51
A65: Income Tax Rate | C65: =C24/C23 -> 0.18978625 | D65: =D24/D23 -> 0.18231327 | E65: =E24/E23 -> 0.17629644 | I65: 0.19 | J65: 0.19 | K65: 0.19 | L65: 0.19 | M65: 0.19 | N65: 0.19 | O65: 0.19 | P65: 0.19 | Q65: 0.19 | R65: 0.19
...

Sheet Sheet3
A1: MSFT
A2: Discounted Cash Flow Analysis
A3: For the Years Ended June 30
A4: Millions of US Dollars
B6: 2023 | C6: 2024 | D6: 2025 | E6: 2025_Q1 | F6: 2026_Q1 | G6: 2026E | H6: 2027E | I6: 2028E | J6: 2029E | K6: 2030E | L6: 2031E | M6: 2032E | N6: 2033E | O6: 2034E | P6: 2035E
B7: -------------- | C7: -------------- | D7: -------------- | E7: -------------- | F7: -------------- | G7: -------------- | H7: -------------- | I7: -------------- | J7: -------------- | K7: -------------- | L7: -------------- | M7: -------------- | N7: -------------- | O7: -------------- | P7: --------------
A8: Revenue | B8: 211915 | C8: 245122 | D8: 281724 | E8: 65585 | F8: 77673 | G8: 326799.84 | H8: 379087.81 | I8: 439741.86 | J8: 505703.14 | K8: 576501.58 | L8: 651446.79 | M8: 729620.41 | N8: 817174.85 | O8: 907064.09 | P8: 1006841.1
A9: Cost of Goods Sold | B9: 65863 | C9: 74114 | D9: 87831 | E9: 20099 | F9: 24043 | G9: 101307.95 | H9: 113726.34 | I9: 131922.56 | J9: 146653.91 | K9: 161420.44 | L9: 175890.63 | M9: 182405.1 | N9: 204293.71 | O9: 226766.02 | P9: 251710.28
B10: -------------- | C10: -------------- | D10: -------------- | E10: -------------- | F10: -------------- | G10: -------------- | H10: -------------- | I10: -------------- | J10: -------------- | K10: -------------- | L10: -------------- | M10: -------------- | N10: -------------- | O10: -------------- | P10: --------------
A11: Gross Margin | B11: 146052 | C11: 171008 | D11: 193893 | E11: 45486 | F11: 53630 | G11: 225491.89 | H11: 265361.47 | I11: 307819.31 | J11: 359049.23 | K11: 415081.14 | L11: 475556.16 | M11: 547215.3 | N11: 612881.14 | O11: 680298.07 | P11: 755130.85
A13: Operating Expenses:
A14: SG&A | B14: 30334 | C14: 32065 | D14: 32877 | E14: 7390 | F14: 7523 | G14: 37745.382 | H14: 43595.099 | I14: 48371.605 | J14: 53098.83 | K14: 58514.911 | L14: 65144.679 | M14: 72962.041 | N14: 81717.485 | O14: 90706.409 | P14: 100684.11
A15: R&D | B15: 27195 | C15: 29510 | D15: 32488 | E15: 7544 | F15: 8146 | G15: 38562.381 | H15: 44353.274 | I15: 50570.314 | J15: 58155.862 | K15: 66297.682 | L15: 71659.147 | M15: 80258.245 | N15: 89889.234 | O15: 99777.05 | P15: 110752.53
B16: -------------- | C16: -------------- | D16: -------------- | E16: -------------- | F16: -------------- | G16: -------------- | H16: -------------- | I16: -------------- | J16: -------------- | K16: -------------- | L16: -------------- | M16: -------------- | N16: -------------- | O16: -------------- | P16: --------------
A17: Total Operating Expenses | B17: 57529 | C17: 61575 | D17: 65365 | E17: 14934 | F17: 15669 | G17: 76307.763 | H17: 87948.373 | I17: 98941.92 | J17: 111254.69 | K17: 124812.59 | L17: 136803.83 | M17: 153220.29 | N17: 171606.72 | O17: 190483.46 | P17: 211436.64
A19: Operating Income | B19: 88523 | C19: 109433 | D19: 128528 | E19: 30552 | F19: 37961 | G19: 149184.13 | H19: 177413.1 | I19: 208877.39 | J19: 247794.54 | K19: 290268.55 | L19: 338752.33 | M19: 393995.02 | N19: 441274.42 | O19: 489814.61 | P19: 543694.21
A21: Other Income/(Expense) | B21: 788 | C21: -1646 | D21: -4901 | E21: -3660 | F21: 0 | G21: 0 | H21: 0 | I21: 0 | J21: 0 | K21: 0 | L21: 0 | M21: 0 | N21: 0 | O21: 0 | P21: 0
B22: -------------- | C22: -------------- | D22: -------------- | E22: -------------- | F22: -------------- | G22: -------------- | H22: -------------- | I22: -------------- | J22: -------------- | K22: -------------- | L22: -------------- | M22: -------------- | N22: -------------- | O22: -------------- | P22: --------------
A23: Pretax Income | B23: 89311 | C23: 107787 | D23: 123627 | E23: 30269 | F23: 34301 | G23: 149184.13 | H23: 177413.1 | I23: 208877.39 | J23: 247794.54 | K23: 290268.55 | L23: 338752.33 | M23: 393995.02 | N23: 441274.42 | O23: 489814.61 | P23: 543694.21
A24: Income Taxes | B24: 16950 | C24: 19651 | D24: 21795 | E24: 5602 | F24: 3468 | G24: 28344.984 | H24: 33708.488 | I24: 39686.703 | J24: 47080.963 | K24: 55151.024 | L24: 64362.943 | M24: 74859.054 | N24: 83842.14 | O24: 93064.775 | P24: 103301.9
A26: Net Income | B26: 72361 | C26: 88136 | D26: 101832 | E26: 24667 | F26: 30833 | G26: 120839.14 | H26: 143704.61 | I26: 169190.68 | J26: 200713.58 | K26: 235117.52 | L26: 274389.39 | M26: 319135.97 | N26: 357432.28 | O26: 396749.83 | P26: 440392.31
A28: + Depreciation & Amortization | B28: 13861 | C28: 22287 | D28: 34153 | F28: 13061 | G28: 42279.542 | H28: 61475.796 | I28: 67404.87 | J28: 72379.906 | K28: 77513.96 | L28: 83413.912 | M28: 89431.125 | N28: 96265.513 | O28: 103406.34 | P28: 110787.54
A29: - Capital Expenditures | B29: -28107 | C29: -44477 | D29: -64551 | F29: -19394 | G29: -98039.952 | H29: -109935.47 | I29: -109935.47 | J29: -93555.082 | K29: -98005.269 | L29: -100974.25 | M29: -102146.86 | N29: -110318.61 | O29: -113383.01 | P29: -115786.73
A30: - Working Capital Additions | B30: -5390 | C30: -6760 | D30: 168 | F30: -12109 | G30: -7677.0416 | H30: -8905.3683 | I30: -10330.227 | J30: -11234.122 | K30: -12057.958 | L30: -12764.209 | M30: -13314.052 | N30: -14911.739 | O30: -15309.385 | P30: -16993.417
B31: -------------- | C31: -------------- | D31: -------------- | E31: -------------- | F31: -------------- | G31: -------------- | H31: -------------- | I31: -------------- | J31: -------------- | K31: -------------- | L31: -------------- | M31: -------------- | N31: -------------- | O31: -------------- | P31: --------------
A32: Free Cash Flow | B32: 52725 | C32: 59186 | D32: 71602 | G32: 43051.268 | H32: 86339.571 | I32: 116329.86 | J32: 168304.28 | K32: 202568.26 | L32: 244064.84 | M32: 293106.18 | N32: 328467.45 | O32: 371463.78 | P32: 418399.71 | Q32: 5643320.6
A33: Present Value Factor | G33: 0.96978668 | H33: 0.90279135 | I33: 0.83187352 | J33: 0.76652657 | K33: 0.70631288 | L33: 0.65082921 | M33: 0.599704 | N33: 0.55259488 | O33: 0.50918637 | P33: 0.46918777 | Q33: 0.45038264
G34: -------------- | H34: -------------- | I34: -------------- | J34: -------------- | K34: -------------- | L34: -------------- | M34: -------------- | N34: -------------- | O34: -------------- | P34: -------------- | Q34: --------------
A35: PV Free Cash Flow | G35: 41750.547 | H35: 77946.618 | I35: 96771.73 | J35: 129009.7 | K35: 143076.57 | L35: 158844.53 | M35: 175776.95 | N35: 181509.43 | O35: 189144.29 | P35: 196308.03 | Q35: 2541653.6
A37: Value of Firm | D37: 3931792
A38: Less: Debt Outstanding | D38: -43208
A39: Plus: Cash | D39: 102012
D40: --------------
A41: Equity Value | D41: 3990596
A42: Shares Outstanding | D42: 7466
D43: --------------
A44: Value Per Share | D44: 534.50254

Sheet nwc
B1: 2022 | C1: 2023 | D1: 2024 | E1: 2025 | F1: 2026q1
A2: working capital | B2: 31860 | C2: 37250 | D2: 44010 | E2: 43842 | F2: 31733
A3: change in working capital | C3: =C2-B2 -> 5390 | D3: =D2-C2 -> 6760 | E3: =E2-D2 -> -168 | F3: =F2-E2 -> -12109
A5: rev | C5: 211915 | D5: 245122 | E5: 281724
A6: working capital/rev | C6: =C2/C5 -> 0.17577802 | D6: =D2/D5 -> 0.17954325 | E6: =E2/E5 -> 0.15562039
A11: 11/14 market cap | B11: 3850008.5
A12: 11/14 total debt | B12: 2318519
A14: 11/14 debt/capital | B14: =B12/B11 -> 0.6022114
A19: r&d (% of rev) | B19: 8.18 | C19: 7.86 | D19: 7.21 | E19: 8.44 | F19: 7.05
A23: rev yoy | B23: 25.17 | C23: 18.53 | D23: 42.61 | E23: -4.51 | F23: 33.89
A25: cogs ( % rev) | B25: 46.9 | C25: 48.37 | D25: 40.44 | E25: 45.64 | F25: 43.88
