Workbook

Sheet Sheet1
B2: Option Selection
B3: Operating Scenario | D3: 1
I4: Projected
E5: 2025_Q4 | F5: 2026 | G5: =F5+1 -> 2027 | H5: =G5+1 -> 2028 | I5: =H5+1 -> 2029 | J5: =I5+1 -> 2030 | K5: =J5+1 -> 2031 | L5: =K5+1 -> 2032 | M5: =L5+1 -> 2033 | N5: =M5+1 -> 2034 | O5: =N5+1 -> 2035
A8: Total Revenue Growth | E8: =CHOOSE($D$3,E9,E10,E11) -> 0.02 | F8: =CHOOSE($D$3,F9,F10,F11) -> 0.01 | G8: =CHOOSE($D$3,G9,G10,G11) -> 0.02 | H8: =CHOOSE($D$3,H9,H10,H11) -> 0.02 | I8: =CHOOSE($D$3,I9,I10,I11) -> 0.01 | J8: =CHOOSE($D$3,J9,J10,J11) -> 0.01 | K8: =CHOOSE($D$3,K9,K10,K11) -> 0.01 | L8: =CHOOSE($D$3,L9,L10,L11) -> 0.01 | ... O8: =CHOOSE($D$3,O9,O10,O11) -> 0.01
A9: Base | E9: 0.02 | F9: 0.01 | G9: 0.02 | H9: 0.02 | I9: 0.01 | J9: 0.01 | K9: 0.01 | L9: 0.01 | M9: 0.01 | N9: 0.01 | O9: 0.01
A10: Bull | E10: 0.02 | F10: 0.02 | G10: 0.035 | H10: 0.035 | I10: 0.035 | J10: 0.035 | K10: 0.03 | L10: 0.03 | M10: 0.03 | N10: 0.025 | O10: 0.025
A11: Bear | E11: 0.01 | F11: -0.01 | G11: -0.005 | H11: 0 | I11: 0.005 | J11: 0.005 | K11: 0.005 | L11: 0.005 | M11: 0.005 | N11: 0.005 | O11: 0.005
A13: Gross Margin | E13: =1-E14 -> 0.544 | F13: =1-F14 -> 0.546 | G13: =1-G14 -> 0.5475 | H13: =1-H14 -> 0.5475 | I13: =1-I14 -> 0.5475 | J13: =1-J14 -> 0.5475 | K13: =1-K14 -> 0.5475 | L13: =1-L14 -> 0.5475 | ... O13: =1-O14 -> 0.5475
A14: COGS | E14: {=INDEX(E15:E18,$D$3)} -> 0.456 | F14: {=INDEX(F15:F18,$D$3)} -> 0.454 | G14: {=INDEX(G15:G18,$D$3)} -> 0.4525 | H14: {=INDEX(H15:H18,$D$3)} -> 0.4525 | I14: {=INDEX(I15:I18,$D$3)} -> 0.4525 | J14: {=INDEX(J15:J18,$D$3)} -> 0.4525 | K14: {=INDEX(K15:K18,$D$3)} -> 0.4525 | L14: {=INDEX(L15:L18,$D$3)} -> 0.4525 | ... O14: {=INDEX(O15:O18,$D$3)} -> 0.4525
A15: Base | E15: 0.456 | F15: 0.454 | G15: 0.4525 | H15: 0.4525 | I15: 0.4525 | J15: 0.4525 | K15: 0.4525 | L15: 0.4525 | M15: 0.4525 | N15: 0.4525 | O15: 0.4525
A16: Bull | E16: 0.4555 | F16: 0.4535 | G16: 0.452 | H16: 0.451 | I16: 0.4505 | J16: 0.4505 | K16: 0.4505 | L16: 0.4505 | M16: 0.4505 | N16: 0.4505 | O16: 0.4505
A17: Bear | E17: 0.46 | F17: 0.456 | G17: 0.457 | H17: 0.4565 | I17: 0.456 | J17: 0.456 | K17: 0.456 | L17: 0.456 | M17: 0.456 | N17: 0.456 | O17: 0.456
A19: Operating Expense
A21: SG&A | E21: {=INDEX(E22:E24,$D$3)} -> 0.3965 | F21: {=INDEX(F22:F24,$D$3)} -> 0.3825 | G21: {=INDEX(G22:G24,$D$3)} -> 0.3818 | H21: {=INDEX(H22:H24,$D$3)} -> 0.3805 | I21: {=INDEX(I22:I24,$D$3)} -> 0.3805 | J21: {=INDEX(J22:J24,$D$3)} -> 0.3805 | K21: {=INDEX(K22:K24,$D$3)} -> 0.3805 | L21: {=INDEX(L22:L24,$D$3)} -> 0.3805 | ... O21: {=INDEX(O22:O24,$D$3)} -> 0.3805
A22: Base | E22: 0.3965 | F22: 0.3825 | G22: 0.3818 | H22: 0.3805 | I22: 0.3805 | J22: 0.3805 | K22: 0.3805 | L22: 0.3805 | M22: 0.3805 | N22: 0.3805 | O22: 0.3805
A23: Bull | E23: 0.3955 | F23: 0.3822 | G23: 0.381 | H23: 0.3805 | I23: 0.3805 | J23: 0.3805 | K23: 0.3805 | L23: 0.3805 | M23: 0.3805 | N23: 0.3805 | O23: 0.3805
A24: Bear | E24: 0.4 | F24: 0.3905 | G24: 0.397 | H24: 0.397 | I24: 0.3955 | J24: 0.395 | K24: 0.3945 | L24: 0.3945 | M24: 0.3945 | N24: 0.3945 | O24: 0.3945
A26: R&D | E26: {=INDEX(E27:E29,$D$3)} -> 0.01 | F26: {=INDEX(F27:F29,$D$3)} -> 0.01 | G26: {=INDEX(G27:G29,$D$3)} -> 0.01 | H26: {=INDEX(H27:H29,$D$3)} -> 0.01 | I26: {=INDEX(I27:I29,$D$3)} -> 0.008 | J26: {=INDEX(J27:J29,$D$3)} -> 0.008 | K26: {=INDEX(K27:K29,$D$3)} -> 0.008 | L26: {=INDEX(L27:L29,$D$3)} -> 0.008 | ... O26: {=INDEX(O27:O29,$D$3)} -> 0.008
A27: Base | E27: 0.01 | F27: 0.01 | G27: 0.01 | H27: 0.01 | I27: 0.008 | J27: 0.008 | K27: 0.008 | L27: 0.008 | M27: 0.008 | N27: 0.008 | O27: 0.008
A28: Bull | E28: 0.01 | F28: 0.01 | G28: 0.01 | H28: 0.008 | I28: 0.008 | J28: 0.008 | K28: 0.008 | L28: 0.008 | M28: 0.008 | N28: 0.008 | O28: 0.008
A29: Bear | E29: 0.01 | F29: 0.013 | G29: 0.013 | H29: 0.013 | I29: 0.013 | J29: 0.01 | K29: 0.01 | L29: 0.01 | M29: 0.01 | N29: 0.01 | O29: 0.01
A31: CapEx | E31: {=INDEX(E32:E34,$D$3)} -> 0.067 | F31: {=INDEX(F32:F34,$D$3)} -> 0.055 | G31: {=INDEX(G32:G34,$D$3)} -> 0.055 | H31: {=INDEX(H32:H34,$D$3)} -> 0.055 | I31: {=INDEX(I32:I34,$D$3)} -> 0.055 | J31: {=INDEX(J32:J34,$D$3)} -> 0.05 | K31: {=INDEX(K32:K34,$D$3)} -> 0.05 | L31: {=INDEX(L32:L34,$D$3)} -> 0.05 | ... O31: {=INDEX(O32:O34,$D$3)} -> 0.05
A32: Base | E32: 0.067 | F32: 0.055 | G32: 0.055 | H32: 0.055 | I32: 0.055 | J32: 0.05 | K32: 0.05 | L32: 0.05 | M32: 0.05 | N32: 0.05 | O32: 0.05
A33: Bull | E33: 0.065 | F33: 0.055 | G33: 0.055 | H33: 0.05 | I33: 0.05 | J33: 0.05 | K33: 0.05 | L33: 0.05 | M33: 0.05 | N33: 0.05 | O33: 0.05
A34: Bear | E34: 0.068 | F34: 0.057 | G34: 0.057 | H34: 0.057 | I34: 0.055 | J34: 0.055 | K34: 0.05 | L34: 0.05 | M34: 0.05 | N34: 0.05 | O34: 0.05
A36: Other Income | E36: {=INDEX(E37:E39,$D$3)} -> 0 | F36: {=INDEX(F37:F39,$D$3)} -> 0 | G36: {=INDEX(G37:G39,$D$3)} -> 0 | H36: {=INDEX(H37:H39,$D$3)} -> 0 | I36: {=INDEX(I37:I39,$D$3)} -> 0 | J36: {=INDEX(J37:J39,$D$3)} -> 0 | K36: {=INDEX(K37:K39,$D$3)} -> 0 | L36: {=INDEX(L37:L39,$D$3)} -> 0 | ... O36: {=INDEX(O37:O39,$D$3)} -> 0
A37: Base | E37: 0 | F37: 0 | G37: 0 | H37: 0 | I37: 0 | J37: 0 | K37: 0 | L37: 0 | M37: 0 | N37: 0 | O37: 0
A38: Bull | E38: 0 | F38: 0 | G38: 0 | H38: 0 | I38: 0 | J38: 0 | K38: 0 | L38: 0 | M38: 0 | N38: 0 | O38: 0
A39: Bear | E39: 0 | F39: 0 | G39: 0 | H39: 0 | I39: 0 | J39: 0 | K39: 0 | L39: 0 | M39: 0 | N39: 0 | O39: 0
A41: ROIC | E41: {=INDEX(E42:E44,$D$3)} -> 0.175
A42: Base | E42: 0.175
A43: Bull | E43: 0.21
A44: Bear | E44: 0.17

Sheet Sheet2
J2: Pepsico
I3: Disconted Cash Flow Model
C6: 2023 | D6: 2024 | E6: 2024_Q4 | F6: 2025_Q1-3 | G6: 2025 | H6: 2025_Q4 | I6: =G6+1 -> 2026 | J6: =I6+1 -> 2027 | K6: =J6+1 -> 2028 | L6: =K6+1 -> 2029 | M6: =L6+1 -> 2030 | N6: =M6+1 -> 2031 | O6: =N6+1 -> 2032 | P6: =O6+1 -> 2033 | Q6: =P6+1 -> 2034 | R6: =Q6+1 -> 2035
A8: Revenue | C8: 91471 | D8: 91854 | E8: 27784 | F8: 64582 | G8: =F8+H8 -> 92921.68 | H8: =E8*(1+H54) -> 28339.68 | I8: =G8*(1+I54) -> 93850.897 | J8: =I8*(1+J54) -> 95727.915 | K8: =J8*(1+K54) -> 97642.473 | L8: =K8*(1+L54) -> 98618.898 | M8: =L8*(1+M54) -> 99605.087 | N8: =M8*(1+N54) -> 100601.14 | O8: =N8*(1+O54) -> 101607.15 | P8: =O8*(1+P54) -> 102623.22 | Q8: =P8*(1+Q54) -> 103649.45 | R8: =Q8*(1+R54) -> 104685.95
A9: Cost of Goods Sold | C9: 41865 | D9: 41409 | E9: 12857 | F9: 29377 | G9: =F9+H9 -> 42299.894 | H9: =H8*H55 -> 12922.894 | I9: =I8*I55 -> 42608.307 | J9: =J8*J55 -> 43316.881 | K9: =K8*K55 -> 44183.219 | L9: =L8*L55 -> 44625.051 | M9: =M8*M55 -> 45071.302 | N9: =N8*N55 -> 45522.015 | O9: =O8*O55 -> 45977.235 | ... R9: =R8*R55 -> 47370.391
A11: Gross Margin | C11: =C8-C9 -> 49606 | D11: =D8-D9 -> 50445 | E11: =E8-E9 -> 14927 | F11: =F8-F9 -> 35205 | G11: =G8-G9 -> 50621.786 | H11: =H8-H9 -> 15416.786 | I11: =I8-I9 -> 51242.59 | J11: =J8-J9 -> 52411.033 | ... R11: =R8-R9 -> 57315.556
A13: Operating Expenses:
A14: SG&A | C14: 34927 | D14: 35119 | E14: 11465 | F14: 24450 | G14: =H14+F14 -> 35686.683 | H14: =H8*H60 -> 11236.683 | I14: =I8*I60 -> 35897.968 | J14: =J8*J60 -> 36548.918 | K14: =K8*K60 -> 37152.961 | L14: =L8*L60 -> 37524.491 | M14: =M8*M60 -> 37899.736 | N14: =N8*N60 -> 38278.733 | O14: =O8*O60 -> 38661.52 | ... R14: =R8*R60 -> 39833.003
A15: R&D | C15: 804 | D15: 813 | E15: 0 | F15: 0 | G15: =F15+H15 -> 283.3968 | H15: =H8*H61 -> 283.3968 | I15: =I8*I61 -> 938.50897 | J15: =J8*J61 -> 957.27915 | K15: =K8*K61 -> 976.42473 | L15: =L8*L61 -> 788.95118 | M15: =M8*M61 -> 796.84069 | N15: =N8*N61 -> 804.8091 | O15: =O8*O61 -> 812.85719 | ... R15: =R8*R61 -> 837.48758
A17: Total Operating Expenses | C17: =SUM(C14:C15) -> 35731 | D17: =SUM(D14:D15) -> 35932 | E17: =E14+E15 -> 11465 | F17: =F15+F14 -> 24450 | G17: =SUM(G14:G14) -> 35686.683 | H17: =SUM(H14:H14) -> 11236.683 | I17: =SUM(I14:I14) -> 35897.968 | J17: =SUM(J14:J14) -> 36548.918 | K17: =SUM(K14:K14) -> 37152.961 | L17: =SUM(L14:L14) -> 37524.491 | M17: =SUM(M14:M14) -> 37899.736 | N17: =SUM(N14:N14) -> 38278.733 | ... R17: =SUM(R14:R14) -> 39833.003
A19: Operating Income | C19: =C11-C17 -> 13875 | D19: =D11-D17 -> 14513 | E19: =E11-E17+89 -> 3551 | F19: =F11-F17 -> 10755 | G19: =G11-G17 -> 14935.103 | H19: =H11-H17 -> 4180.1028 | I19: =I11-I17 -> 15344.622 | J19: =J11-J17 -> 15862.115 | K19: =K11-K17 -> 16306.293 | L19: =L11-L17 -> 16469.356 | M19: =M11-M17 -> 16634.049 | ... R19: =R11-R17 -> 17482.553
A21: Other Income/(Expense) | C21: 0 | D21: 0 | E21: 0 | F21: 0 | G21: =F21+H21 -> 0 | H21: =H8*H67 -> 0 | I21: =I8*I67 -> 0 | J21: =J8*J67 -> 0 | K21: =K8*K67 -> 0 | L21: =L8*L67 -> 0 | M21: =M8*M67 -> 0 | N21: =N8*N67 -> 0 | O21: =O8*O67 -> 0 | ... R21: =R8*R67 -> 0
A23: Pretax Income | C23: =C21+C19 -> 13875 | D23: =D21+D19 -> 14513 | E23: =E21+E19 -> 3551 | F23: =F21+F19 -> 10755 | G23: =F23+H23 -> 14935.103 | H23: =H19+H21 -> 4180.1028 | I23: =I19+I21 -> 15344.622 | J23: =J19+J21 -> 15862.115 | K23: =K19+K21 -> 16306.293 | L23: =L19+L21 -> 16469.356 | M23: =M19+M21 -> 16634.049 | N23: =N19+N21 -> 16800.39 | O23: =O19+O21 -> 16968.394 | ... R23: =R19+R21 -> 17482.553
A24: Income Taxes | C24: =C23*C70 -> 2747.25 | D24: =D23*D70 -> 2815.522 | E24: =E23*E70 -> 632.078 | F24: =F23*F70 -> 2097.225 | G24: =H24+F24 -> 2912.345 | H24: =H23*H70 -> 815.12005 | I24: =I23*I70 -> 2992.2012 | J24: =J23*J70 -> 3093.1125 | K24: =K23*K70 -> 3179.7271 | L24: =L23*L70 -> 3211.5244 | M24: =M23*M70 -> 3243.6396 | N24: =N23*N70 -> 3276.076 | O24: =O23*O70 -> 3308.8368 | ... R24: =R23*R70 -> 3409.0979
A26: Net Income | C26: =C23-C24 -> 11127.75 | D26: =D23-D24 -> 11697.478 | E26: =E23-E24 -> 2918.922 | F26: =F23-F24 -> 8657.775 | G26: =F26+H26 -> 12022.758 | H26: =H23-H24 -> 3364.9828 | I26: =I23-I24 -> 12352.42 | J26: =J23-J24 -> 12769.003 | K26: =K23-K24 -> 13126.566 | L26: =L23-L24 -> 13257.832 | M26: =M23-M24 -> 13390.41 | N26: =N23-N24 -> 13524.314 | O26: =O23-O24 -> 13659.557 | ... R26: =R23-R24 -> 14073.455
A28: + Depreciation & Amortization | C28: =C113 -> 2948 | D28: =D113 -> 3160 | E28: 1042 | F28: =F113 -> 2315 | G28: =G113 -> 2962.2553 | H28: =H113 -> 647.25532 | I28: =I113 -> 2732.8467 | J28: =J113 -> 2886.834 | K28: =K113 -> 3049.0863 | L28: =L113 -> 3214.0238 | M28: =M113 -> 3354.772 | ... R28: =R113 -> 4111.3668
A29: - Capital Expenditures | C29: -5320 | D29: -4976 | E29: -2303 | F29: -2227 | G29: =F29+H29 -> -4125.7586 | H29: =-H8*H76 -> -1898.7586 | I29: =-I8*I76 -> -5161.7993 | J29: =-J8*J76 -> -5265.0353 | K29: =-K8*K76 -> -5370.336 | L29: =-L8*L76 -> -5424.0394 | M29: =-M8*M76 -> -4980.2543 | N29: =-N8*N76 -> -5030.0569 | O29: =-O8*O76 -> -5080.3574 | ... R29: =-R8*R76 -> -5234.2974
A30: - Working Capital Additions | C30: 1010 | D30: -296 | E30: 2904 | F30: -3192 | G30: =F30+H30 -> -3158.6592 | H30: =(E8-H8)*C78 -> 33.3408 | I30: =(G8-I8)*C78 -> 55.753008 | J30: =(I8-J8)*$C$78 -> 112.62108 | K30: =(J8-K8)*$C$78 -> 114.8735 | L30: =(K8-L8)*$C$78 -> 58.585484 | M30: =(L8-M8)*$C$78 -> 59.171339 | N30: =(M8-N8)*$C$78 -> 59.763052 | O30: =(N8-O8)*$C$78 -> 60.360683 | P30: =(O8-P8)*$C$78 -> 60.964289 | Q30: =(P8-Q8)*$C$78 -> 61.573932 | R30: =(Q8-R8)*$C$78 -> 62.189672
A32: Free Cash Flow | C32: =SUM(C28:C30)+C26 -> 9765.75 | D32: =SUM(D28:D30)+D26 -> 9585.478 | E32: =SUM(E26:E30) -> 4561.922 | F32: =SUM(F26:F30) -> 5553.775 | G32: =SUM(G26:G30) -> 7700.5953 | H32: =H26+H28+H29+H30 -> 2146.8203 | I32: =I26+I28+I29+I30 -> 9979.2208 | J32: =J26+J28+J29+J30 -> 10503.423 | K32: =K26+K28+K29+K30 -> 10920.19 | L32: =L26+L28+L29+L30 -> 11106.401 | M32: =M26+M28+M29+M30 -> 11824.099 | N32: =N26+N28+N29+N30 -> 12055.03 | O32: =O26+O28+O29+O30 -> 12289.324 | ... R32: =R26+R28+R29+R30 -> 13012.714 | S32: =R26*(1-0.005/Sheet1!E41)/(C88-0.005) -> 302070.15
A33: Present Value Factor | H33: =1/(1+$C$88)^H89 -> 0.99388916 | I33: =1/(1+$C$88)^I89 -> 0.96389056 | J33: =1/(1+$C$88)^J89 -> 0.91776474 | K33: =1/(1+$C$88)^K89 -> 0.8738462 | L33: =1/(1+$C$88)^L89 -> 0.83202934 | M33: =1/(1+$C$88)^M89 -> 0.79221357 | N33: =1/(1+$C$88)^N89 -> 0.75430314 | O33: =1/(1+$C$88)^O89 -> 0.71820687 | ... S33: =1/(1+$C$88)^S89 -> 0.60493998
A35: PV Free Cash Flow | H35: =H32*H33 -> 2133.7014 | I35: =I32*I33 -> 9618.8768 | J35: =J32*J33 -> 9639.671 | K35: =K32*K33 -> 9542.5663 | L35: =L32*L33 -> 9240.8519 | M35: =M32*M33 -> 9367.2116 | N35: =N32*N33 -> 9093.1474 | O35: =O32*O33 -> 8826.277 | ... S35: =S32*S33 -> 182734.31
A37: Value of Firm | D37: =SUM(H35:S35) -> 275143.87
A38: Less: Debt Outstanding | D38: -50849
A39: Plus: Cash | D39: 8661
A41: Equity Value | D41: =D37+D38+D39 -> 232955.87
A42: Shares Outstanding | D42: 1372
A44: Value Per Share | D44: =D41/D42 -> 169.79291 | F44: % Change | G44: =(D44-D46)/D46 -> 0.16696156
A46: Current Market Price | D46: 145.5
I48: Pepsico
H49: Ratios and Margins
H52: =H6 -> 2025_Q4 | I52: =I6 -> 2026 | J52: =J6 -> 2027 | K52: =K6 -> 2028 | L52: =L6 -> 2029 | M52: =M6 -> 2030 | N52: =N6 -> 2031 | O52: =O6 -> 2032 | ... R52: =R6 -> 2035
A54: Revenue Growth | C54: 0.059 | D54: =(D8-C8)/C8 -> 0.0041871194 | G54: =(G8-D8)/D8 -> 0.011623664 | H54: =Sheet1!E8 -> 0.02 | I54: =Sheet1!F8 -> 0.01 | J54: =Sheet1!G8 -> 0.02 | K54: =Sheet1!H8 -> 0.02 | L54: =Sheet1!I8 -> 0.01 | M54: =Sheet1!J8 -> 0.01 | N54: =Sheet1!K8 -> 0.01 | O54: =Sheet1!L8 -> 0.01 | ... R54: =Sheet1!O8 -> 0.01
A55: Cost of Goods Sold | C55: =C9/C8 -> 0.45768604 | D55: =D9/D8 -> 0.45081325 | E55: =E9/E8 -> 0.46274834 | F55: =F9/F8 -> 0.45487907 | G55: =G9/G8 -> 0.45522094 | H55: =Sheet1!E14 -> 0.456 | I55: =Sheet1!F14 -> 0.454 | J55: =Sheet1!G14 -> 0.4525 | K55: =Sheet1!H14 -> 0.4525 | L55: =Sheet1!I14 -> 0.4525 | M55: =Sheet1!J14 -> 0.4525 | N55: =Sheet1!K14 -> 0.4525 | O55: =Sheet1!L14 -> 0.4525 | ... R55: =Sheet1!O14 -> 0.4525
A57: Gross Margin | C57: =C11/C8 -> 0.54231396 | D57: =D11/D8 -> 0.54918675 | E57: =E11/E8 -> 0.53725166 | F57: =F11/F8 -> 0.54512093 | G57: =G11/G8 -> 0.54477906 | H57: =Sheet1!E13 -> 0.544 | I57: =Sheet1!F13 -> 0.546 | J57: =Sheet1!G13 -> 0.5475 | K57: =Sheet1!H13 -> 0.5475 | L57: =Sheet1!I13 -> 0.5475 | M57: =Sheet1!J13 -> 0.5475 | N57: =Sheet1!K13 -> 0.5475 | O57: =Sheet1!L13 -> 0.5475 | ... R57: =Sheet1!O13 -> 0.5475
A59: Operating Expenses:
A60: SG&A | C60: =C14/C8 -> 0.38183687 | D60: =D14/D8 -> 0.38233501 | E60: =E14/E8 -> 0.41264757 | F60: =F14/F8 -> 0.37858846 | G60: =G14/G8 -> 0.3840512 | H60: =Sheet1!E21 -> 0.3965 | I60: =Sheet1!F21 -> 0.3825 | J60: =Sheet1!G21 -> 0.3818 | K60: =Sheet1!H21 -> 0.3805 | L60: =Sheet1!I21 -> 0.3805 | M60: =Sheet1!J21 -> 0.3805 | N60: =Sheet1!K21 -> 0.3805 | O60: =Sheet1!L21 -> 0.3805 | ... R60: =Sheet1!O21 -> 0.3805
A61: R&D | C61: =C15/C8 -> 0.008789671 | D61: =D15/D8 -> 0.0088510027 | E61: =E15/E8 -> 0 | F61: =F15/F8 -> 0 | G61: =G15/G8 -> 0.0030498458 | H61: =Sheet1!E26 -> 0.01 | I61: =Sheet1!F26 -> 0.01 | J61: =Sheet1!G26 -> 0.01 | K61: =Sheet1!H26 -> 0.01 | L61: =Sheet1!I26 -> 0.008 | M61: =Sheet1!J26 -> 0.008 | N61: =Sheet1!K26 -> 0.008 | O61: =Sheet1!L26 -> 0.008 | ... R61: =Sheet1!O26 -> 0.008
A63: Total Operating Expenses | C63: =C17/C8 -> 0.39062654 | D63: =D17/D8 -> 0.39118601 | E63: =E17/E8 -> 0.41264757 | F63: =F17/F8 -> 0.37858846 | G63: =G17/G8 -> 0.3840512 | H63: =H17/H8 -> 0.3965 | I63: =I17/I8 -> 0.3825 | J63: =J17/J8 -> 0.3818 | ... R63: =R17/R8 -> 0.3805
A65: Operating Income | C65: =C19/C8 -> 0.15168742 | D65: =D19/D8 -> 0.15800074 | E65: =E19/E8 -> 0.12780737 | F65: =F19/F8 -> 0.16653247 | G65: =G19/G8 -> 0.16072786 | H65: =H19/H8 -> 0.1475 | I65: =I19/I8 -> 0.1635 | J65: =J19/J8 -> 0.1657 | ... R65: =R19/R8 -> 0.167
A67: Other Income/(Expense) | C67: =C21/C8 -> 0 | D67: =D21/D8 -> 0 | E67: =E21/E8 -> 0 | F67: =F21/F8 -> 0 | G67: =G21/G8 -> 0 | H67: =Sheet1!E36 -> 0 | I67: =Sheet1!F36 -> 0 | J67: =Sheet1!G36 -> 0 | K67: =Sheet1!H36 -> 0 | L67: =Sheet1!I36 -> 0 | M67: =Sheet1!J36 -> 0 | N67: =Sheet1!K36 -> 0 | O67: =Sheet1!L36 -> 0 | ... R67: =Sheet1!O36 -> 0
...

Sheet Sheet3
